ERROR - 2022-05-24 18:58:51,021 - process: 60056 - utils.py - polls.utils - 84 - utils - HTTPConnectionPool(host='127.0.0.1', port=6800): Max retries exceeded with url: / (Caused by NewConnectionError('<urllib3.connection.HTTPConnection object at 0x00000209A78BC8E0>: Failed to establish a new connection: [WinError 10061] No connection could be made because the target machine actively refused it'))
Traceback (most recent call last):
  File "C:\Users\46121\PycharmProjects\CS65_3\vr_env\lib\site-packages\urllib3\connection.py", line 174, in _new_conn
    conn = connection.create_connection(
  File "C:\Users\46121\PycharmProjects\CS65_3\vr_env\lib\site-packages\urllib3\util\connection.py", line 95, in create_connection
    raise err
  File "C:\Users\46121\PycharmProjects\CS65_3\vr_env\lib\site-packages\urllib3\util\connection.py", line 85, in create_connection
    sock.connect(sa)
ConnectionRefusedError: [WinError 10061] No connection could be made because the target machine actively refused it

During handling of the above exception, another exception occurred:

Traceback (most recent call last):
  File "C:\Users\46121\PycharmProjects\CS65_3\vr_env\lib\site-packages\urllib3\connectionpool.py", line 703, in urlopen
    httplib_response = self._make_request(
  File "C:\Users\46121\PycharmProjects\CS65_3\vr_env\lib\site-packages\urllib3\connectionpool.py", line 398, in _make_request
    conn.request(method, url, **httplib_request_kw)
  File "C:\Users\46121\PycharmProjects\CS65_3\vr_env\lib\site-packages\urllib3\connection.py", line 239, in request
    super(HTTPConnection, self).request(method, url, body=body, headers=headers)
  File "C:\Users\46121\AppData\Local\Programs\Python\Python38\lib\http\client.py", line 1240, in request
    self._send_request(method, url, body, headers, encode_chunked)
  File "C:\Users\46121\AppData\Local\Programs\Python\Python38\lib\http\client.py", line 1286, in _send_request
    self.endheaders(body, encode_chunked=encode_chunked)
  File "C:\Users\46121\AppData\Local\Programs\Python\Python38\lib\http\client.py", line 1235, in endheaders
    self._send_output(message_body, encode_chunked=encode_chunked)
  File "C:\Users\46121\AppData\Local\Programs\Python\Python38\lib\http\client.py", line 1006, in _send_output
    self.send(msg)
  File "C:\Users\46121\AppData\Local\Programs\Python\Python38\lib\http\client.py", line 946, in send
    self.connect()
  File "C:\Users\46121\PycharmProjects\CS65_3\vr_env\lib\site-packages\urllib3\connection.py", line 205, in connect
    conn = self._new_conn()
  File "C:\Users\46121\PycharmProjects\CS65_3\vr_env\lib\site-packages\urllib3\connection.py", line 186, in _new_conn
    raise NewConnectionError(
urllib3.exceptions.NewConnectionError: <urllib3.connection.HTTPConnection object at 0x00000209A78BC8E0>: Failed to establish a new connection: [WinError 10061] No connection could be made because the target machine actively refused it

During handling of the above exception, another exception occurred:

Traceback (most recent call last):
  File "C:\Users\46121\PycharmProjects\CS65_3\vr_env\lib\site-packages\requests\adapters.py", line 440, in send
    resp = conn.urlopen(
  File "C:\Users\46121\PycharmProjects\CS65_3\vr_env\lib\site-packages\urllib3\connectionpool.py", line 785, in urlopen
    retries = retries.increment(
  File "C:\Users\46121\PycharmProjects\CS65_3\vr_env\lib\site-packages\urllib3\util\retry.py", line 592, in increment
    raise MaxRetryError(_pool, url, error or ResponseError(cause))
urllib3.exceptions.MaxRetryError: HTTPConnectionPool(host='127.0.0.1', port=6800): Max retries exceeded with url: / (Caused by NewConnectionError('<urllib3.connection.HTTPConnection object at 0x00000209A78BC8E0>: Failed to establish a new connection: [WinError 10061] No connection could be made because the target machine actively refused it'))

During handling of the above exception, another exception occurred:

Traceback (most recent call last):
  File "C:\Users\46121\PycharmProjects\CS65_3\cs65_4\cs65_5\polls\utils.py", line 82, in wrapper
    result = func(*args, **kwargs)
  File "C:\Users\46121\PycharmProjects\CS65_3\vr_env\lib\site-packages\django\views\decorators\csrf.py", line 54, in wrapped_view
    return view_func(*args, **kwargs)
  File "C:\Users\46121\PycharmProjects\CS65_3\vr_env\lib\site-packages\django\views\generic\base.py", line 69, in view
    return self.dispatch(request, *args, **kwargs)
  File "C:\Users\46121\PycharmProjects\CS65_3\vr_env\lib\site-packages\rest_framework\views.py", line 509, in dispatch
    response = self.handle_exception(exc)
  File "C:\Users\46121\PycharmProjects\CS65_3\vr_env\lib\site-packages\rest_framework\views.py", line 469, in handle_exception
    self.raise_uncaught_exception(exc)
  File "C:\Users\46121\PycharmProjects\CS65_3\vr_env\lib\site-packages\rest_framework\views.py", line 480, in raise_uncaught_exception
    raise exc
  File "C:\Users\46121\PycharmProjects\CS65_3\vr_env\lib\site-packages\rest_framework\views.py", line 506, in dispatch
    response = handler(request, *args, **kwargs)
  File "C:\Users\46121\PycharmProjects\CS65_3\vr_env\lib\site-packages\rest_framework\decorators.py", line 50, in handler
    return func(*args, **kwargs)
  File "C:\Users\46121\PycharmProjects\CS65_3\cs65_4\cs65_5\polls\views.py", line 170, in client_status
    requests.get(scrapyd_url(client.ip, client.port), timeout=3)
  File "C:\Users\46121\PycharmProjects\CS65_3\vr_env\lib\site-packages\requests\api.py", line 75, in get
    return request('get', url, params=params, **kwargs)
  File "C:\Users\46121\PycharmProjects\CS65_3\vr_env\lib\site-packages\requests\api.py", line 61, in request
    return session.request(method=method, url=url, **kwargs)
  File "C:\Users\46121\PycharmProjects\CS65_3\vr_env\lib\site-packages\requests\sessions.py", line 529, in request
    resp = self.send(prep, **send_kwargs)
  File "C:\Users\46121\PycharmProjects\CS65_3\vr_env\lib\site-packages\requests\sessions.py", line 645, in send
    r = adapter.send(request, **kwargs)
  File "C:\Users\46121\PycharmProjects\CS65_3\vr_env\lib\site-packages\requests\adapters.py", line 519, in send
    raise ConnectionError(e, request=request)
requests.exceptions.ConnectionError: HTTPConnectionPool(host='127.0.0.1', port=6800): Max retries exceeded with url: / (Caused by NewConnectionError('<urllib3.connection.HTTPConnection object at 0x00000209A78BC8E0>: Failed to establish a new connection: [WinError 10061] No connection could be made because the target machine actively refused it'))
ERROR - 2022-05-24 19:39:04,610 - process: 60056 - utils.py - polls.utils - 84 - utils - HTTPConnectionPool(host='127.0.0.1', port=6800): Max retries exceeded with url: / (Caused by NewConnectionError('<urllib3.connection.HTTPConnection object at 0x00000209A7D1B550>: Failed to establish a new connection: [WinError 10061] No connection could be made because the target machine actively refused it'))
Traceback (most recent call last):
  File "C:\Users\46121\PycharmProjects\CS65_3\vr_env\lib\site-packages\urllib3\connection.py", line 174, in _new_conn
    conn = connection.create_connection(
  File "C:\Users\46121\PycharmProjects\CS65_3\vr_env\lib\site-packages\urllib3\util\connection.py", line 95, in create_connection
    raise err
  File "C:\Users\46121\PycharmProjects\CS65_3\vr_env\lib\site-packages\urllib3\util\connection.py", line 85, in create_connection
    sock.connect(sa)
ConnectionRefusedError: [WinError 10061] No connection could be made because the target machine actively refused it

During handling of the above exception, another exception occurred:

Traceback (most recent call last):
  File "C:\Users\46121\PycharmProjects\CS65_3\vr_env\lib\site-packages\urllib3\connectionpool.py", line 703, in urlopen
    httplib_response = self._make_request(
  File "C:\Users\46121\PycharmProjects\CS65_3\vr_env\lib\site-packages\urllib3\connectionpool.py", line 398, in _make_request
    conn.request(method, url, **httplib_request_kw)
  File "C:\Users\46121\PycharmProjects\CS65_3\vr_env\lib\site-packages\urllib3\connection.py", line 239, in request
    super(HTTPConnection, self).request(method, url, body=body, headers=headers)
  File "C:\Users\46121\AppData\Local\Programs\Python\Python38\lib\http\client.py", line 1240, in request
    self._send_request(method, url, body, headers, encode_chunked)
  File "C:\Users\46121\AppData\Local\Programs\Python\Python38\lib\http\client.py", line 1286, in _send_request
    self.endheaders(body, encode_chunked=encode_chunked)
  File "C:\Users\46121\AppData\Local\Programs\Python\Python38\lib\http\client.py", line 1235, in endheaders
    self._send_output(message_body, encode_chunked=encode_chunked)
  File "C:\Users\46121\AppData\Local\Programs\Python\Python38\lib\http\client.py", line 1006, in _send_output
    self.send(msg)
  File "C:\Users\46121\AppData\Local\Programs\Python\Python38\lib\http\client.py", line 946, in send
    self.connect()
  File "C:\Users\46121\PycharmProjects\CS65_3\vr_env\lib\site-packages\urllib3\connection.py", line 205, in connect
    conn = self._new_conn()
  File "C:\Users\46121\PycharmProjects\CS65_3\vr_env\lib\site-packages\urllib3\connection.py", line 186, in _new_conn
    raise NewConnectionError(
urllib3.exceptions.NewConnectionError: <urllib3.connection.HTTPConnection object at 0x00000209A7D1B550>: Failed to establish a new connection: [WinError 10061] No connection could be made because the target machine actively refused it

During handling of the above exception, another exception occurred:

Traceback (most recent call last):
  File "C:\Users\46121\PycharmProjects\CS65_3\vr_env\lib\site-packages\requests\adapters.py", line 440, in send
    resp = conn.urlopen(
  File "C:\Users\46121\PycharmProjects\CS65_3\vr_env\lib\site-packages\urllib3\connectionpool.py", line 785, in urlopen
    retries = retries.increment(
  File "C:\Users\46121\PycharmProjects\CS65_3\vr_env\lib\site-packages\urllib3\util\retry.py", line 592, in increment
    raise MaxRetryError(_pool, url, error or ResponseError(cause))
urllib3.exceptions.MaxRetryError: HTTPConnectionPool(host='127.0.0.1', port=6800): Max retries exceeded with url: / (Caused by NewConnectionError('<urllib3.connection.HTTPConnection object at 0x00000209A7D1B550>: Failed to establish a new connection: [WinError 10061] No connection could be made because the target machine actively refused it'))

During handling of the above exception, another exception occurred:

Traceback (most recent call last):
  File "C:\Users\46121\PycharmProjects\CS65_3\cs65_4\cs65_5\polls\utils.py", line 82, in wrapper
    result = func(*args, **kwargs)
  File "C:\Users\46121\PycharmProjects\CS65_3\vr_env\lib\site-packages\django\views\decorators\csrf.py", line 54, in wrapped_view
    return view_func(*args, **kwargs)
  File "C:\Users\46121\PycharmProjects\CS65_3\vr_env\lib\site-packages\django\views\generic\base.py", line 69, in view
    return self.dispatch(request, *args, **kwargs)
  File "C:\Users\46121\PycharmProjects\CS65_3\vr_env\lib\site-packages\rest_framework\views.py", line 509, in dispatch
    response = self.handle_exception(exc)
  File "C:\Users\46121\PycharmProjects\CS65_3\vr_env\lib\site-packages\rest_framework\views.py", line 469, in handle_exception
    self.raise_uncaught_exception(exc)
  File "C:\Users\46121\PycharmProjects\CS65_3\vr_env\lib\site-packages\rest_framework\views.py", line 480, in raise_uncaught_exception
    raise exc
  File "C:\Users\46121\PycharmProjects\CS65_3\vr_env\lib\site-packages\rest_framework\views.py", line 506, in dispatch
    response = handler(request, *args, **kwargs)
  File "C:\Users\46121\PycharmProjects\CS65_3\vr_env\lib\site-packages\rest_framework\decorators.py", line 50, in handler
    return func(*args, **kwargs)
  File "C:\Users\46121\PycharmProjects\CS65_3\cs65_4\cs65_5\polls\views.py", line 170, in client_status
    requests.get(scrapyd_url(client.ip, client.port), timeout=3)
  File "C:\Users\46121\PycharmProjects\CS65_3\vr_env\lib\site-packages\requests\api.py", line 75, in get
    return request('get', url, params=params, **kwargs)
  File "C:\Users\46121\PycharmProjects\CS65_3\vr_env\lib\site-packages\requests\api.py", line 61, in request
    return session.request(method=method, url=url, **kwargs)
  File "C:\Users\46121\PycharmProjects\CS65_3\vr_env\lib\site-packages\requests\sessions.py", line 529, in request
    resp = self.send(prep, **send_kwargs)
  File "C:\Users\46121\PycharmProjects\CS65_3\vr_env\lib\site-packages\requests\sessions.py", line 645, in send
    r = adapter.send(request, **kwargs)
  File "C:\Users\46121\PycharmProjects\CS65_3\vr_env\lib\site-packages\requests\adapters.py", line 519, in send
    raise ConnectionError(e, request=request)
requests.exceptions.ConnectionError: HTTPConnectionPool(host='127.0.0.1', port=6800): Max retries exceeded with url: / (Caused by NewConnectionError('<urllib3.connection.HTTPConnection object at 0x00000209A7D1B550>: Failed to establish a new connection: [WinError 10061] No connection could be made because the target machine actively refused it'))
ERROR - 2022-05-24 19:39:31,351 - process: 60056 - utils.py - polls.utils - 84 - utils - HTTPConnectionPool(host='127.0.0.1', port=6800): Max retries exceeded with url: / (Caused by NewConnectionError('<urllib3.connection.HTTPConnection object at 0x00000209A7BE7B80>: Failed to establish a new connection: [WinError 10061] No connection could be made because the target machine actively refused it'))
Traceback (most recent call last):
  File "C:\Users\46121\PycharmProjects\CS65_3\vr_env\lib\site-packages\urllib3\connection.py", line 174, in _new_conn
    conn = connection.create_connection(
  File "C:\Users\46121\PycharmProjects\CS65_3\vr_env\lib\site-packages\urllib3\util\connection.py", line 95, in create_connection
    raise err
  File "C:\Users\46121\PycharmProjects\CS65_3\vr_env\lib\site-packages\urllib3\util\connection.py", line 85, in create_connection
    sock.connect(sa)
ConnectionRefusedError: [WinError 10061] No connection could be made because the target machine actively refused it

During handling of the above exception, another exception occurred:

Traceback (most recent call last):
  File "C:\Users\46121\PycharmProjects\CS65_3\vr_env\lib\site-packages\urllib3\connectionpool.py", line 703, in urlopen
    httplib_response = self._make_request(
  File "C:\Users\46121\PycharmProjects\CS65_3\vr_env\lib\site-packages\urllib3\connectionpool.py", line 398, in _make_request
    conn.request(method, url, **httplib_request_kw)
  File "C:\Users\46121\PycharmProjects\CS65_3\vr_env\lib\site-packages\urllib3\connection.py", line 239, in request
    super(HTTPConnection, self).request(method, url, body=body, headers=headers)
  File "C:\Users\46121\AppData\Local\Programs\Python\Python38\lib\http\client.py", line 1240, in request
    self._send_request(method, url, body, headers, encode_chunked)
  File "C:\Users\46121\AppData\Local\Programs\Python\Python38\lib\http\client.py", line 1286, in _send_request
    self.endheaders(body, encode_chunked=encode_chunked)
  File "C:\Users\46121\AppData\Local\Programs\Python\Python38\lib\http\client.py", line 1235, in endheaders
    self._send_output(message_body, encode_chunked=encode_chunked)
  File "C:\Users\46121\AppData\Local\Programs\Python\Python38\lib\http\client.py", line 1006, in _send_output
    self.send(msg)
  File "C:\Users\46121\AppData\Local\Programs\Python\Python38\lib\http\client.py", line 946, in send
    self.connect()
  File "C:\Users\46121\PycharmProjects\CS65_3\vr_env\lib\site-packages\urllib3\connection.py", line 205, in connect
    conn = self._new_conn()
  File "C:\Users\46121\PycharmProjects\CS65_3\vr_env\lib\site-packages\urllib3\connection.py", line 186, in _new_conn
    raise NewConnectionError(
urllib3.exceptions.NewConnectionError: <urllib3.connection.HTTPConnection object at 0x00000209A7BE7B80>: Failed to establish a new connection: [WinError 10061] No connection could be made because the target machine actively refused it

During handling of the above exception, another exception occurred:

Traceback (most recent call last):
  File "C:\Users\46121\PycharmProjects\CS65_3\vr_env\lib\site-packages\requests\adapters.py", line 440, in send
    resp = conn.urlopen(
  File "C:\Users\46121\PycharmProjects\CS65_3\vr_env\lib\site-packages\urllib3\connectionpool.py", line 785, in urlopen
    retries = retries.increment(
  File "C:\Users\46121\PycharmProjects\CS65_3\vr_env\lib\site-packages\urllib3\util\retry.py", line 592, in increment
    raise MaxRetryError(_pool, url, error or ResponseError(cause))
urllib3.exceptions.MaxRetryError: HTTPConnectionPool(host='127.0.0.1', port=6800): Max retries exceeded with url: / (Caused by NewConnectionError('<urllib3.connection.HTTPConnection object at 0x00000209A7BE7B80>: Failed to establish a new connection: [WinError 10061] No connection could be made because the target machine actively refused it'))

During handling of the above exception, another exception occurred:

Traceback (most recent call last):
  File "C:\Users\46121\PycharmProjects\CS65_3\cs65_4\cs65_5\polls\utils.py", line 82, in wrapper
    result = func(*args, **kwargs)
  File "C:\Users\46121\PycharmProjects\CS65_3\vr_env\lib\site-packages\django\views\decorators\csrf.py", line 54, in wrapped_view
    return view_func(*args, **kwargs)
  File "C:\Users\46121\PycharmProjects\CS65_3\vr_env\lib\site-packages\django\views\generic\base.py", line 69, in view
    return self.dispatch(request, *args, **kwargs)
  File "C:\Users\46121\PycharmProjects\CS65_3\vr_env\lib\site-packages\rest_framework\views.py", line 509, in dispatch
    response = self.handle_exception(exc)
  File "C:\Users\46121\PycharmProjects\CS65_3\vr_env\lib\site-packages\rest_framework\views.py", line 469, in handle_exception
    self.raise_uncaught_exception(exc)
  File "C:\Users\46121\PycharmProjects\CS65_3\vr_env\lib\site-packages\rest_framework\views.py", line 480, in raise_uncaught_exception
    raise exc
  File "C:\Users\46121\PycharmProjects\CS65_3\vr_env\lib\site-packages\rest_framework\views.py", line 506, in dispatch
    response = handler(request, *args, **kwargs)
  File "C:\Users\46121\PycharmProjects\CS65_3\vr_env\lib\site-packages\rest_framework\decorators.py", line 50, in handler
    return func(*args, **kwargs)
  File "C:\Users\46121\PycharmProjects\CS65_3\cs65_4\cs65_5\polls\views.py", line 170, in client_status
    requests.get(scrapyd_url(client.ip, client.port), timeout=3)
  File "C:\Users\46121\PycharmProjects\CS65_3\vr_env\lib\site-packages\requests\api.py", line 75, in get
    return request('get', url, params=params, **kwargs)
  File "C:\Users\46121\PycharmProjects\CS65_3\vr_env\lib\site-packages\requests\api.py", line 61, in request
    return session.request(method=method, url=url, **kwargs)
  File "C:\Users\46121\PycharmProjects\CS65_3\vr_env\lib\site-packages\requests\sessions.py", line 529, in request
    resp = self.send(prep, **send_kwargs)
  File "C:\Users\46121\PycharmProjects\CS65_3\vr_env\lib\site-packages\requests\sessions.py", line 645, in send
    r = adapter.send(request, **kwargs)
  File "C:\Users\46121\PycharmProjects\CS65_3\vr_env\lib\site-packages\requests\adapters.py", line 519, in send
    raise ConnectionError(e, request=request)
requests.exceptions.ConnectionError: HTTPConnectionPool(host='127.0.0.1', port=6800): Max retries exceeded with url: / (Caused by NewConnectionError('<urllib3.connection.HTTPConnection object at 0x00000209A7BE7B80>: Failed to establish a new connection: [WinError 10061] No connection could be made because the target machine actively refused it'))
ERROR - 2022-05-24 19:49:16,795 - process: 60056 - utils.py - polls.utils - 84 - utils - HTTPConnectionPool(host='127.0.0.1', port=6800): Max retries exceeded with url: / (Caused by NewConnectionError('<urllib3.connection.HTTPConnection object at 0x00000209A7A5EAF0>: Failed to establish a new connection: [WinError 10061] No connection could be made because the target machine actively refused it'))
Traceback (most recent call last):
  File "C:\Users\46121\PycharmProjects\CS65_3\vr_env\lib\site-packages\urllib3\connection.py", line 174, in _new_conn
    conn = connection.create_connection(
  File "C:\Users\46121\PycharmProjects\CS65_3\vr_env\lib\site-packages\urllib3\util\connection.py", line 95, in create_connection
    raise err
  File "C:\Users\46121\PycharmProjects\CS65_3\vr_env\lib\site-packages\urllib3\util\connection.py", line 85, in create_connection
    sock.connect(sa)
ConnectionRefusedError: [WinError 10061] No connection could be made because the target machine actively refused it

During handling of the above exception, another exception occurred:

Traceback (most recent call last):
  File "C:\Users\46121\PycharmProjects\CS65_3\vr_env\lib\site-packages\urllib3\connectionpool.py", line 703, in urlopen
    httplib_response = self._make_request(
  File "C:\Users\46121\PycharmProjects\CS65_3\vr_env\lib\site-packages\urllib3\connectionpool.py", line 398, in _make_request
    conn.request(method, url, **httplib_request_kw)
  File "C:\Users\46121\PycharmProjects\CS65_3\vr_env\lib\site-packages\urllib3\connection.py", line 239, in request
    super(HTTPConnection, self).request(method, url, body=body, headers=headers)
  File "C:\Users\46121\AppData\Local\Programs\Python\Python38\lib\http\client.py", line 1240, in request
    self._send_request(method, url, body, headers, encode_chunked)
  File "C:\Users\46121\AppData\Local\Programs\Python\Python38\lib\http\client.py", line 1286, in _send_request
    self.endheaders(body, encode_chunked=encode_chunked)
  File "C:\Users\46121\AppData\Local\Programs\Python\Python38\lib\http\client.py", line 1235, in endheaders
    self._send_output(message_body, encode_chunked=encode_chunked)
  File "C:\Users\46121\AppData\Local\Programs\Python\Python38\lib\http\client.py", line 1006, in _send_output
    self.send(msg)
  File "C:\Users\46121\AppData\Local\Programs\Python\Python38\lib\http\client.py", line 946, in send
    self.connect()
  File "C:\Users\46121\PycharmProjects\CS65_3\vr_env\lib\site-packages\urllib3\connection.py", line 205, in connect
    conn = self._new_conn()
  File "C:\Users\46121\PycharmProjects\CS65_3\vr_env\lib\site-packages\urllib3\connection.py", line 186, in _new_conn
    raise NewConnectionError(
urllib3.exceptions.NewConnectionError: <urllib3.connection.HTTPConnection object at 0x00000209A7A5EAF0>: Failed to establish a new connection: [WinError 10061] No connection could be made because the target machine actively refused it

During handling of the above exception, another exception occurred:

Traceback (most recent call last):
  File "C:\Users\46121\PycharmProjects\CS65_3\vr_env\lib\site-packages\requests\adapters.py", line 440, in send
    resp = conn.urlopen(
  File "C:\Users\46121\PycharmProjects\CS65_3\vr_env\lib\site-packages\urllib3\connectionpool.py", line 785, in urlopen
    retries = retries.increment(
  File "C:\Users\46121\PycharmProjects\CS65_3\vr_env\lib\site-packages\urllib3\util\retry.py", line 592, in increment
    raise MaxRetryError(_pool, url, error or ResponseError(cause))
urllib3.exceptions.MaxRetryError: HTTPConnectionPool(host='127.0.0.1', port=6800): Max retries exceeded with url: / (Caused by NewConnectionError('<urllib3.connection.HTTPConnection object at 0x00000209A7A5EAF0>: Failed to establish a new connection: [WinError 10061] No connection could be made because the target machine actively refused it'))

During handling of the above exception, another exception occurred:

Traceback (most recent call last):
  File "C:\Users\46121\PycharmProjects\CS65_3\cs65_4\cs65_5\polls\utils.py", line 82, in wrapper
    result = func(*args, **kwargs)
  File "C:\Users\46121\PycharmProjects\CS65_3\vr_env\lib\site-packages\django\views\decorators\csrf.py", line 54, in wrapped_view
    return view_func(*args, **kwargs)
  File "C:\Users\46121\PycharmProjects\CS65_3\vr_env\lib\site-packages\django\views\generic\base.py", line 69, in view
    return self.dispatch(request, *args, **kwargs)
  File "C:\Users\46121\PycharmProjects\CS65_3\vr_env\lib\site-packages\rest_framework\views.py", line 509, in dispatch
    response = self.handle_exception(exc)
  File "C:\Users\46121\PycharmProjects\CS65_3\vr_env\lib\site-packages\rest_framework\views.py", line 469, in handle_exception
    self.raise_uncaught_exception(exc)
  File "C:\Users\46121\PycharmProjects\CS65_3\vr_env\lib\site-packages\rest_framework\views.py", line 480, in raise_uncaught_exception
    raise exc
  File "C:\Users\46121\PycharmProjects\CS65_3\vr_env\lib\site-packages\rest_framework\views.py", line 506, in dispatch
    response = handler(request, *args, **kwargs)
  File "C:\Users\46121\PycharmProjects\CS65_3\vr_env\lib\site-packages\rest_framework\decorators.py", line 50, in handler
    return func(*args, **kwargs)
  File "C:\Users\46121\PycharmProjects\CS65_3\cs65_4\cs65_5\polls\views.py", line 170, in client_status
    requests.get(scrapyd_url(client.ip, client.port), timeout=3)
  File "C:\Users\46121\PycharmProjects\CS65_3\vr_env\lib\site-packages\requests\api.py", line 75, in get
    return request('get', url, params=params, **kwargs)
  File "C:\Users\46121\PycharmProjects\CS65_3\vr_env\lib\site-packages\requests\api.py", line 61, in request
    return session.request(method=method, url=url, **kwargs)
  File "C:\Users\46121\PycharmProjects\CS65_3\vr_env\lib\site-packages\requests\sessions.py", line 529, in request
    resp = self.send(prep, **send_kwargs)
  File "C:\Users\46121\PycharmProjects\CS65_3\vr_env\lib\site-packages\requests\sessions.py", line 645, in send
    r = adapter.send(request, **kwargs)
  File "C:\Users\46121\PycharmProjects\CS65_3\vr_env\lib\site-packages\requests\adapters.py", line 519, in send
    raise ConnectionError(e, request=request)
requests.exceptions.ConnectionError: HTTPConnectionPool(host='127.0.0.1', port=6800): Max retries exceeded with url: / (Caused by NewConnectionError('<urllib3.connection.HTTPConnection object at 0x00000209A7A5EAF0>: Failed to establish a new connection: [WinError 10061] No connection could be made because the target machine actively refused it'))
ERROR - 2022-05-24 21:02:03,871 - process: 60056 - utils.py - polls.utils - 84 - utils - HTTPConnectionPool(host='127.0.0.1', port=6800): Max retries exceeded with url: / (Caused by NewConnectionError('<urllib3.connection.HTTPConnection object at 0x00000209A7ABBD00>: Failed to establish a new connection: [WinError 10061] No connection could be made because the target machine actively refused it'))
Traceback (most recent call last):
  File "C:\Users\46121\PycharmProjects\CS65_3\vr_env\lib\site-packages\urllib3\connection.py", line 174, in _new_conn
    conn = connection.create_connection(
  File "C:\Users\46121\PycharmProjects\CS65_3\vr_env\lib\site-packages\urllib3\util\connection.py", line 95, in create_connection
    raise err
  File "C:\Users\46121\PycharmProjects\CS65_3\vr_env\lib\site-packages\urllib3\util\connection.py", line 85, in create_connection
    sock.connect(sa)
ConnectionRefusedError: [WinError 10061] No connection could be made because the target machine actively refused it

During handling of the above exception, another exception occurred:

Traceback (most recent call last):
  File "C:\Users\46121\PycharmProjects\CS65_3\vr_env\lib\site-packages\urllib3\connectionpool.py", line 703, in urlopen
    httplib_response = self._make_request(
  File "C:\Users\46121\PycharmProjects\CS65_3\vr_env\lib\site-packages\urllib3\connectionpool.py", line 398, in _make_request
    conn.request(method, url, **httplib_request_kw)
  File "C:\Users\46121\PycharmProjects\CS65_3\vr_env\lib\site-packages\urllib3\connection.py", line 239, in request
    super(HTTPConnection, self).request(method, url, body=body, headers=headers)
  File "C:\Users\46121\AppData\Local\Programs\Python\Python38\lib\http\client.py", line 1240, in request
    self._send_request(method, url, body, headers, encode_chunked)
  File "C:\Users\46121\AppData\Local\Programs\Python\Python38\lib\http\client.py", line 1286, in _send_request
    self.endheaders(body, encode_chunked=encode_chunked)
  File "C:\Users\46121\AppData\Local\Programs\Python\Python38\lib\http\client.py", line 1235, in endheaders
    self._send_output(message_body, encode_chunked=encode_chunked)
  File "C:\Users\46121\AppData\Local\Programs\Python\Python38\lib\http\client.py", line 1006, in _send_output
    self.send(msg)
  File "C:\Users\46121\AppData\Local\Programs\Python\Python38\lib\http\client.py", line 946, in send
    self.connect()
  File "C:\Users\46121\PycharmProjects\CS65_3\vr_env\lib\site-packages\urllib3\connection.py", line 205, in connect
    conn = self._new_conn()
  File "C:\Users\46121\PycharmProjects\CS65_3\vr_env\lib\site-packages\urllib3\connection.py", line 186, in _new_conn
    raise NewConnectionError(
urllib3.exceptions.NewConnectionError: <urllib3.connection.HTTPConnection object at 0x00000209A7ABBD00>: Failed to establish a new connection: [WinError 10061] No connection could be made because the target machine actively refused it

During handling of the above exception, another exception occurred:

Traceback (most recent call last):
  File "C:\Users\46121\PycharmProjects\CS65_3\vr_env\lib\site-packages\requests\adapters.py", line 440, in send
    resp = conn.urlopen(
  File "C:\Users\46121\PycharmProjects\CS65_3\vr_env\lib\site-packages\urllib3\connectionpool.py", line 785, in urlopen
    retries = retries.increment(
  File "C:\Users\46121\PycharmProjects\CS65_3\vr_env\lib\site-packages\urllib3\util\retry.py", line 592, in increment
    raise MaxRetryError(_pool, url, error or ResponseError(cause))
urllib3.exceptions.MaxRetryError: HTTPConnectionPool(host='127.0.0.1', port=6800): Max retries exceeded with url: / (Caused by NewConnectionError('<urllib3.connection.HTTPConnection object at 0x00000209A7ABBD00>: Failed to establish a new connection: [WinError 10061] No connection could be made because the target machine actively refused it'))

During handling of the above exception, another exception occurred:

Traceback (most recent call last):
  File "C:\Users\46121\PycharmProjects\CS65_3\cs65_4\cs65_5\polls\utils.py", line 82, in wrapper
    result = func(*args, **kwargs)
  File "C:\Users\46121\PycharmProjects\CS65_3\vr_env\lib\site-packages\django\views\decorators\csrf.py", line 54, in wrapped_view
    return view_func(*args, **kwargs)
  File "C:\Users\46121\PycharmProjects\CS65_3\vr_env\lib\site-packages\django\views\generic\base.py", line 69, in view
    return self.dispatch(request, *args, **kwargs)
  File "C:\Users\46121\PycharmProjects\CS65_3\vr_env\lib\site-packages\rest_framework\views.py", line 509, in dispatch
    response = self.handle_exception(exc)
  File "C:\Users\46121\PycharmProjects\CS65_3\vr_env\lib\site-packages\rest_framework\views.py", line 469, in handle_exception
    self.raise_uncaught_exception(exc)
  File "C:\Users\46121\PycharmProjects\CS65_3\vr_env\lib\site-packages\rest_framework\views.py", line 480, in raise_uncaught_exception
    raise exc
  File "C:\Users\46121\PycharmProjects\CS65_3\vr_env\lib\site-packages\rest_framework\views.py", line 506, in dispatch
    response = handler(request, *args, **kwargs)
  File "C:\Users\46121\PycharmProjects\CS65_3\vr_env\lib\site-packages\rest_framework\decorators.py", line 50, in handler
    return func(*args, **kwargs)
  File "C:\Users\46121\PycharmProjects\CS65_3\cs65_4\cs65_5\polls\views.py", line 170, in client_status
    requests.get(scrapyd_url(client.ip, client.port), timeout=3)
  File "C:\Users\46121\PycharmProjects\CS65_3\vr_env\lib\site-packages\requests\api.py", line 75, in get
    return request('get', url, params=params, **kwargs)
  File "C:\Users\46121\PycharmProjects\CS65_3\vr_env\lib\site-packages\requests\api.py", line 61, in request
    return session.request(method=method, url=url, **kwargs)
  File "C:\Users\46121\PycharmProjects\CS65_3\vr_env\lib\site-packages\requests\sessions.py", line 529, in request
    resp = self.send(prep, **send_kwargs)
  File "C:\Users\46121\PycharmProjects\CS65_3\vr_env\lib\site-packages\requests\sessions.py", line 645, in send
    r = adapter.send(request, **kwargs)
  File "C:\Users\46121\PycharmProjects\CS65_3\vr_env\lib\site-packages\requests\adapters.py", line 519, in send
    raise ConnectionError(e, request=request)
requests.exceptions.ConnectionError: HTTPConnectionPool(host='127.0.0.1', port=6800): Max retries exceeded with url: / (Caused by NewConnectionError('<urllib3.connection.HTTPConnection object at 0x00000209A7ABBD00>: Failed to establish a new connection: [WinError 10061] No connection could be made because the target machine actively refused it'))
ERROR - 2022-05-24 23:04:22,270 - process: 60056 - utils.py - polls.utils - 84 - utils - HTTPConnectionPool(host='127.0.0.1', port=6800): Max retries exceeded with url: / (Caused by NewConnectionError('<urllib3.connection.HTTPConnection object at 0x00000209A7BA7130>: Failed to establish a new connection: [WinError 10061] No connection could be made because the target machine actively refused it'))
Traceback (most recent call last):
  File "C:\Users\46121\PycharmProjects\CS65_3\vr_env\lib\site-packages\urllib3\connection.py", line 174, in _new_conn
    conn = connection.create_connection(
  File "C:\Users\46121\PycharmProjects\CS65_3\vr_env\lib\site-packages\urllib3\util\connection.py", line 95, in create_connection
    raise err
  File "C:\Users\46121\PycharmProjects\CS65_3\vr_env\lib\site-packages\urllib3\util\connection.py", line 85, in create_connection
    sock.connect(sa)
ConnectionRefusedError: [WinError 10061] No connection could be made because the target machine actively refused it

During handling of the above exception, another exception occurred:

Traceback (most recent call last):
  File "C:\Users\46121\PycharmProjects\CS65_3\vr_env\lib\site-packages\urllib3\connectionpool.py", line 703, in urlopen
    httplib_response = self._make_request(
  File "C:\Users\46121\PycharmProjects\CS65_3\vr_env\lib\site-packages\urllib3\connectionpool.py", line 398, in _make_request
    conn.request(method, url, **httplib_request_kw)
  File "C:\Users\46121\PycharmProjects\CS65_3\vr_env\lib\site-packages\urllib3\connection.py", line 239, in request
    super(HTTPConnection, self).request(method, url, body=body, headers=headers)
  File "C:\Users\46121\AppData\Local\Programs\Python\Python38\lib\http\client.py", line 1240, in request
    self._send_request(method, url, body, headers, encode_chunked)
  File "C:\Users\46121\AppData\Local\Programs\Python\Python38\lib\http\client.py", line 1286, in _send_request
    self.endheaders(body, encode_chunked=encode_chunked)
  File "C:\Users\46121\AppData\Local\Programs\Python\Python38\lib\http\client.py", line 1235, in endheaders
    self._send_output(message_body, encode_chunked=encode_chunked)
  File "C:\Users\46121\AppData\Local\Programs\Python\Python38\lib\http\client.py", line 1006, in _send_output
    self.send(msg)
  File "C:\Users\46121\AppData\Local\Programs\Python\Python38\lib\http\client.py", line 946, in send
    self.connect()
  File "C:\Users\46121\PycharmProjects\CS65_3\vr_env\lib\site-packages\urllib3\connection.py", line 205, in connect
    conn = self._new_conn()
  File "C:\Users\46121\PycharmProjects\CS65_3\vr_env\lib\site-packages\urllib3\connection.py", line 186, in _new_conn
    raise NewConnectionError(
urllib3.exceptions.NewConnectionError: <urllib3.connection.HTTPConnection object at 0x00000209A7BA7130>: Failed to establish a new connection: [WinError 10061] No connection could be made because the target machine actively refused it

During handling of the above exception, another exception occurred:

Traceback (most recent call last):
  File "C:\Users\46121\PycharmProjects\CS65_3\vr_env\lib\site-packages\requests\adapters.py", line 440, in send
    resp = conn.urlopen(
  File "C:\Users\46121\PycharmProjects\CS65_3\vr_env\lib\site-packages\urllib3\connectionpool.py", line 785, in urlopen
    retries = retries.increment(
  File "C:\Users\46121\PycharmProjects\CS65_3\vr_env\lib\site-packages\urllib3\util\retry.py", line 592, in increment
    raise MaxRetryError(_pool, url, error or ResponseError(cause))
urllib3.exceptions.MaxRetryError: HTTPConnectionPool(host='127.0.0.1', port=6800): Max retries exceeded with url: / (Caused by NewConnectionError('<urllib3.connection.HTTPConnection object at 0x00000209A7BA7130>: Failed to establish a new connection: [WinError 10061] No connection could be made because the target machine actively refused it'))

During handling of the above exception, another exception occurred:

Traceback (most recent call last):
  File "C:\Users\46121\PycharmProjects\CS65_3\cs65_4\cs65_5\polls\utils.py", line 82, in wrapper
    result = func(*args, **kwargs)
  File "C:\Users\46121\PycharmProjects\CS65_3\vr_env\lib\site-packages\django\views\decorators\csrf.py", line 54, in wrapped_view
    return view_func(*args, **kwargs)
  File "C:\Users\46121\PycharmProjects\CS65_3\vr_env\lib\site-packages\django\views\generic\base.py", line 69, in view
    return self.dispatch(request, *args, **kwargs)
  File "C:\Users\46121\PycharmProjects\CS65_3\vr_env\lib\site-packages\rest_framework\views.py", line 509, in dispatch
    response = self.handle_exception(exc)
  File "C:\Users\46121\PycharmProjects\CS65_3\vr_env\lib\site-packages\rest_framework\views.py", line 469, in handle_exception
    self.raise_uncaught_exception(exc)
  File "C:\Users\46121\PycharmProjects\CS65_3\vr_env\lib\site-packages\rest_framework\views.py", line 480, in raise_uncaught_exception
    raise exc
  File "C:\Users\46121\PycharmProjects\CS65_3\vr_env\lib\site-packages\rest_framework\views.py", line 506, in dispatch
    response = handler(request, *args, **kwargs)
  File "C:\Users\46121\PycharmProjects\CS65_3\vr_env\lib\site-packages\rest_framework\decorators.py", line 50, in handler
    return func(*args, **kwargs)
  File "C:\Users\46121\PycharmProjects\CS65_3\cs65_4\cs65_5\polls\views.py", line 170, in client_status
    requests.get(scrapyd_url(client.ip, client.port), timeout=3)
  File "C:\Users\46121\PycharmProjects\CS65_3\vr_env\lib\site-packages\requests\api.py", line 75, in get
    return request('get', url, params=params, **kwargs)
  File "C:\Users\46121\PycharmProjects\CS65_3\vr_env\lib\site-packages\requests\api.py", line 61, in request
    return session.request(method=method, url=url, **kwargs)
  File "C:\Users\46121\PycharmProjects\CS65_3\vr_env\lib\site-packages\requests\sessions.py", line 529, in request
    resp = self.send(prep, **send_kwargs)
  File "C:\Users\46121\PycharmProjects\CS65_3\vr_env\lib\site-packages\requests\sessions.py", line 645, in send
    r = adapter.send(request, **kwargs)
  File "C:\Users\46121\PycharmProjects\CS65_3\vr_env\lib\site-packages\requests\adapters.py", line 519, in send
    raise ConnectionError(e, request=request)
requests.exceptions.ConnectionError: HTTPConnectionPool(host='127.0.0.1', port=6800): Max retries exceeded with url: / (Caused by NewConnectionError('<urllib3.connection.HTTPConnection object at 0x00000209A7BA7130>: Failed to establish a new connection: [WinError 10061] No connection could be made because the target machine actively refused it'))
ERROR - 2022-05-24 23:04:30,468 - process: 60056 - utils.py - polls.utils - 84 - utils - HTTPConnectionPool(host='127.0.0.1', port=6800): Max retries exceeded with url: / (Caused by NewConnectionError('<urllib3.connection.HTTPConnection object at 0x00000209A7BA7190>: Failed to establish a new connection: [WinError 10061] No connection could be made because the target machine actively refused it'))
Traceback (most recent call last):
  File "C:\Users\46121\PycharmProjects\CS65_3\vr_env\lib\site-packages\urllib3\connection.py", line 174, in _new_conn
    conn = connection.create_connection(
  File "C:\Users\46121\PycharmProjects\CS65_3\vr_env\lib\site-packages\urllib3\util\connection.py", line 95, in create_connection
    raise err
  File "C:\Users\46121\PycharmProjects\CS65_3\vr_env\lib\site-packages\urllib3\util\connection.py", line 85, in create_connection
    sock.connect(sa)
ConnectionRefusedError: [WinError 10061] No connection could be made because the target machine actively refused it

During handling of the above exception, another exception occurred:

Traceback (most recent call last):
  File "C:\Users\46121\PycharmProjects\CS65_3\vr_env\lib\site-packages\urllib3\connectionpool.py", line 703, in urlopen
    httplib_response = self._make_request(
  File "C:\Users\46121\PycharmProjects\CS65_3\vr_env\lib\site-packages\urllib3\connectionpool.py", line 398, in _make_request
    conn.request(method, url, **httplib_request_kw)
  File "C:\Users\46121\PycharmProjects\CS65_3\vr_env\lib\site-packages\urllib3\connection.py", line 239, in request
    super(HTTPConnection, self).request(method, url, body=body, headers=headers)
  File "C:\Users\46121\AppData\Local\Programs\Python\Python38\lib\http\client.py", line 1240, in request
    self._send_request(method, url, body, headers, encode_chunked)
  File "C:\Users\46121\AppData\Local\Programs\Python\Python38\lib\http\client.py", line 1286, in _send_request
    self.endheaders(body, encode_chunked=encode_chunked)
  File "C:\Users\46121\AppData\Local\Programs\Python\Python38\lib\http\client.py", line 1235, in endheaders
    self._send_output(message_body, encode_chunked=encode_chunked)
  File "C:\Users\46121\AppData\Local\Programs\Python\Python38\lib\http\client.py", line 1006, in _send_output
    self.send(msg)
  File "C:\Users\46121\AppData\Local\Programs\Python\Python38\lib\http\client.py", line 946, in send
    self.connect()
  File "C:\Users\46121\PycharmProjects\CS65_3\vr_env\lib\site-packages\urllib3\connection.py", line 205, in connect
    conn = self._new_conn()
  File "C:\Users\46121\PycharmProjects\CS65_3\vr_env\lib\site-packages\urllib3\connection.py", line 186, in _new_conn
    raise NewConnectionError(
urllib3.exceptions.NewConnectionError: <urllib3.connection.HTTPConnection object at 0x00000209A7BA7190>: Failed to establish a new connection: [WinError 10061] No connection could be made because the target machine actively refused it

During handling of the above exception, another exception occurred:

Traceback (most recent call last):
  File "C:\Users\46121\PycharmProjects\CS65_3\vr_env\lib\site-packages\requests\adapters.py", line 440, in send
    resp = conn.urlopen(
  File "C:\Users\46121\PycharmProjects\CS65_3\vr_env\lib\site-packages\urllib3\connectionpool.py", line 785, in urlopen
    retries = retries.increment(
  File "C:\Users\46121\PycharmProjects\CS65_3\vr_env\lib\site-packages\urllib3\util\retry.py", line 592, in increment
    raise MaxRetryError(_pool, url, error or ResponseError(cause))
urllib3.exceptions.MaxRetryError: HTTPConnectionPool(host='127.0.0.1', port=6800): Max retries exceeded with url: / (Caused by NewConnectionError('<urllib3.connection.HTTPConnection object at 0x00000209A7BA7190>: Failed to establish a new connection: [WinError 10061] No connection could be made because the target machine actively refused it'))

During handling of the above exception, another exception occurred:

Traceback (most recent call last):
  File "C:\Users\46121\PycharmProjects\CS65_3\cs65_4\cs65_5\polls\utils.py", line 82, in wrapper
    result = func(*args, **kwargs)
  File "C:\Users\46121\PycharmProjects\CS65_3\vr_env\lib\site-packages\django\views\decorators\csrf.py", line 54, in wrapped_view
    return view_func(*args, **kwargs)
  File "C:\Users\46121\PycharmProjects\CS65_3\vr_env\lib\site-packages\django\views\generic\base.py", line 69, in view
    return self.dispatch(request, *args, **kwargs)
  File "C:\Users\46121\PycharmProjects\CS65_3\vr_env\lib\site-packages\rest_framework\views.py", line 509, in dispatch
    response = self.handle_exception(exc)
  File "C:\Users\46121\PycharmProjects\CS65_3\vr_env\lib\site-packages\rest_framework\views.py", line 469, in handle_exception
    self.raise_uncaught_exception(exc)
  File "C:\Users\46121\PycharmProjects\CS65_3\vr_env\lib\site-packages\rest_framework\views.py", line 480, in raise_uncaught_exception
    raise exc
  File "C:\Users\46121\PycharmProjects\CS65_3\vr_env\lib\site-packages\rest_framework\views.py", line 506, in dispatch
    response = handler(request, *args, **kwargs)
  File "C:\Users\46121\PycharmProjects\CS65_3\vr_env\lib\site-packages\rest_framework\decorators.py", line 50, in handler
    return func(*args, **kwargs)
  File "C:\Users\46121\PycharmProjects\CS65_3\cs65_4\cs65_5\polls\views.py", line 170, in client_status
    requests.get(scrapyd_url(client.ip, client.port), timeout=3)
  File "C:\Users\46121\PycharmProjects\CS65_3\vr_env\lib\site-packages\requests\api.py", line 75, in get
    return request('get', url, params=params, **kwargs)
  File "C:\Users\46121\PycharmProjects\CS65_3\vr_env\lib\site-packages\requests\api.py", line 61, in request
    return session.request(method=method, url=url, **kwargs)
  File "C:\Users\46121\PycharmProjects\CS65_3\vr_env\lib\site-packages\requests\sessions.py", line 529, in request
    resp = self.send(prep, **send_kwargs)
  File "C:\Users\46121\PycharmProjects\CS65_3\vr_env\lib\site-packages\requests\sessions.py", line 645, in send
    r = adapter.send(request, **kwargs)
  File "C:\Users\46121\PycharmProjects\CS65_3\vr_env\lib\site-packages\requests\adapters.py", line 519, in send
    raise ConnectionError(e, request=request)
requests.exceptions.ConnectionError: HTTPConnectionPool(host='127.0.0.1', port=6800): Max retries exceeded with url: / (Caused by NewConnectionError('<urllib3.connection.HTTPConnection object at 0x00000209A7BA7190>: Failed to establish a new connection: [WinError 10061] No connection could be made because the target machine actively refused it'))
ERROR - 2022-05-24 23:04:34,507 - process: 60056 - utils.py - polls.utils - 84 - utils - HTTPConnectionPool(host='127.0.0.1', port=6800): Max retries exceeded with url: / (Caused by NewConnectionError('<urllib3.connection.HTTPConnection object at 0x00000209A78FEB80>: Failed to establish a new connection: [WinError 10061] No connection could be made because the target machine actively refused it'))
Traceback (most recent call last):
  File "C:\Users\46121\PycharmProjects\CS65_3\vr_env\lib\site-packages\urllib3\connection.py", line 174, in _new_conn
    conn = connection.create_connection(
  File "C:\Users\46121\PycharmProjects\CS65_3\vr_env\lib\site-packages\urllib3\util\connection.py", line 95, in create_connection
    raise err
  File "C:\Users\46121\PycharmProjects\CS65_3\vr_env\lib\site-packages\urllib3\util\connection.py", line 85, in create_connection
    sock.connect(sa)
ConnectionRefusedError: [WinError 10061] No connection could be made because the target machine actively refused it

During handling of the above exception, another exception occurred:

Traceback (most recent call last):
  File "C:\Users\46121\PycharmProjects\CS65_3\vr_env\lib\site-packages\urllib3\connectionpool.py", line 703, in urlopen
    httplib_response = self._make_request(
  File "C:\Users\46121\PycharmProjects\CS65_3\vr_env\lib\site-packages\urllib3\connectionpool.py", line 398, in _make_request
    conn.request(method, url, **httplib_request_kw)
  File "C:\Users\46121\PycharmProjects\CS65_3\vr_env\lib\site-packages\urllib3\connection.py", line 239, in request
    super(HTTPConnection, self).request(method, url, body=body, headers=headers)
  File "C:\Users\46121\AppData\Local\Programs\Python\Python38\lib\http\client.py", line 1240, in request
    self._send_request(method, url, body, headers, encode_chunked)
  File "C:\Users\46121\AppData\Local\Programs\Python\Python38\lib\http\client.py", line 1286, in _send_request
    self.endheaders(body, encode_chunked=encode_chunked)
  File "C:\Users\46121\AppData\Local\Programs\Python\Python38\lib\http\client.py", line 1235, in endheaders
    self._send_output(message_body, encode_chunked=encode_chunked)
  File "C:\Users\46121\AppData\Local\Programs\Python\Python38\lib\http\client.py", line 1006, in _send_output
    self.send(msg)
  File "C:\Users\46121\AppData\Local\Programs\Python\Python38\lib\http\client.py", line 946, in send
    self.connect()
  File "C:\Users\46121\PycharmProjects\CS65_3\vr_env\lib\site-packages\urllib3\connection.py", line 205, in connect
    conn = self._new_conn()
  File "C:\Users\46121\PycharmProjects\CS65_3\vr_env\lib\site-packages\urllib3\connection.py", line 186, in _new_conn
    raise NewConnectionError(
urllib3.exceptions.NewConnectionError: <urllib3.connection.HTTPConnection object at 0x00000209A78FEB80>: Failed to establish a new connection: [WinError 10061] No connection could be made because the target machine actively refused it

During handling of the above exception, another exception occurred:

Traceback (most recent call last):
  File "C:\Users\46121\PycharmProjects\CS65_3\vr_env\lib\site-packages\requests\adapters.py", line 440, in send
    resp = conn.urlopen(
  File "C:\Users\46121\PycharmProjects\CS65_3\vr_env\lib\site-packages\urllib3\connectionpool.py", line 785, in urlopen
    retries = retries.increment(
  File "C:\Users\46121\PycharmProjects\CS65_3\vr_env\lib\site-packages\urllib3\util\retry.py", line 592, in increment
    raise MaxRetryError(_pool, url, error or ResponseError(cause))
urllib3.exceptions.MaxRetryError: HTTPConnectionPool(host='127.0.0.1', port=6800): Max retries exceeded with url: / (Caused by NewConnectionError('<urllib3.connection.HTTPConnection object at 0x00000209A78FEB80>: Failed to establish a new connection: [WinError 10061] No connection could be made because the target machine actively refused it'))

During handling of the above exception, another exception occurred:

Traceback (most recent call last):
  File "C:\Users\46121\PycharmProjects\CS65_3\cs65_4\cs65_5\polls\utils.py", line 82, in wrapper
    result = func(*args, **kwargs)
  File "C:\Users\46121\PycharmProjects\CS65_3\vr_env\lib\site-packages\django\views\decorators\csrf.py", line 54, in wrapped_view
    return view_func(*args, **kwargs)
  File "C:\Users\46121\PycharmProjects\CS65_3\vr_env\lib\site-packages\django\views\generic\base.py", line 69, in view
    return self.dispatch(request, *args, **kwargs)
  File "C:\Users\46121\PycharmProjects\CS65_3\vr_env\lib\site-packages\rest_framework\views.py", line 509, in dispatch
    response = self.handle_exception(exc)
  File "C:\Users\46121\PycharmProjects\CS65_3\vr_env\lib\site-packages\rest_framework\views.py", line 469, in handle_exception
    self.raise_uncaught_exception(exc)
  File "C:\Users\46121\PycharmProjects\CS65_3\vr_env\lib\site-packages\rest_framework\views.py", line 480, in raise_uncaught_exception
    raise exc
  File "C:\Users\46121\PycharmProjects\CS65_3\vr_env\lib\site-packages\rest_framework\views.py", line 506, in dispatch
    response = handler(request, *args, **kwargs)
  File "C:\Users\46121\PycharmProjects\CS65_3\vr_env\lib\site-packages\rest_framework\decorators.py", line 50, in handler
    return func(*args, **kwargs)
  File "C:\Users\46121\PycharmProjects\CS65_3\cs65_4\cs65_5\polls\views.py", line 170, in client_status
    requests.get(scrapyd_url(client.ip, client.port), timeout=3)
  File "C:\Users\46121\PycharmProjects\CS65_3\vr_env\lib\site-packages\requests\api.py", line 75, in get
    return request('get', url, params=params, **kwargs)
  File "C:\Users\46121\PycharmProjects\CS65_3\vr_env\lib\site-packages\requests\api.py", line 61, in request
    return session.request(method=method, url=url, **kwargs)
  File "C:\Users\46121\PycharmProjects\CS65_3\vr_env\lib\site-packages\requests\sessions.py", line 529, in request
    resp = self.send(prep, **send_kwargs)
  File "C:\Users\46121\PycharmProjects\CS65_3\vr_env\lib\site-packages\requests\sessions.py", line 645, in send
    r = adapter.send(request, **kwargs)
  File "C:\Users\46121\PycharmProjects\CS65_3\vr_env\lib\site-packages\requests\adapters.py", line 519, in send
    raise ConnectionError(e, request=request)
requests.exceptions.ConnectionError: HTTPConnectionPool(host='127.0.0.1', port=6800): Max retries exceeded with url: / (Caused by NewConnectionError('<urllib3.connection.HTTPConnection object at 0x00000209A78FEB80>: Failed to establish a new connection: [WinError 10061] No connection could be made because the target machine actively refused it'))
