ERROR - 2022-05-17 21:13:17,324 - process: 41476 - utils.py - polls.utils - 76 - utils - HTTPConnectionPool(host='127.0.0.1', port=6800): Max retries exceeded with url: / (Caused by NewConnectionError('<urllib3.connection.HTTPConnection object at 0x000001EC579AEC70>: Failed to establish a new connection: [WinError 10061] No connection could be made because the target machine actively refused it'))
Traceback (most recent call last):
  File "C:\Users\46121\PycharmProjects\CS65_3\vr_env\lib\site-packages\urllib3\connection.py", line 174, in _new_conn
    conn = connection.create_connection(
  File "C:\Users\46121\PycharmProjects\CS65_3\vr_env\lib\site-packages\urllib3\util\connection.py", line 95, in create_connection
    raise err
  File "C:\Users\46121\PycharmProjects\CS65_3\vr_env\lib\site-packages\urllib3\util\connection.py", line 85, in create_connection
    sock.connect(sa)
ConnectionRefusedError: [WinError 10061] No connection could be made because the target machine actively refused it

During handling of the above exception, another exception occurred:

Traceback (most recent call last):
  File "C:\Users\46121\PycharmProjects\CS65_3\vr_env\lib\site-packages\urllib3\connectionpool.py", line 703, in urlopen
    httplib_response = self._make_request(
  File "C:\Users\46121\PycharmProjects\CS65_3\vr_env\lib\site-packages\urllib3\connectionpool.py", line 398, in _make_request
    conn.request(method, url, **httplib_request_kw)
  File "C:\Users\46121\PycharmProjects\CS65_3\vr_env\lib\site-packages\urllib3\connection.py", line 239, in request
    super(HTTPConnection, self).request(method, url, body=body, headers=headers)
  File "C:\Users\46121\AppData\Local\Programs\Python\Python38\lib\http\client.py", line 1240, in request
    self._send_request(method, url, body, headers, encode_chunked)
  File "C:\Users\46121\AppData\Local\Programs\Python\Python38\lib\http\client.py", line 1286, in _send_request
    self.endheaders(body, encode_chunked=encode_chunked)
  File "C:\Users\46121\AppData\Local\Programs\Python\Python38\lib\http\client.py", line 1235, in endheaders
    self._send_output(message_body, encode_chunked=encode_chunked)
  File "C:\Users\46121\AppData\Local\Programs\Python\Python38\lib\http\client.py", line 1006, in _send_output
    self.send(msg)
  File "C:\Users\46121\AppData\Local\Programs\Python\Python38\lib\http\client.py", line 946, in send
    self.connect()
  File "C:\Users\46121\PycharmProjects\CS65_3\vr_env\lib\site-packages\urllib3\connection.py", line 205, in connect
    conn = self._new_conn()
  File "C:\Users\46121\PycharmProjects\CS65_3\vr_env\lib\site-packages\urllib3\connection.py", line 186, in _new_conn
    raise NewConnectionError(
urllib3.exceptions.NewConnectionError: <urllib3.connection.HTTPConnection object at 0x000001EC579AEC70>: Failed to establish a new connection: [WinError 10061] No connection could be made because the target machine actively refused it

During handling of the above exception, another exception occurred:

Traceback (most recent call last):
  File "C:\Users\46121\PycharmProjects\CS65_3\vr_env\lib\site-packages\requests\adapters.py", line 440, in send
    resp = conn.urlopen(
  File "C:\Users\46121\PycharmProjects\CS65_3\vr_env\lib\site-packages\urllib3\connectionpool.py", line 785, in urlopen
    retries = retries.increment(
  File "C:\Users\46121\PycharmProjects\CS65_3\vr_env\lib\site-packages\urllib3\util\retry.py", line 592, in increment
    raise MaxRetryError(_pool, url, error or ResponseError(cause))
urllib3.exceptions.MaxRetryError: HTTPConnectionPool(host='127.0.0.1', port=6800): Max retries exceeded with url: / (Caused by NewConnectionError('<urllib3.connection.HTTPConnection object at 0x000001EC579AEC70>: Failed to establish a new connection: [WinError 10061] No connection could be made because the target machine actively refused it'))

During handling of the above exception, another exception occurred:

Traceback (most recent call last):
  File "C:\Users\46121\PycharmProjects\CS65_3\cs65_4\cs65_5\polls\utils.py", line 74, in wrapper
    result = func(*args, **kwargs)
  File "C:\Users\46121\PycharmProjects\CS65_3\vr_env\lib\site-packages\django\views\decorators\csrf.py", line 54, in wrapped_view
    return view_func(*args, **kwargs)
  File "C:\Users\46121\PycharmProjects\CS65_3\vr_env\lib\site-packages\django\views\generic\base.py", line 69, in view
    return self.dispatch(request, *args, **kwargs)
  File "C:\Users\46121\PycharmProjects\CS65_3\vr_env\lib\site-packages\rest_framework\views.py", line 509, in dispatch
    response = self.handle_exception(exc)
  File "C:\Users\46121\PycharmProjects\CS65_3\vr_env\lib\site-packages\rest_framework\views.py", line 469, in handle_exception
    self.raise_uncaught_exception(exc)
  File "C:\Users\46121\PycharmProjects\CS65_3\vr_env\lib\site-packages\rest_framework\views.py", line 480, in raise_uncaught_exception
    raise exc
  File "C:\Users\46121\PycharmProjects\CS65_3\vr_env\lib\site-packages\rest_framework\views.py", line 506, in dispatch
    response = handler(request, *args, **kwargs)
  File "C:\Users\46121\PycharmProjects\CS65_3\vr_env\lib\site-packages\rest_framework\decorators.py", line 50, in handler
    return func(*args, **kwargs)
  File "C:\Users\46121\PycharmProjects\CS65_3\cs65_4\cs65_5\polls\views.py", line 168, in client_status
    requests.get(scrapyd_url(client.ip, client.port), timeout=3)
  File "C:\Users\46121\PycharmProjects\CS65_3\vr_env\lib\site-packages\requests\api.py", line 75, in get
    return request('get', url, params=params, **kwargs)
  File "C:\Users\46121\PycharmProjects\CS65_3\vr_env\lib\site-packages\requests\api.py", line 61, in request
    return session.request(method=method, url=url, **kwargs)
  File "C:\Users\46121\PycharmProjects\CS65_3\vr_env\lib\site-packages\requests\sessions.py", line 529, in request
    resp = self.send(prep, **send_kwargs)
  File "C:\Users\46121\PycharmProjects\CS65_3\vr_env\lib\site-packages\requests\sessions.py", line 645, in send
    r = adapter.send(request, **kwargs)
  File "C:\Users\46121\PycharmProjects\CS65_3\vr_env\lib\site-packages\requests\adapters.py", line 519, in send
    raise ConnectionError(e, request=request)
requests.exceptions.ConnectionError: HTTPConnectionPool(host='127.0.0.1', port=6800): Max retries exceeded with url: / (Caused by NewConnectionError('<urllib3.connection.HTTPConnection object at 0x000001EC579AEC70>: Failed to establish a new connection: [WinError 10061] No connection could be made because the target machine actively refused it'))
ERROR - 2022-05-17 21:13:29,901 - process: 41476 - utils.py - polls.utils - 76 - utils - HTTPConnectionPool(host='127.0.0.1', port=6800): Max retries exceeded with url: / (Caused by NewConnectionError('<urllib3.connection.HTTPConnection object at 0x000001EC57ABF850>: Failed to establish a new connection: [WinError 10061] No connection could be made because the target machine actively refused it'))
Traceback (most recent call last):
  File "C:\Users\46121\PycharmProjects\CS65_3\vr_env\lib\site-packages\urllib3\connection.py", line 174, in _new_conn
    conn = connection.create_connection(
  File "C:\Users\46121\PycharmProjects\CS65_3\vr_env\lib\site-packages\urllib3\util\connection.py", line 95, in create_connection
    raise err
  File "C:\Users\46121\PycharmProjects\CS65_3\vr_env\lib\site-packages\urllib3\util\connection.py", line 85, in create_connection
    sock.connect(sa)
ConnectionRefusedError: [WinError 10061] No connection could be made because the target machine actively refused it

During handling of the above exception, another exception occurred:

Traceback (most recent call last):
  File "C:\Users\46121\PycharmProjects\CS65_3\vr_env\lib\site-packages\urllib3\connectionpool.py", line 703, in urlopen
    httplib_response = self._make_request(
  File "C:\Users\46121\PycharmProjects\CS65_3\vr_env\lib\site-packages\urllib3\connectionpool.py", line 398, in _make_request
    conn.request(method, url, **httplib_request_kw)
  File "C:\Users\46121\PycharmProjects\CS65_3\vr_env\lib\site-packages\urllib3\connection.py", line 239, in request
    super(HTTPConnection, self).request(method, url, body=body, headers=headers)
  File "C:\Users\46121\AppData\Local\Programs\Python\Python38\lib\http\client.py", line 1240, in request
    self._send_request(method, url, body, headers, encode_chunked)
  File "C:\Users\46121\AppData\Local\Programs\Python\Python38\lib\http\client.py", line 1286, in _send_request
    self.endheaders(body, encode_chunked=encode_chunked)
  File "C:\Users\46121\AppData\Local\Programs\Python\Python38\lib\http\client.py", line 1235, in endheaders
    self._send_output(message_body, encode_chunked=encode_chunked)
  File "C:\Users\46121\AppData\Local\Programs\Python\Python38\lib\http\client.py", line 1006, in _send_output
    self.send(msg)
  File "C:\Users\46121\AppData\Local\Programs\Python\Python38\lib\http\client.py", line 946, in send
    self.connect()
  File "C:\Users\46121\PycharmProjects\CS65_3\vr_env\lib\site-packages\urllib3\connection.py", line 205, in connect
    conn = self._new_conn()
  File "C:\Users\46121\PycharmProjects\CS65_3\vr_env\lib\site-packages\urllib3\connection.py", line 186, in _new_conn
    raise NewConnectionError(
urllib3.exceptions.NewConnectionError: <urllib3.connection.HTTPConnection object at 0x000001EC57ABF850>: Failed to establish a new connection: [WinError 10061] No connection could be made because the target machine actively refused it

During handling of the above exception, another exception occurred:

Traceback (most recent call last):
  File "C:\Users\46121\PycharmProjects\CS65_3\vr_env\lib\site-packages\requests\adapters.py", line 440, in send
    resp = conn.urlopen(
  File "C:\Users\46121\PycharmProjects\CS65_3\vr_env\lib\site-packages\urllib3\connectionpool.py", line 785, in urlopen
    retries = retries.increment(
  File "C:\Users\46121\PycharmProjects\CS65_3\vr_env\lib\site-packages\urllib3\util\retry.py", line 592, in increment
    raise MaxRetryError(_pool, url, error or ResponseError(cause))
urllib3.exceptions.MaxRetryError: HTTPConnectionPool(host='127.0.0.1', port=6800): Max retries exceeded with url: / (Caused by NewConnectionError('<urllib3.connection.HTTPConnection object at 0x000001EC57ABF850>: Failed to establish a new connection: [WinError 10061] No connection could be made because the target machine actively refused it'))

During handling of the above exception, another exception occurred:

Traceback (most recent call last):
  File "C:\Users\46121\PycharmProjects\CS65_3\cs65_4\cs65_5\polls\utils.py", line 74, in wrapper
    result = func(*args, **kwargs)
  File "C:\Users\46121\PycharmProjects\CS65_3\vr_env\lib\site-packages\django\views\decorators\csrf.py", line 54, in wrapped_view
    return view_func(*args, **kwargs)
  File "C:\Users\46121\PycharmProjects\CS65_3\vr_env\lib\site-packages\django\views\generic\base.py", line 69, in view
    return self.dispatch(request, *args, **kwargs)
  File "C:\Users\46121\PycharmProjects\CS65_3\vr_env\lib\site-packages\rest_framework\views.py", line 509, in dispatch
    response = self.handle_exception(exc)
  File "C:\Users\46121\PycharmProjects\CS65_3\vr_env\lib\site-packages\rest_framework\views.py", line 469, in handle_exception
    self.raise_uncaught_exception(exc)
  File "C:\Users\46121\PycharmProjects\CS65_3\vr_env\lib\site-packages\rest_framework\views.py", line 480, in raise_uncaught_exception
    raise exc
  File "C:\Users\46121\PycharmProjects\CS65_3\vr_env\lib\site-packages\rest_framework\views.py", line 506, in dispatch
    response = handler(request, *args, **kwargs)
  File "C:\Users\46121\PycharmProjects\CS65_3\vr_env\lib\site-packages\rest_framework\decorators.py", line 50, in handler
    return func(*args, **kwargs)
  File "C:\Users\46121\PycharmProjects\CS65_3\cs65_4\cs65_5\polls\views.py", line 168, in client_status
    requests.get(scrapyd_url(client.ip, client.port), timeout=3)
  File "C:\Users\46121\PycharmProjects\CS65_3\vr_env\lib\site-packages\requests\api.py", line 75, in get
    return request('get', url, params=params, **kwargs)
  File "C:\Users\46121\PycharmProjects\CS65_3\vr_env\lib\site-packages\requests\api.py", line 61, in request
    return session.request(method=method, url=url, **kwargs)
  File "C:\Users\46121\PycharmProjects\CS65_3\vr_env\lib\site-packages\requests\sessions.py", line 529, in request
    resp = self.send(prep, **send_kwargs)
  File "C:\Users\46121\PycharmProjects\CS65_3\vr_env\lib\site-packages\requests\sessions.py", line 645, in send
    r = adapter.send(request, **kwargs)
  File "C:\Users\46121\PycharmProjects\CS65_3\vr_env\lib\site-packages\requests\adapters.py", line 519, in send
    raise ConnectionError(e, request=request)
requests.exceptions.ConnectionError: HTTPConnectionPool(host='127.0.0.1', port=6800): Max retries exceeded with url: / (Caused by NewConnectionError('<urllib3.connection.HTTPConnection object at 0x000001EC57ABF850>: Failed to establish a new connection: [WinError 10061] No connection could be made because the target machine actively refused it'))
ERROR - 2022-05-18 00:39:44,244 - process: 41476 - utils.py - polls.utils - 76 - utils - Request body exceeded settings.DATA_UPLOAD_MAX_MEMORY_SIZE.
Traceback (most recent call last):
  File "C:\Users\46121\PycharmProjects\CS65_3\cs65_4\cs65_5\polls\utils.py", line 74, in wrapper
    result = func(*args, **kwargs)
  File "C:\Users\46121\PycharmProjects\CS65_3\vr_env\lib\site-packages\django\views\decorators\csrf.py", line 54, in wrapped_view
    return view_func(*args, **kwargs)
  File "C:\Users\46121\PycharmProjects\CS65_3\vr_env\lib\site-packages\django\views\generic\base.py", line 69, in view
    return self.dispatch(request, *args, **kwargs)
  File "C:\Users\46121\PycharmProjects\CS65_3\vr_env\lib\site-packages\rest_framework\views.py", line 509, in dispatch
    response = self.handle_exception(exc)
  File "C:\Users\46121\PycharmProjects\CS65_3\vr_env\lib\site-packages\rest_framework\views.py", line 469, in handle_exception
    self.raise_uncaught_exception(exc)
  File "C:\Users\46121\PycharmProjects\CS65_3\vr_env\lib\site-packages\rest_framework\views.py", line 480, in raise_uncaught_exception
    raise exc
  File "C:\Users\46121\PycharmProjects\CS65_3\vr_env\lib\site-packages\rest_framework\views.py", line 506, in dispatch
    response = handler(request, *args, **kwargs)
  File "C:\Users\46121\PycharmProjects\CS65_3\vr_env\lib\site-packages\rest_framework\decorators.py", line 50, in handler
    return func(*args, **kwargs)
  File "C:\Users\46121\PycharmProjects\CS65_3\cs65_4\cs65_5\polls\views.py", line 749, in project_file_update
    data = json.loads(request.body)
  File "C:\Users\46121\PycharmProjects\CS65_3\vr_env\lib\site-packages\rest_framework\request.py", line 416, in __getattr__
    return getattr(self._request, attr)
  File "C:\Users\46121\PycharmProjects\CS65_3\vr_env\lib\site-packages\django\http\request.py", line 299, in body
    raise RequestDataTooBig('Request body exceeded settings.DATA_UPLOAD_MAX_MEMORY_SIZE.')
django.core.exceptions.RequestDataTooBig: Request body exceeded settings.DATA_UPLOAD_MAX_MEMORY_SIZE.
ERROR - 2022-05-18 00:39:58,064 - process: 41476 - utils.py - polls.utils - 76 - utils - Request body exceeded settings.DATA_UPLOAD_MAX_MEMORY_SIZE.
Traceback (most recent call last):
  File "C:\Users\46121\PycharmProjects\CS65_3\cs65_4\cs65_5\polls\utils.py", line 74, in wrapper
    result = func(*args, **kwargs)
  File "C:\Users\46121\PycharmProjects\CS65_3\vr_env\lib\site-packages\django\views\decorators\csrf.py", line 54, in wrapped_view
    return view_func(*args, **kwargs)
  File "C:\Users\46121\PycharmProjects\CS65_3\vr_env\lib\site-packages\django\views\generic\base.py", line 69, in view
    return self.dispatch(request, *args, **kwargs)
  File "C:\Users\46121\PycharmProjects\CS65_3\vr_env\lib\site-packages\rest_framework\views.py", line 509, in dispatch
    response = self.handle_exception(exc)
  File "C:\Users\46121\PycharmProjects\CS65_3\vr_env\lib\site-packages\rest_framework\views.py", line 469, in handle_exception
    self.raise_uncaught_exception(exc)
  File "C:\Users\46121\PycharmProjects\CS65_3\vr_env\lib\site-packages\rest_framework\views.py", line 480, in raise_uncaught_exception
    raise exc
  File "C:\Users\46121\PycharmProjects\CS65_3\vr_env\lib\site-packages\rest_framework\views.py", line 506, in dispatch
    response = handler(request, *args, **kwargs)
  File "C:\Users\46121\PycharmProjects\CS65_3\vr_env\lib\site-packages\rest_framework\decorators.py", line 50, in handler
    return func(*args, **kwargs)
  File "C:\Users\46121\PycharmProjects\CS65_3\cs65_4\cs65_5\polls\views.py", line 749, in project_file_update
    data = json.loads(request.body)
  File "C:\Users\46121\PycharmProjects\CS65_3\vr_env\lib\site-packages\rest_framework\request.py", line 416, in __getattr__
    return getattr(self._request, attr)
  File "C:\Users\46121\PycharmProjects\CS65_3\vr_env\lib\site-packages\django\http\request.py", line 299, in body
    raise RequestDataTooBig('Request body exceeded settings.DATA_UPLOAD_MAX_MEMORY_SIZE.')
django.core.exceptions.RequestDataTooBig: Request body exceeded settings.DATA_UPLOAD_MAX_MEMORY_SIZE.
ERROR - 2022-05-18 00:40:02,384 - process: 41476 - utils.py - polls.utils - 76 - utils - Request body exceeded settings.DATA_UPLOAD_MAX_MEMORY_SIZE.
Traceback (most recent call last):
  File "C:\Users\46121\PycharmProjects\CS65_3\cs65_4\cs65_5\polls\utils.py", line 74, in wrapper
    result = func(*args, **kwargs)
  File "C:\Users\46121\PycharmProjects\CS65_3\vr_env\lib\site-packages\django\views\decorators\csrf.py", line 54, in wrapped_view
    return view_func(*args, **kwargs)
  File "C:\Users\46121\PycharmProjects\CS65_3\vr_env\lib\site-packages\django\views\generic\base.py", line 69, in view
    return self.dispatch(request, *args, **kwargs)
  File "C:\Users\46121\PycharmProjects\CS65_3\vr_env\lib\site-packages\rest_framework\views.py", line 509, in dispatch
    response = self.handle_exception(exc)
  File "C:\Users\46121\PycharmProjects\CS65_3\vr_env\lib\site-packages\rest_framework\views.py", line 469, in handle_exception
    self.raise_uncaught_exception(exc)
  File "C:\Users\46121\PycharmProjects\CS65_3\vr_env\lib\site-packages\rest_framework\views.py", line 480, in raise_uncaught_exception
    raise exc
  File "C:\Users\46121\PycharmProjects\CS65_3\vr_env\lib\site-packages\rest_framework\views.py", line 506, in dispatch
    response = handler(request, *args, **kwargs)
  File "C:\Users\46121\PycharmProjects\CS65_3\vr_env\lib\site-packages\rest_framework\decorators.py", line 50, in handler
    return func(*args, **kwargs)
  File "C:\Users\46121\PycharmProjects\CS65_3\cs65_4\cs65_5\polls\views.py", line 749, in project_file_update
    data = json.loads(request.body)
  File "C:\Users\46121\PycharmProjects\CS65_3\vr_env\lib\site-packages\rest_framework\request.py", line 416, in __getattr__
    return getattr(self._request, attr)
  File "C:\Users\46121\PycharmProjects\CS65_3\vr_env\lib\site-packages\django\http\request.py", line 299, in body
    raise RequestDataTooBig('Request body exceeded settings.DATA_UPLOAD_MAX_MEMORY_SIZE.')
django.core.exceptions.RequestDataTooBig: Request body exceeded settings.DATA_UPLOAD_MAX_MEMORY_SIZE.
ERROR - 2022-05-18 00:40:04,423 - process: 41476 - utils.py - polls.utils - 76 - utils - Request body exceeded settings.DATA_UPLOAD_MAX_MEMORY_SIZE.
Traceback (most recent call last):
  File "C:\Users\46121\PycharmProjects\CS65_3\cs65_4\cs65_5\polls\utils.py", line 74, in wrapper
    result = func(*args, **kwargs)
  File "C:\Users\46121\PycharmProjects\CS65_3\vr_env\lib\site-packages\django\views\decorators\csrf.py", line 54, in wrapped_view
    return view_func(*args, **kwargs)
  File "C:\Users\46121\PycharmProjects\CS65_3\vr_env\lib\site-packages\django\views\generic\base.py", line 69, in view
    return self.dispatch(request, *args, **kwargs)
  File "C:\Users\46121\PycharmProjects\CS65_3\vr_env\lib\site-packages\rest_framework\views.py", line 509, in dispatch
    response = self.handle_exception(exc)
  File "C:\Users\46121\PycharmProjects\CS65_3\vr_env\lib\site-packages\rest_framework\views.py", line 469, in handle_exception
    self.raise_uncaught_exception(exc)
  File "C:\Users\46121\PycharmProjects\CS65_3\vr_env\lib\site-packages\rest_framework\views.py", line 480, in raise_uncaught_exception
    raise exc
  File "C:\Users\46121\PycharmProjects\CS65_3\vr_env\lib\site-packages\rest_framework\views.py", line 506, in dispatch
    response = handler(request, *args, **kwargs)
  File "C:\Users\46121\PycharmProjects\CS65_3\vr_env\lib\site-packages\rest_framework\decorators.py", line 50, in handler
    return func(*args, **kwargs)
  File "C:\Users\46121\PycharmProjects\CS65_3\cs65_4\cs65_5\polls\views.py", line 749, in project_file_update
    data = json.loads(request.body)
  File "C:\Users\46121\PycharmProjects\CS65_3\vr_env\lib\site-packages\rest_framework\request.py", line 416, in __getattr__
    return getattr(self._request, attr)
  File "C:\Users\46121\PycharmProjects\CS65_3\vr_env\lib\site-packages\django\http\request.py", line 299, in body
    raise RequestDataTooBig('Request body exceeded settings.DATA_UPLOAD_MAX_MEMORY_SIZE.')
django.core.exceptions.RequestDataTooBig: Request body exceeded settings.DATA_UPLOAD_MAX_MEMORY_SIZE.
ERROR - 2022-05-18 01:03:08,462 - process: 41476 - utils.py - polls.utils - 76 - utils - [WinError 3] The system cannot find the path specified: 'C:\\Users\\46121\\PycharmProjects\\CS65_3\\cs65_4\\cs65_5\\projects\\undefined'
Traceback (most recent call last):
  File "C:\Users\46121\PycharmProjects\CS65_3\cs65_4\cs65_5\polls\utils.py", line 74, in wrapper
    result = func(*args, **kwargs)
  File "C:\Users\46121\PycharmProjects\CS65_3\vr_env\lib\site-packages\django\views\decorators\csrf.py", line 54, in wrapped_view
    return view_func(*args, **kwargs)
  File "C:\Users\46121\PycharmProjects\CS65_3\vr_env\lib\site-packages\django\views\generic\base.py", line 69, in view
    return self.dispatch(request, *args, **kwargs)
  File "C:\Users\46121\PycharmProjects\CS65_3\vr_env\lib\site-packages\rest_framework\views.py", line 509, in dispatch
    response = self.handle_exception(exc)
  File "C:\Users\46121\PycharmProjects\CS65_3\vr_env\lib\site-packages\rest_framework\views.py", line 469, in handle_exception
    self.raise_uncaught_exception(exc)
  File "C:\Users\46121\PycharmProjects\CS65_3\vr_env\lib\site-packages\rest_framework\views.py", line 480, in raise_uncaught_exception
    raise exc
  File "C:\Users\46121\PycharmProjects\CS65_3\vr_env\lib\site-packages\rest_framework\views.py", line 506, in dispatch
    response = handler(request, *args, **kwargs)
  File "C:\Users\46121\PycharmProjects\CS65_3\vr_env\lib\site-packages\rest_framework\decorators.py", line 50, in handler
    return func(*args, **kwargs)
  File "C:\Users\46121\PycharmProjects\CS65_3\cs65_4\cs65_5\polls\views.py", line 414, in project_tree
    tree = get_tree(join(path, project_name))
  File "C:\Users\46121\PycharmProjects\CS65_3\cs65_4\cs65_5\polls\utils.py", line 101, in get_tree
    for file in os.listdir(path):
FileNotFoundError: [WinError 3] The system cannot find the path specified: 'C:\\Users\\46121\\PycharmProjects\\CS65_3\\cs65_4\\cs65_5\\projects\\undefined'
ERROR - 2022-05-18 01:03:10,593 - process: 41476 - utils.py - polls.utils - 76 - utils - [WinError 3] The system cannot find the path specified: 'C:\\Users\\46121\\PycharmProjects\\CS65_3\\cs65_4\\cs65_5\\projects\\undefined'
Traceback (most recent call last):
  File "C:\Users\46121\PycharmProjects\CS65_3\cs65_4\cs65_5\polls\utils.py", line 74, in wrapper
    result = func(*args, **kwargs)
  File "C:\Users\46121\PycharmProjects\CS65_3\vr_env\lib\site-packages\django\views\decorators\csrf.py", line 54, in wrapped_view
    return view_func(*args, **kwargs)
  File "C:\Users\46121\PycharmProjects\CS65_3\vr_env\lib\site-packages\django\views\generic\base.py", line 69, in view
    return self.dispatch(request, *args, **kwargs)
  File "C:\Users\46121\PycharmProjects\CS65_3\vr_env\lib\site-packages\rest_framework\views.py", line 509, in dispatch
    response = self.handle_exception(exc)
  File "C:\Users\46121\PycharmProjects\CS65_3\vr_env\lib\site-packages\rest_framework\views.py", line 469, in handle_exception
    self.raise_uncaught_exception(exc)
  File "C:\Users\46121\PycharmProjects\CS65_3\vr_env\lib\site-packages\rest_framework\views.py", line 480, in raise_uncaught_exception
    raise exc
  File "C:\Users\46121\PycharmProjects\CS65_3\vr_env\lib\site-packages\rest_framework\views.py", line 506, in dispatch
    response = handler(request, *args, **kwargs)
  File "C:\Users\46121\PycharmProjects\CS65_3\vr_env\lib\site-packages\rest_framework\decorators.py", line 50, in handler
    return func(*args, **kwargs)
  File "C:\Users\46121\PycharmProjects\CS65_3\cs65_4\cs65_5\polls\views.py", line 414, in project_tree
    tree = get_tree(join(path, project_name))
  File "C:\Users\46121\PycharmProjects\CS65_3\cs65_4\cs65_5\polls\utils.py", line 101, in get_tree
    for file in os.listdir(path):
FileNotFoundError: [WinError 3] The system cannot find the path specified: 'C:\\Users\\46121\\PycharmProjects\\CS65_3\\cs65_4\\cs65_5\\projects\\undefined'
ERROR - 2022-05-18 01:03:11,683 - process: 41476 - utils.py - polls.utils - 76 - utils - [WinError 3] The system cannot find the path specified: 'C:\\Users\\46121\\PycharmProjects\\CS65_3\\cs65_4\\cs65_5\\projects\\undefined'
Traceback (most recent call last):
  File "C:\Users\46121\PycharmProjects\CS65_3\cs65_4\cs65_5\polls\utils.py", line 74, in wrapper
    result = func(*args, **kwargs)
  File "C:\Users\46121\PycharmProjects\CS65_3\vr_env\lib\site-packages\django\views\decorators\csrf.py", line 54, in wrapped_view
    return view_func(*args, **kwargs)
  File "C:\Users\46121\PycharmProjects\CS65_3\vr_env\lib\site-packages\django\views\generic\base.py", line 69, in view
    return self.dispatch(request, *args, **kwargs)
  File "C:\Users\46121\PycharmProjects\CS65_3\vr_env\lib\site-packages\rest_framework\views.py", line 509, in dispatch
    response = self.handle_exception(exc)
  File "C:\Users\46121\PycharmProjects\CS65_3\vr_env\lib\site-packages\rest_framework\views.py", line 469, in handle_exception
    self.raise_uncaught_exception(exc)
  File "C:\Users\46121\PycharmProjects\CS65_3\vr_env\lib\site-packages\rest_framework\views.py", line 480, in raise_uncaught_exception
    raise exc
  File "C:\Users\46121\PycharmProjects\CS65_3\vr_env\lib\site-packages\rest_framework\views.py", line 506, in dispatch
    response = handler(request, *args, **kwargs)
  File "C:\Users\46121\PycharmProjects\CS65_3\vr_env\lib\site-packages\rest_framework\decorators.py", line 50, in handler
    return func(*args, **kwargs)
  File "C:\Users\46121\PycharmProjects\CS65_3\cs65_4\cs65_5\polls\views.py", line 414, in project_tree
    tree = get_tree(join(path, project_name))
  File "C:\Users\46121\PycharmProjects\CS65_3\cs65_4\cs65_5\polls\utils.py", line 101, in get_tree
    for file in os.listdir(path):
FileNotFoundError: [WinError 3] The system cannot find the path specified: 'C:\\Users\\46121\\PycharmProjects\\CS65_3\\cs65_4\\cs65_5\\projects\\undefined'
ERROR - 2022-05-18 01:03:14,853 - process: 41476 - utils.py - polls.utils - 76 - utils - [WinError 3] The system cannot find the path specified: 'C:\\Users\\46121\\PycharmProjects\\CS65_3\\cs65_4\\cs65_5\\projects\\undefined'
Traceback (most recent call last):
  File "C:\Users\46121\PycharmProjects\CS65_3\cs65_4\cs65_5\polls\utils.py", line 74, in wrapper
    result = func(*args, **kwargs)
  File "C:\Users\46121\PycharmProjects\CS65_3\vr_env\lib\site-packages\django\views\decorators\csrf.py", line 54, in wrapped_view
    return view_func(*args, **kwargs)
  File "C:\Users\46121\PycharmProjects\CS65_3\vr_env\lib\site-packages\django\views\generic\base.py", line 69, in view
    return self.dispatch(request, *args, **kwargs)
  File "C:\Users\46121\PycharmProjects\CS65_3\vr_env\lib\site-packages\rest_framework\views.py", line 509, in dispatch
    response = self.handle_exception(exc)
  File "C:\Users\46121\PycharmProjects\CS65_3\vr_env\lib\site-packages\rest_framework\views.py", line 469, in handle_exception
    self.raise_uncaught_exception(exc)
  File "C:\Users\46121\PycharmProjects\CS65_3\vr_env\lib\site-packages\rest_framework\views.py", line 480, in raise_uncaught_exception
    raise exc
  File "C:\Users\46121\PycharmProjects\CS65_3\vr_env\lib\site-packages\rest_framework\views.py", line 506, in dispatch
    response = handler(request, *args, **kwargs)
  File "C:\Users\46121\PycharmProjects\CS65_3\vr_env\lib\site-packages\rest_framework\decorators.py", line 50, in handler
    return func(*args, **kwargs)
  File "C:\Users\46121\PycharmProjects\CS65_3\cs65_4\cs65_5\polls\views.py", line 414, in project_tree
    tree = get_tree(join(path, project_name))
  File "C:\Users\46121\PycharmProjects\CS65_3\cs65_4\cs65_5\polls\utils.py", line 101, in get_tree
    for file in os.listdir(path):
FileNotFoundError: [WinError 3] The system cannot find the path specified: 'C:\\Users\\46121\\PycharmProjects\\CS65_3\\cs65_4\\cs65_5\\projects\\undefined'
ERROR - 2022-05-18 01:03:15,523 - process: 41476 - utils.py - polls.utils - 76 - utils - HTTPConnectionPool(host='127.0.0.1', port=6800): Max retries exceeded with url: / (Caused by NewConnectionError('<urllib3.connection.HTTPConnection object at 0x000001EC577E81C0>: Failed to establish a new connection: [WinError 10061] No connection could be made because the target machine actively refused it'))
Traceback (most recent call last):
  File "C:\Users\46121\PycharmProjects\CS65_3\vr_env\lib\site-packages\urllib3\connection.py", line 174, in _new_conn
    conn = connection.create_connection(
  File "C:\Users\46121\PycharmProjects\CS65_3\vr_env\lib\site-packages\urllib3\util\connection.py", line 95, in create_connection
    raise err
  File "C:\Users\46121\PycharmProjects\CS65_3\vr_env\lib\site-packages\urllib3\util\connection.py", line 85, in create_connection
    sock.connect(sa)
ConnectionRefusedError: [WinError 10061] No connection could be made because the target machine actively refused it

During handling of the above exception, another exception occurred:

Traceback (most recent call last):
  File "C:\Users\46121\PycharmProjects\CS65_3\vr_env\lib\site-packages\urllib3\connectionpool.py", line 703, in urlopen
    httplib_response = self._make_request(
  File "C:\Users\46121\PycharmProjects\CS65_3\vr_env\lib\site-packages\urllib3\connectionpool.py", line 398, in _make_request
    conn.request(method, url, **httplib_request_kw)
  File "C:\Users\46121\PycharmProjects\CS65_3\vr_env\lib\site-packages\urllib3\connection.py", line 239, in request
    super(HTTPConnection, self).request(method, url, body=body, headers=headers)
  File "C:\Users\46121\AppData\Local\Programs\Python\Python38\lib\http\client.py", line 1240, in request
    self._send_request(method, url, body, headers, encode_chunked)
  File "C:\Users\46121\AppData\Local\Programs\Python\Python38\lib\http\client.py", line 1286, in _send_request
    self.endheaders(body, encode_chunked=encode_chunked)
  File "C:\Users\46121\AppData\Local\Programs\Python\Python38\lib\http\client.py", line 1235, in endheaders
    self._send_output(message_body, encode_chunked=encode_chunked)
  File "C:\Users\46121\AppData\Local\Programs\Python\Python38\lib\http\client.py", line 1006, in _send_output
    self.send(msg)
  File "C:\Users\46121\AppData\Local\Programs\Python\Python38\lib\http\client.py", line 946, in send
    self.connect()
  File "C:\Users\46121\PycharmProjects\CS65_3\vr_env\lib\site-packages\urllib3\connection.py", line 205, in connect
    conn = self._new_conn()
  File "C:\Users\46121\PycharmProjects\CS65_3\vr_env\lib\site-packages\urllib3\connection.py", line 186, in _new_conn
    raise NewConnectionError(
urllib3.exceptions.NewConnectionError: <urllib3.connection.HTTPConnection object at 0x000001EC577E81C0>: Failed to establish a new connection: [WinError 10061] No connection could be made because the target machine actively refused it

During handling of the above exception, another exception occurred:

Traceback (most recent call last):
  File "C:\Users\46121\PycharmProjects\CS65_3\vr_env\lib\site-packages\requests\adapters.py", line 440, in send
    resp = conn.urlopen(
  File "C:\Users\46121\PycharmProjects\CS65_3\vr_env\lib\site-packages\urllib3\connectionpool.py", line 785, in urlopen
    retries = retries.increment(
  File "C:\Users\46121\PycharmProjects\CS65_3\vr_env\lib\site-packages\urllib3\util\retry.py", line 592, in increment
    raise MaxRetryError(_pool, url, error or ResponseError(cause))
urllib3.exceptions.MaxRetryError: HTTPConnectionPool(host='127.0.0.1', port=6800): Max retries exceeded with url: / (Caused by NewConnectionError('<urllib3.connection.HTTPConnection object at 0x000001EC577E81C0>: Failed to establish a new connection: [WinError 10061] No connection could be made because the target machine actively refused it'))

During handling of the above exception, another exception occurred:

Traceback (most recent call last):
  File "C:\Users\46121\PycharmProjects\CS65_3\cs65_4\cs65_5\polls\utils.py", line 74, in wrapper
    result = func(*args, **kwargs)
  File "C:\Users\46121\PycharmProjects\CS65_3\vr_env\lib\site-packages\django\views\decorators\csrf.py", line 54, in wrapped_view
    return view_func(*args, **kwargs)
  File "C:\Users\46121\PycharmProjects\CS65_3\vr_env\lib\site-packages\django\views\generic\base.py", line 69, in view
    return self.dispatch(request, *args, **kwargs)
  File "C:\Users\46121\PycharmProjects\CS65_3\vr_env\lib\site-packages\rest_framework\views.py", line 509, in dispatch
    response = self.handle_exception(exc)
  File "C:\Users\46121\PycharmProjects\CS65_3\vr_env\lib\site-packages\rest_framework\views.py", line 469, in handle_exception
    self.raise_uncaught_exception(exc)
  File "C:\Users\46121\PycharmProjects\CS65_3\vr_env\lib\site-packages\rest_framework\views.py", line 480, in raise_uncaught_exception
    raise exc
  File "C:\Users\46121\PycharmProjects\CS65_3\vr_env\lib\site-packages\rest_framework\views.py", line 506, in dispatch
    response = handler(request, *args, **kwargs)
  File "C:\Users\46121\PycharmProjects\CS65_3\vr_env\lib\site-packages\rest_framework\decorators.py", line 50, in handler
    return func(*args, **kwargs)
  File "C:\Users\46121\PycharmProjects\CS65_3\cs65_4\cs65_5\polls\views.py", line 168, in client_status
    requests.get(scrapyd_url(client.ip, client.port), timeout=3)
  File "C:\Users\46121\PycharmProjects\CS65_3\vr_env\lib\site-packages\requests\api.py", line 75, in get
    return request('get', url, params=params, **kwargs)
  File "C:\Users\46121\PycharmProjects\CS65_3\vr_env\lib\site-packages\requests\api.py", line 61, in request
    return session.request(method=method, url=url, **kwargs)
  File "C:\Users\46121\PycharmProjects\CS65_3\vr_env\lib\site-packages\requests\sessions.py", line 529, in request
    resp = self.send(prep, **send_kwargs)
  File "C:\Users\46121\PycharmProjects\CS65_3\vr_env\lib\site-packages\requests\sessions.py", line 645, in send
    r = adapter.send(request, **kwargs)
  File "C:\Users\46121\PycharmProjects\CS65_3\vr_env\lib\site-packages\requests\adapters.py", line 519, in send
    raise ConnectionError(e, request=request)
requests.exceptions.ConnectionError: HTTPConnectionPool(host='127.0.0.1', port=6800): Max retries exceeded with url: / (Caused by NewConnectionError('<urllib3.connection.HTTPConnection object at 0x000001EC577E81C0>: Failed to establish a new connection: [WinError 10061] No connection could be made because the target machine actively refused it'))
ERROR - 2022-05-18 01:03:15,735 - process: 41476 - utils.py - polls.utils - 76 - utils - [WinError 3] The system cannot find the path specified: 'C:\\Users\\46121\\PycharmProjects\\CS65_3\\cs65_4\\cs65_5\\projects\\undefined'
Traceback (most recent call last):
  File "C:\Users\46121\PycharmProjects\CS65_3\cs65_4\cs65_5\polls\utils.py", line 74, in wrapper
    result = func(*args, **kwargs)
  File "C:\Users\46121\PycharmProjects\CS65_3\vr_env\lib\site-packages\django\views\decorators\csrf.py", line 54, in wrapped_view
    return view_func(*args, **kwargs)
  File "C:\Users\46121\PycharmProjects\CS65_3\vr_env\lib\site-packages\django\views\generic\base.py", line 69, in view
    return self.dispatch(request, *args, **kwargs)
  File "C:\Users\46121\PycharmProjects\CS65_3\vr_env\lib\site-packages\rest_framework\views.py", line 509, in dispatch
    response = self.handle_exception(exc)
  File "C:\Users\46121\PycharmProjects\CS65_3\vr_env\lib\site-packages\rest_framework\views.py", line 469, in handle_exception
    self.raise_uncaught_exception(exc)
  File "C:\Users\46121\PycharmProjects\CS65_3\vr_env\lib\site-packages\rest_framework\views.py", line 480, in raise_uncaught_exception
    raise exc
  File "C:\Users\46121\PycharmProjects\CS65_3\vr_env\lib\site-packages\rest_framework\views.py", line 506, in dispatch
    response = handler(request, *args, **kwargs)
  File "C:\Users\46121\PycharmProjects\CS65_3\vr_env\lib\site-packages\rest_framework\decorators.py", line 50, in handler
    return func(*args, **kwargs)
  File "C:\Users\46121\PycharmProjects\CS65_3\cs65_4\cs65_5\polls\views.py", line 414, in project_tree
    tree = get_tree(join(path, project_name))
  File "C:\Users\46121\PycharmProjects\CS65_3\cs65_4\cs65_5\polls\utils.py", line 101, in get_tree
    for file in os.listdir(path):
FileNotFoundError: [WinError 3] The system cannot find the path specified: 'C:\\Users\\46121\\PycharmProjects\\CS65_3\\cs65_4\\cs65_5\\projects\\undefined'
ERROR - 2022-05-18 01:03:24,461 - process: 41476 - utils.py - polls.utils - 76 - utils - [WinError 3] The system cannot find the path specified: 'C:\\Users\\46121\\PycharmProjects\\CS65_3\\cs65_4\\cs65_5\\projects\\undefined'
Traceback (most recent call last):
  File "C:\Users\46121\PycharmProjects\CS65_3\cs65_4\cs65_5\polls\utils.py", line 74, in wrapper
    result = func(*args, **kwargs)
  File "C:\Users\46121\PycharmProjects\CS65_3\vr_env\lib\site-packages\django\views\decorators\csrf.py", line 54, in wrapped_view
    return view_func(*args, **kwargs)
  File "C:\Users\46121\PycharmProjects\CS65_3\vr_env\lib\site-packages\django\views\generic\base.py", line 69, in view
    return self.dispatch(request, *args, **kwargs)
  File "C:\Users\46121\PycharmProjects\CS65_3\vr_env\lib\site-packages\rest_framework\views.py", line 509, in dispatch
    response = self.handle_exception(exc)
  File "C:\Users\46121\PycharmProjects\CS65_3\vr_env\lib\site-packages\rest_framework\views.py", line 469, in handle_exception
    self.raise_uncaught_exception(exc)
  File "C:\Users\46121\PycharmProjects\CS65_3\vr_env\lib\site-packages\rest_framework\views.py", line 480, in raise_uncaught_exception
    raise exc
  File "C:\Users\46121\PycharmProjects\CS65_3\vr_env\lib\site-packages\rest_framework\views.py", line 506, in dispatch
    response = handler(request, *args, **kwargs)
  File "C:\Users\46121\PycharmProjects\CS65_3\vr_env\lib\site-packages\rest_framework\decorators.py", line 50, in handler
    return func(*args, **kwargs)
  File "C:\Users\46121\PycharmProjects\CS65_3\cs65_4\cs65_5\polls\views.py", line 414, in project_tree
    tree = get_tree(join(path, project_name))
  File "C:\Users\46121\PycharmProjects\CS65_3\cs65_4\cs65_5\polls\utils.py", line 101, in get_tree
    for file in os.listdir(path):
FileNotFoundError: [WinError 3] The system cannot find the path specified: 'C:\\Users\\46121\\PycharmProjects\\CS65_3\\cs65_4\\cs65_5\\projects\\undefined'
ERROR - 2022-05-18 01:03:24,545 - process: 41476 - utils.py - polls.utils - 76 - utils - HTTPConnectionPool(host='127.0.0.1', port=6800): Max retries exceeded with url: / (Caused by NewConnectionError('<urllib3.connection.HTTPConnection object at 0x000001EC57A371C0>: Failed to establish a new connection: [WinError 10061] No connection could be made because the target machine actively refused it'))
Traceback (most recent call last):
  File "C:\Users\46121\PycharmProjects\CS65_3\vr_env\lib\site-packages\urllib3\connection.py", line 174, in _new_conn
    conn = connection.create_connection(
  File "C:\Users\46121\PycharmProjects\CS65_3\vr_env\lib\site-packages\urllib3\util\connection.py", line 95, in create_connection
    raise err
  File "C:\Users\46121\PycharmProjects\CS65_3\vr_env\lib\site-packages\urllib3\util\connection.py", line 85, in create_connection
    sock.connect(sa)
ConnectionRefusedError: [WinError 10061] No connection could be made because the target machine actively refused it

During handling of the above exception, another exception occurred:

Traceback (most recent call last):
  File "C:\Users\46121\PycharmProjects\CS65_3\vr_env\lib\site-packages\urllib3\connectionpool.py", line 703, in urlopen
    httplib_response = self._make_request(
  File "C:\Users\46121\PycharmProjects\CS65_3\vr_env\lib\site-packages\urllib3\connectionpool.py", line 398, in _make_request
    conn.request(method, url, **httplib_request_kw)
  File "C:\Users\46121\PycharmProjects\CS65_3\vr_env\lib\site-packages\urllib3\connection.py", line 239, in request
    super(HTTPConnection, self).request(method, url, body=body, headers=headers)
  File "C:\Users\46121\AppData\Local\Programs\Python\Python38\lib\http\client.py", line 1240, in request
    self._send_request(method, url, body, headers, encode_chunked)
  File "C:\Users\46121\AppData\Local\Programs\Python\Python38\lib\http\client.py", line 1286, in _send_request
    self.endheaders(body, encode_chunked=encode_chunked)
  File "C:\Users\46121\AppData\Local\Programs\Python\Python38\lib\http\client.py", line 1235, in endheaders
    self._send_output(message_body, encode_chunked=encode_chunked)
  File "C:\Users\46121\AppData\Local\Programs\Python\Python38\lib\http\client.py", line 1006, in _send_output
    self.send(msg)
  File "C:\Users\46121\AppData\Local\Programs\Python\Python38\lib\http\client.py", line 946, in send
    self.connect()
  File "C:\Users\46121\PycharmProjects\CS65_3\vr_env\lib\site-packages\urllib3\connection.py", line 205, in connect
    conn = self._new_conn()
  File "C:\Users\46121\PycharmProjects\CS65_3\vr_env\lib\site-packages\urllib3\connection.py", line 186, in _new_conn
    raise NewConnectionError(
urllib3.exceptions.NewConnectionError: <urllib3.connection.HTTPConnection object at 0x000001EC57A371C0>: Failed to establish a new connection: [WinError 10061] No connection could be made because the target machine actively refused it

During handling of the above exception, another exception occurred:

Traceback (most recent call last):
  File "C:\Users\46121\PycharmProjects\CS65_3\vr_env\lib\site-packages\requests\adapters.py", line 440, in send
    resp = conn.urlopen(
  File "C:\Users\46121\PycharmProjects\CS65_3\vr_env\lib\site-packages\urllib3\connectionpool.py", line 785, in urlopen
    retries = retries.increment(
  File "C:\Users\46121\PycharmProjects\CS65_3\vr_env\lib\site-packages\urllib3\util\retry.py", line 592, in increment
    raise MaxRetryError(_pool, url, error or ResponseError(cause))
urllib3.exceptions.MaxRetryError: HTTPConnectionPool(host='127.0.0.1', port=6800): Max retries exceeded with url: / (Caused by NewConnectionError('<urllib3.connection.HTTPConnection object at 0x000001EC57A371C0>: Failed to establish a new connection: [WinError 10061] No connection could be made because the target machine actively refused it'))

During handling of the above exception, another exception occurred:

Traceback (most recent call last):
  File "C:\Users\46121\PycharmProjects\CS65_3\cs65_4\cs65_5\polls\utils.py", line 74, in wrapper
    result = func(*args, **kwargs)
  File "C:\Users\46121\PycharmProjects\CS65_3\vr_env\lib\site-packages\django\views\decorators\csrf.py", line 54, in wrapped_view
    return view_func(*args, **kwargs)
  File "C:\Users\46121\PycharmProjects\CS65_3\vr_env\lib\site-packages\django\views\generic\base.py", line 69, in view
    return self.dispatch(request, *args, **kwargs)
  File "C:\Users\46121\PycharmProjects\CS65_3\vr_env\lib\site-packages\rest_framework\views.py", line 509, in dispatch
    response = self.handle_exception(exc)
  File "C:\Users\46121\PycharmProjects\CS65_3\vr_env\lib\site-packages\rest_framework\views.py", line 469, in handle_exception
    self.raise_uncaught_exception(exc)
  File "C:\Users\46121\PycharmProjects\CS65_3\vr_env\lib\site-packages\rest_framework\views.py", line 480, in raise_uncaught_exception
    raise exc
  File "C:\Users\46121\PycharmProjects\CS65_3\vr_env\lib\site-packages\rest_framework\views.py", line 506, in dispatch
    response = handler(request, *args, **kwargs)
  File "C:\Users\46121\PycharmProjects\CS65_3\vr_env\lib\site-packages\rest_framework\decorators.py", line 50, in handler
    return func(*args, **kwargs)
  File "C:\Users\46121\PycharmProjects\CS65_3\cs65_4\cs65_5\polls\views.py", line 168, in client_status
    requests.get(scrapyd_url(client.ip, client.port), timeout=3)
  File "C:\Users\46121\PycharmProjects\CS65_3\vr_env\lib\site-packages\requests\api.py", line 75, in get
    return request('get', url, params=params, **kwargs)
  File "C:\Users\46121\PycharmProjects\CS65_3\vr_env\lib\site-packages\requests\api.py", line 61, in request
    return session.request(method=method, url=url, **kwargs)
  File "C:\Users\46121\PycharmProjects\CS65_3\vr_env\lib\site-packages\requests\sessions.py", line 529, in request
    resp = self.send(prep, **send_kwargs)
  File "C:\Users\46121\PycharmProjects\CS65_3\vr_env\lib\site-packages\requests\sessions.py", line 645, in send
    r = adapter.send(request, **kwargs)
  File "C:\Users\46121\PycharmProjects\CS65_3\vr_env\lib\site-packages\requests\adapters.py", line 519, in send
    raise ConnectionError(e, request=request)
requests.exceptions.ConnectionError: HTTPConnectionPool(host='127.0.0.1', port=6800): Max retries exceeded with url: / (Caused by NewConnectionError('<urllib3.connection.HTTPConnection object at 0x000001EC57A371C0>: Failed to establish a new connection: [WinError 10061] No connection could be made because the target machine actively refused it'))
ERROR - 2022-05-18 01:03:27,852 - process: 41476 - utils.py - polls.utils - 76 - utils - [WinError 3] The system cannot find the path specified: 'C:\\Users\\46121\\PycharmProjects\\CS65_3\\cs65_4\\cs65_5\\projects\\undefined'
Traceback (most recent call last):
  File "C:\Users\46121\PycharmProjects\CS65_3\cs65_4\cs65_5\polls\utils.py", line 74, in wrapper
    result = func(*args, **kwargs)
  File "C:\Users\46121\PycharmProjects\CS65_3\vr_env\lib\site-packages\django\views\decorators\csrf.py", line 54, in wrapped_view
    return view_func(*args, **kwargs)
  File "C:\Users\46121\PycharmProjects\CS65_3\vr_env\lib\site-packages\django\views\generic\base.py", line 69, in view
    return self.dispatch(request, *args, **kwargs)
  File "C:\Users\46121\PycharmProjects\CS65_3\vr_env\lib\site-packages\rest_framework\views.py", line 509, in dispatch
    response = self.handle_exception(exc)
  File "C:\Users\46121\PycharmProjects\CS65_3\vr_env\lib\site-packages\rest_framework\views.py", line 469, in handle_exception
    self.raise_uncaught_exception(exc)
  File "C:\Users\46121\PycharmProjects\CS65_3\vr_env\lib\site-packages\rest_framework\views.py", line 480, in raise_uncaught_exception
    raise exc
  File "C:\Users\46121\PycharmProjects\CS65_3\vr_env\lib\site-packages\rest_framework\views.py", line 506, in dispatch
    response = handler(request, *args, **kwargs)
  File "C:\Users\46121\PycharmProjects\CS65_3\vr_env\lib\site-packages\rest_framework\decorators.py", line 50, in handler
    return func(*args, **kwargs)
  File "C:\Users\46121\PycharmProjects\CS65_3\cs65_4\cs65_5\polls\views.py", line 414, in project_tree
    tree = get_tree(join(path, project_name))
  File "C:\Users\46121\PycharmProjects\CS65_3\cs65_4\cs65_5\polls\utils.py", line 101, in get_tree
    for file in os.listdir(path):
FileNotFoundError: [WinError 3] The system cannot find the path specified: 'C:\\Users\\46121\\PycharmProjects\\CS65_3\\cs65_4\\cs65_5\\projects\\undefined'
ERROR - 2022-05-18 01:03:29,878 - process: 41476 - utils.py - polls.utils - 76 - utils - [WinError 3] The system cannot find the path specified: 'C:\\Users\\46121\\PycharmProjects\\CS65_3\\cs65_4\\cs65_5\\projects\\undefined'
Traceback (most recent call last):
  File "C:\Users\46121\PycharmProjects\CS65_3\cs65_4\cs65_5\polls\utils.py", line 74, in wrapper
    result = func(*args, **kwargs)
  File "C:\Users\46121\PycharmProjects\CS65_3\vr_env\lib\site-packages\django\views\decorators\csrf.py", line 54, in wrapped_view
    return view_func(*args, **kwargs)
  File "C:\Users\46121\PycharmProjects\CS65_3\vr_env\lib\site-packages\django\views\generic\base.py", line 69, in view
    return self.dispatch(request, *args, **kwargs)
  File "C:\Users\46121\PycharmProjects\CS65_3\vr_env\lib\site-packages\rest_framework\views.py", line 509, in dispatch
    response = self.handle_exception(exc)
  File "C:\Users\46121\PycharmProjects\CS65_3\vr_env\lib\site-packages\rest_framework\views.py", line 469, in handle_exception
    self.raise_uncaught_exception(exc)
  File "C:\Users\46121\PycharmProjects\CS65_3\vr_env\lib\site-packages\rest_framework\views.py", line 480, in raise_uncaught_exception
    raise exc
  File "C:\Users\46121\PycharmProjects\CS65_3\vr_env\lib\site-packages\rest_framework\views.py", line 506, in dispatch
    response = handler(request, *args, **kwargs)
  File "C:\Users\46121\PycharmProjects\CS65_3\vr_env\lib\site-packages\rest_framework\decorators.py", line 50, in handler
    return func(*args, **kwargs)
  File "C:\Users\46121\PycharmProjects\CS65_3\cs65_4\cs65_5\polls\views.py", line 414, in project_tree
    tree = get_tree(join(path, project_name))
  File "C:\Users\46121\PycharmProjects\CS65_3\cs65_4\cs65_5\polls\utils.py", line 101, in get_tree
    for file in os.listdir(path):
FileNotFoundError: [WinError 3] The system cannot find the path specified: 'C:\\Users\\46121\\PycharmProjects\\CS65_3\\cs65_4\\cs65_5\\projects\\undefined'
ERROR - 2022-05-18 01:03:31,408 - process: 41476 - utils.py - polls.utils - 76 - utils - [WinError 3] The system cannot find the path specified: 'C:\\Users\\46121\\PycharmProjects\\CS65_3\\cs65_4\\cs65_5\\projects\\undefined'
Traceback (most recent call last):
  File "C:\Users\46121\PycharmProjects\CS65_3\cs65_4\cs65_5\polls\utils.py", line 74, in wrapper
    result = func(*args, **kwargs)
  File "C:\Users\46121\PycharmProjects\CS65_3\vr_env\lib\site-packages\django\views\decorators\csrf.py", line 54, in wrapped_view
    return view_func(*args, **kwargs)
  File "C:\Users\46121\PycharmProjects\CS65_3\vr_env\lib\site-packages\django\views\generic\base.py", line 69, in view
    return self.dispatch(request, *args, **kwargs)
  File "C:\Users\46121\PycharmProjects\CS65_3\vr_env\lib\site-packages\rest_framework\views.py", line 509, in dispatch
    response = self.handle_exception(exc)
  File "C:\Users\46121\PycharmProjects\CS65_3\vr_env\lib\site-packages\rest_framework\views.py", line 469, in handle_exception
    self.raise_uncaught_exception(exc)
  File "C:\Users\46121\PycharmProjects\CS65_3\vr_env\lib\site-packages\rest_framework\views.py", line 480, in raise_uncaught_exception
    raise exc
  File "C:\Users\46121\PycharmProjects\CS65_3\vr_env\lib\site-packages\rest_framework\views.py", line 506, in dispatch
    response = handler(request, *args, **kwargs)
  File "C:\Users\46121\PycharmProjects\CS65_3\vr_env\lib\site-packages\rest_framework\decorators.py", line 50, in handler
    return func(*args, **kwargs)
  File "C:\Users\46121\PycharmProjects\CS65_3\cs65_4\cs65_5\polls\views.py", line 414, in project_tree
    tree = get_tree(join(path, project_name))
  File "C:\Users\46121\PycharmProjects\CS65_3\cs65_4\cs65_5\polls\utils.py", line 101, in get_tree
    for file in os.listdir(path):
FileNotFoundError: [WinError 3] The system cannot find the path specified: 'C:\\Users\\46121\\PycharmProjects\\CS65_3\\cs65_4\\cs65_5\\projects\\undefined'
ERROR - 2022-05-18 01:03:32,750 - process: 41476 - utils.py - polls.utils - 76 - utils - [WinError 3] The system cannot find the path specified: 'C:\\Users\\46121\\PycharmProjects\\CS65_3\\cs65_4\\cs65_5\\projects\\undefined'
Traceback (most recent call last):
  File "C:\Users\46121\PycharmProjects\CS65_3\cs65_4\cs65_5\polls\utils.py", line 74, in wrapper
    result = func(*args, **kwargs)
  File "C:\Users\46121\PycharmProjects\CS65_3\vr_env\lib\site-packages\django\views\decorators\csrf.py", line 54, in wrapped_view
    return view_func(*args, **kwargs)
  File "C:\Users\46121\PycharmProjects\CS65_3\vr_env\lib\site-packages\django\views\generic\base.py", line 69, in view
    return self.dispatch(request, *args, **kwargs)
  File "C:\Users\46121\PycharmProjects\CS65_3\vr_env\lib\site-packages\rest_framework\views.py", line 509, in dispatch
    response = self.handle_exception(exc)
  File "C:\Users\46121\PycharmProjects\CS65_3\vr_env\lib\site-packages\rest_framework\views.py", line 469, in handle_exception
    self.raise_uncaught_exception(exc)
  File "C:\Users\46121\PycharmProjects\CS65_3\vr_env\lib\site-packages\rest_framework\views.py", line 480, in raise_uncaught_exception
    raise exc
  File "C:\Users\46121\PycharmProjects\CS65_3\vr_env\lib\site-packages\rest_framework\views.py", line 506, in dispatch
    response = handler(request, *args, **kwargs)
  File "C:\Users\46121\PycharmProjects\CS65_3\vr_env\lib\site-packages\rest_framework\decorators.py", line 50, in handler
    return func(*args, **kwargs)
  File "C:\Users\46121\PycharmProjects\CS65_3\cs65_4\cs65_5\polls\views.py", line 414, in project_tree
    tree = get_tree(join(path, project_name))
  File "C:\Users\46121\PycharmProjects\CS65_3\cs65_4\cs65_5\polls\utils.py", line 101, in get_tree
    for file in os.listdir(path):
FileNotFoundError: [WinError 3] The system cannot find the path specified: 'C:\\Users\\46121\\PycharmProjects\\CS65_3\\cs65_4\\cs65_5\\projects\\undefined'
ERROR - 2022-05-18 01:03:32,987 - process: 41476 - utils.py - polls.utils - 76 - utils - HTTPConnectionPool(host='127.0.0.1', port=6800): Max retries exceeded with url: / (Caused by NewConnectionError('<urllib3.connection.HTTPConnection object at 0x000001EC57967730>: Failed to establish a new connection: [WinError 10061] No connection could be made because the target machine actively refused it'))
Traceback (most recent call last):
  File "C:\Users\46121\PycharmProjects\CS65_3\vr_env\lib\site-packages\urllib3\connection.py", line 174, in _new_conn
    conn = connection.create_connection(
  File "C:\Users\46121\PycharmProjects\CS65_3\vr_env\lib\site-packages\urllib3\util\connection.py", line 95, in create_connection
    raise err
  File "C:\Users\46121\PycharmProjects\CS65_3\vr_env\lib\site-packages\urllib3\util\connection.py", line 85, in create_connection
    sock.connect(sa)
ConnectionRefusedError: [WinError 10061] No connection could be made because the target machine actively refused it

During handling of the above exception, another exception occurred:

Traceback (most recent call last):
  File "C:\Users\46121\PycharmProjects\CS65_3\vr_env\lib\site-packages\urllib3\connectionpool.py", line 703, in urlopen
    httplib_response = self._make_request(
  File "C:\Users\46121\PycharmProjects\CS65_3\vr_env\lib\site-packages\urllib3\connectionpool.py", line 398, in _make_request
    conn.request(method, url, **httplib_request_kw)
  File "C:\Users\46121\PycharmProjects\CS65_3\vr_env\lib\site-packages\urllib3\connection.py", line 239, in request
    super(HTTPConnection, self).request(method, url, body=body, headers=headers)
  File "C:\Users\46121\AppData\Local\Programs\Python\Python38\lib\http\client.py", line 1240, in request
    self._send_request(method, url, body, headers, encode_chunked)
  File "C:\Users\46121\AppData\Local\Programs\Python\Python38\lib\http\client.py", line 1286, in _send_request
    self.endheaders(body, encode_chunked=encode_chunked)
  File "C:\Users\46121\AppData\Local\Programs\Python\Python38\lib\http\client.py", line 1235, in endheaders
    self._send_output(message_body, encode_chunked=encode_chunked)
  File "C:\Users\46121\AppData\Local\Programs\Python\Python38\lib\http\client.py", line 1006, in _send_output
    self.send(msg)
  File "C:\Users\46121\AppData\Local\Programs\Python\Python38\lib\http\client.py", line 946, in send
    self.connect()
  File "C:\Users\46121\PycharmProjects\CS65_3\vr_env\lib\site-packages\urllib3\connection.py", line 205, in connect
    conn = self._new_conn()
  File "C:\Users\46121\PycharmProjects\CS65_3\vr_env\lib\site-packages\urllib3\connection.py", line 186, in _new_conn
    raise NewConnectionError(
urllib3.exceptions.NewConnectionError: <urllib3.connection.HTTPConnection object at 0x000001EC57967730>: Failed to establish a new connection: [WinError 10061] No connection could be made because the target machine actively refused it

During handling of the above exception, another exception occurred:

Traceback (most recent call last):
  File "C:\Users\46121\PycharmProjects\CS65_3\vr_env\lib\site-packages\requests\adapters.py", line 440, in send
    resp = conn.urlopen(
  File "C:\Users\46121\PycharmProjects\CS65_3\vr_env\lib\site-packages\urllib3\connectionpool.py", line 785, in urlopen
    retries = retries.increment(
  File "C:\Users\46121\PycharmProjects\CS65_3\vr_env\lib\site-packages\urllib3\util\retry.py", line 592, in increment
    raise MaxRetryError(_pool, url, error or ResponseError(cause))
urllib3.exceptions.MaxRetryError: HTTPConnectionPool(host='127.0.0.1', port=6800): Max retries exceeded with url: / (Caused by NewConnectionError('<urllib3.connection.HTTPConnection object at 0x000001EC57967730>: Failed to establish a new connection: [WinError 10061] No connection could be made because the target machine actively refused it'))

During handling of the above exception, another exception occurred:

Traceback (most recent call last):
  File "C:\Users\46121\PycharmProjects\CS65_3\cs65_4\cs65_5\polls\utils.py", line 74, in wrapper
    result = func(*args, **kwargs)
  File "C:\Users\46121\PycharmProjects\CS65_3\vr_env\lib\site-packages\django\views\decorators\csrf.py", line 54, in wrapped_view
    return view_func(*args, **kwargs)
  File "C:\Users\46121\PycharmProjects\CS65_3\vr_env\lib\site-packages\django\views\generic\base.py", line 69, in view
    return self.dispatch(request, *args, **kwargs)
  File "C:\Users\46121\PycharmProjects\CS65_3\vr_env\lib\site-packages\rest_framework\views.py", line 509, in dispatch
    response = self.handle_exception(exc)
  File "C:\Users\46121\PycharmProjects\CS65_3\vr_env\lib\site-packages\rest_framework\views.py", line 469, in handle_exception
    self.raise_uncaught_exception(exc)
  File "C:\Users\46121\PycharmProjects\CS65_3\vr_env\lib\site-packages\rest_framework\views.py", line 480, in raise_uncaught_exception
    raise exc
  File "C:\Users\46121\PycharmProjects\CS65_3\vr_env\lib\site-packages\rest_framework\views.py", line 506, in dispatch
    response = handler(request, *args, **kwargs)
  File "C:\Users\46121\PycharmProjects\CS65_3\vr_env\lib\site-packages\rest_framework\decorators.py", line 50, in handler
    return func(*args, **kwargs)
  File "C:\Users\46121\PycharmProjects\CS65_3\cs65_4\cs65_5\polls\views.py", line 168, in client_status
    requests.get(scrapyd_url(client.ip, client.port), timeout=3)
  File "C:\Users\46121\PycharmProjects\CS65_3\vr_env\lib\site-packages\requests\api.py", line 75, in get
    return request('get', url, params=params, **kwargs)
  File "C:\Users\46121\PycharmProjects\CS65_3\vr_env\lib\site-packages\requests\api.py", line 61, in request
    return session.request(method=method, url=url, **kwargs)
  File "C:\Users\46121\PycharmProjects\CS65_3\vr_env\lib\site-packages\requests\sessions.py", line 529, in request
    resp = self.send(prep, **send_kwargs)
  File "C:\Users\46121\PycharmProjects\CS65_3\vr_env\lib\site-packages\requests\sessions.py", line 645, in send
    r = adapter.send(request, **kwargs)
  File "C:\Users\46121\PycharmProjects\CS65_3\vr_env\lib\site-packages\requests\adapters.py", line 519, in send
    raise ConnectionError(e, request=request)
requests.exceptions.ConnectionError: HTTPConnectionPool(host='127.0.0.1', port=6800): Max retries exceeded with url: / (Caused by NewConnectionError('<urllib3.connection.HTTPConnection object at 0x000001EC57967730>: Failed to establish a new connection: [WinError 10061] No connection could be made because the target machine actively refused it'))
ERROR - 2022-05-18 01:03:35,052 - process: 41476 - utils.py - polls.utils - 76 - utils - HTTPConnectionPool(host='127.0.0.1', port=6800): Max retries exceeded with url: / (Caused by NewConnectionError('<urllib3.connection.HTTPConnection object at 0x000001EC577A1100>: Failed to establish a new connection: [WinError 10061] No connection could be made because the target machine actively refused it'))
Traceback (most recent call last):
  File "C:\Users\46121\PycharmProjects\CS65_3\vr_env\lib\site-packages\urllib3\connection.py", line 174, in _new_conn
    conn = connection.create_connection(
  File "C:\Users\46121\PycharmProjects\CS65_3\vr_env\lib\site-packages\urllib3\util\connection.py", line 95, in create_connection
    raise err
  File "C:\Users\46121\PycharmProjects\CS65_3\vr_env\lib\site-packages\urllib3\util\connection.py", line 85, in create_connection
    sock.connect(sa)
ConnectionRefusedError: [WinError 10061] No connection could be made because the target machine actively refused it

During handling of the above exception, another exception occurred:

Traceback (most recent call last):
  File "C:\Users\46121\PycharmProjects\CS65_3\vr_env\lib\site-packages\urllib3\connectionpool.py", line 703, in urlopen
    httplib_response = self._make_request(
  File "C:\Users\46121\PycharmProjects\CS65_3\vr_env\lib\site-packages\urllib3\connectionpool.py", line 398, in _make_request
    conn.request(method, url, **httplib_request_kw)
  File "C:\Users\46121\PycharmProjects\CS65_3\vr_env\lib\site-packages\urllib3\connection.py", line 239, in request
    super(HTTPConnection, self).request(method, url, body=body, headers=headers)
  File "C:\Users\46121\AppData\Local\Programs\Python\Python38\lib\http\client.py", line 1240, in request
    self._send_request(method, url, body, headers, encode_chunked)
  File "C:\Users\46121\AppData\Local\Programs\Python\Python38\lib\http\client.py", line 1286, in _send_request
    self.endheaders(body, encode_chunked=encode_chunked)
  File "C:\Users\46121\AppData\Local\Programs\Python\Python38\lib\http\client.py", line 1235, in endheaders
    self._send_output(message_body, encode_chunked=encode_chunked)
  File "C:\Users\46121\AppData\Local\Programs\Python\Python38\lib\http\client.py", line 1006, in _send_output
    self.send(msg)
  File "C:\Users\46121\AppData\Local\Programs\Python\Python38\lib\http\client.py", line 946, in send
    self.connect()
  File "C:\Users\46121\PycharmProjects\CS65_3\vr_env\lib\site-packages\urllib3\connection.py", line 205, in connect
    conn = self._new_conn()
  File "C:\Users\46121\PycharmProjects\CS65_3\vr_env\lib\site-packages\urllib3\connection.py", line 186, in _new_conn
    raise NewConnectionError(
urllib3.exceptions.NewConnectionError: <urllib3.connection.HTTPConnection object at 0x000001EC577A1100>: Failed to establish a new connection: [WinError 10061] No connection could be made because the target machine actively refused it

During handling of the above exception, another exception occurred:

Traceback (most recent call last):
  File "C:\Users\46121\PycharmProjects\CS65_3\vr_env\lib\site-packages\requests\adapters.py", line 440, in send
    resp = conn.urlopen(
  File "C:\Users\46121\PycharmProjects\CS65_3\vr_env\lib\site-packages\urllib3\connectionpool.py", line 785, in urlopen
    retries = retries.increment(
  File "C:\Users\46121\PycharmProjects\CS65_3\vr_env\lib\site-packages\urllib3\util\retry.py", line 592, in increment
    raise MaxRetryError(_pool, url, error or ResponseError(cause))
urllib3.exceptions.MaxRetryError: HTTPConnectionPool(host='127.0.0.1', port=6800): Max retries exceeded with url: / (Caused by NewConnectionError('<urllib3.connection.HTTPConnection object at 0x000001EC577A1100>: Failed to establish a new connection: [WinError 10061] No connection could be made because the target machine actively refused it'))

During handling of the above exception, another exception occurred:

Traceback (most recent call last):
  File "C:\Users\46121\PycharmProjects\CS65_3\cs65_4\cs65_5\polls\utils.py", line 74, in wrapper
    result = func(*args, **kwargs)
  File "C:\Users\46121\PycharmProjects\CS65_3\vr_env\lib\site-packages\django\views\decorators\csrf.py", line 54, in wrapped_view
    return view_func(*args, **kwargs)
  File "C:\Users\46121\PycharmProjects\CS65_3\vr_env\lib\site-packages\django\views\generic\base.py", line 69, in view
    return self.dispatch(request, *args, **kwargs)
  File "C:\Users\46121\PycharmProjects\CS65_3\vr_env\lib\site-packages\rest_framework\views.py", line 509, in dispatch
    response = self.handle_exception(exc)
  File "C:\Users\46121\PycharmProjects\CS65_3\vr_env\lib\site-packages\rest_framework\views.py", line 469, in handle_exception
    self.raise_uncaught_exception(exc)
  File "C:\Users\46121\PycharmProjects\CS65_3\vr_env\lib\site-packages\rest_framework\views.py", line 480, in raise_uncaught_exception
    raise exc
  File "C:\Users\46121\PycharmProjects\CS65_3\vr_env\lib\site-packages\rest_framework\views.py", line 506, in dispatch
    response = handler(request, *args, **kwargs)
  File "C:\Users\46121\PycharmProjects\CS65_3\vr_env\lib\site-packages\rest_framework\decorators.py", line 50, in handler
    return func(*args, **kwargs)
  File "C:\Users\46121\PycharmProjects\CS65_3\cs65_4\cs65_5\polls\views.py", line 168, in client_status
    requests.get(scrapyd_url(client.ip, client.port), timeout=3)
  File "C:\Users\46121\PycharmProjects\CS65_3\vr_env\lib\site-packages\requests\api.py", line 75, in get
    return request('get', url, params=params, **kwargs)
  File "C:\Users\46121\PycharmProjects\CS65_3\vr_env\lib\site-packages\requests\api.py", line 61, in request
    return session.request(method=method, url=url, **kwargs)
  File "C:\Users\46121\PycharmProjects\CS65_3\vr_env\lib\site-packages\requests\sessions.py", line 529, in request
    resp = self.send(prep, **send_kwargs)
  File "C:\Users\46121\PycharmProjects\CS65_3\vr_env\lib\site-packages\requests\sessions.py", line 645, in send
    r = adapter.send(request, **kwargs)
  File "C:\Users\46121\PycharmProjects\CS65_3\vr_env\lib\site-packages\requests\adapters.py", line 519, in send
    raise ConnectionError(e, request=request)
requests.exceptions.ConnectionError: HTTPConnectionPool(host='127.0.0.1', port=6800): Max retries exceeded with url: / (Caused by NewConnectionError('<urllib3.connection.HTTPConnection object at 0x000001EC577A1100>: Failed to establish a new connection: [WinError 10061] No connection could be made because the target machine actively refused it'))
ERROR - 2022-05-18 13:45:29,127 - process: 41476 - utils.py - polls.utils - 76 - utils - [WinError 3] The system cannot find the path specified: 'C:\\Users\\46121\\PycharmProjects\\CS65_3\\cs65_4\\cs65_5\\projects\\undefined'
Traceback (most recent call last):
  File "C:\Users\46121\PycharmProjects\CS65_3\cs65_4\cs65_5\polls\utils.py", line 74, in wrapper
    result = func(*args, **kwargs)
  File "C:\Users\46121\PycharmProjects\CS65_3\vr_env\lib\site-packages\django\views\decorators\csrf.py", line 54, in wrapped_view
    return view_func(*args, **kwargs)
  File "C:\Users\46121\PycharmProjects\CS65_3\vr_env\lib\site-packages\django\views\generic\base.py", line 69, in view
    return self.dispatch(request, *args, **kwargs)
  File "C:\Users\46121\PycharmProjects\CS65_3\vr_env\lib\site-packages\rest_framework\views.py", line 509, in dispatch
    response = self.handle_exception(exc)
  File "C:\Users\46121\PycharmProjects\CS65_3\vr_env\lib\site-packages\rest_framework\views.py", line 469, in handle_exception
    self.raise_uncaught_exception(exc)
  File "C:\Users\46121\PycharmProjects\CS65_3\vr_env\lib\site-packages\rest_framework\views.py", line 480, in raise_uncaught_exception
    raise exc
  File "C:\Users\46121\PycharmProjects\CS65_3\vr_env\lib\site-packages\rest_framework\views.py", line 506, in dispatch
    response = handler(request, *args, **kwargs)
  File "C:\Users\46121\PycharmProjects\CS65_3\vr_env\lib\site-packages\rest_framework\decorators.py", line 50, in handler
    return func(*args, **kwargs)
  File "C:\Users\46121\PycharmProjects\CS65_3\cs65_4\cs65_5\polls\views.py", line 414, in project_tree
    tree = get_tree(join(path, project_name))
  File "C:\Users\46121\PycharmProjects\CS65_3\cs65_4\cs65_5\polls\utils.py", line 101, in get_tree
    for file in os.listdir(path):
FileNotFoundError: [WinError 3] The system cannot find the path specified: 'C:\\Users\\46121\\PycharmProjects\\CS65_3\\cs65_4\\cs65_5\\projects\\undefined'
ERROR - 2022-05-18 13:45:32,629 - process: 41476 - utils.py - polls.utils - 76 - utils - HTTPConnectionPool(host='127.0.0.1', port=6800): Max retries exceeded with url: / (Caused by NewConnectionError('<urllib3.connection.HTTPConnection object at 0x000001EC57B2BA00>: Failed to establish a new connection: [WinError 10061] No connection could be made because the target machine actively refused it'))
Traceback (most recent call last):
  File "C:\Users\46121\PycharmProjects\CS65_3\vr_env\lib\site-packages\urllib3\connection.py", line 174, in _new_conn
    conn = connection.create_connection(
  File "C:\Users\46121\PycharmProjects\CS65_3\vr_env\lib\site-packages\urllib3\util\connection.py", line 95, in create_connection
    raise err
  File "C:\Users\46121\PycharmProjects\CS65_3\vr_env\lib\site-packages\urllib3\util\connection.py", line 85, in create_connection
    sock.connect(sa)
ConnectionRefusedError: [WinError 10061] No connection could be made because the target machine actively refused it

During handling of the above exception, another exception occurred:

Traceback (most recent call last):
  File "C:\Users\46121\PycharmProjects\CS65_3\vr_env\lib\site-packages\urllib3\connectionpool.py", line 703, in urlopen
    httplib_response = self._make_request(
  File "C:\Users\46121\PycharmProjects\CS65_3\vr_env\lib\site-packages\urllib3\connectionpool.py", line 398, in _make_request
    conn.request(method, url, **httplib_request_kw)
  File "C:\Users\46121\PycharmProjects\CS65_3\vr_env\lib\site-packages\urllib3\connection.py", line 239, in request
    super(HTTPConnection, self).request(method, url, body=body, headers=headers)
  File "C:\Users\46121\AppData\Local\Programs\Python\Python38\lib\http\client.py", line 1240, in request
    self._send_request(method, url, body, headers, encode_chunked)
  File "C:\Users\46121\AppData\Local\Programs\Python\Python38\lib\http\client.py", line 1286, in _send_request
    self.endheaders(body, encode_chunked=encode_chunked)
  File "C:\Users\46121\AppData\Local\Programs\Python\Python38\lib\http\client.py", line 1235, in endheaders
    self._send_output(message_body, encode_chunked=encode_chunked)
  File "C:\Users\46121\AppData\Local\Programs\Python\Python38\lib\http\client.py", line 1006, in _send_output
    self.send(msg)
  File "C:\Users\46121\AppData\Local\Programs\Python\Python38\lib\http\client.py", line 946, in send
    self.connect()
  File "C:\Users\46121\PycharmProjects\CS65_3\vr_env\lib\site-packages\urllib3\connection.py", line 205, in connect
    conn = self._new_conn()
  File "C:\Users\46121\PycharmProjects\CS65_3\vr_env\lib\site-packages\urllib3\connection.py", line 186, in _new_conn
    raise NewConnectionError(
urllib3.exceptions.NewConnectionError: <urllib3.connection.HTTPConnection object at 0x000001EC57B2BA00>: Failed to establish a new connection: [WinError 10061] No connection could be made because the target machine actively refused it

During handling of the above exception, another exception occurred:

Traceback (most recent call last):
  File "C:\Users\46121\PycharmProjects\CS65_3\vr_env\lib\site-packages\requests\adapters.py", line 440, in send
    resp = conn.urlopen(
  File "C:\Users\46121\PycharmProjects\CS65_3\vr_env\lib\site-packages\urllib3\connectionpool.py", line 785, in urlopen
    retries = retries.increment(
  File "C:\Users\46121\PycharmProjects\CS65_3\vr_env\lib\site-packages\urllib3\util\retry.py", line 592, in increment
    raise MaxRetryError(_pool, url, error or ResponseError(cause))
urllib3.exceptions.MaxRetryError: HTTPConnectionPool(host='127.0.0.1', port=6800): Max retries exceeded with url: / (Caused by NewConnectionError('<urllib3.connection.HTTPConnection object at 0x000001EC57B2BA00>: Failed to establish a new connection: [WinError 10061] No connection could be made because the target machine actively refused it'))

During handling of the above exception, another exception occurred:

Traceback (most recent call last):
  File "C:\Users\46121\PycharmProjects\CS65_3\cs65_4\cs65_5\polls\utils.py", line 74, in wrapper
    result = func(*args, **kwargs)
  File "C:\Users\46121\PycharmProjects\CS65_3\vr_env\lib\site-packages\django\views\decorators\csrf.py", line 54, in wrapped_view
    return view_func(*args, **kwargs)
  File "C:\Users\46121\PycharmProjects\CS65_3\vr_env\lib\site-packages\django\views\generic\base.py", line 69, in view
    return self.dispatch(request, *args, **kwargs)
  File "C:\Users\46121\PycharmProjects\CS65_3\vr_env\lib\site-packages\rest_framework\views.py", line 509, in dispatch
    response = self.handle_exception(exc)
  File "C:\Users\46121\PycharmProjects\CS65_3\vr_env\lib\site-packages\rest_framework\views.py", line 469, in handle_exception
    self.raise_uncaught_exception(exc)
  File "C:\Users\46121\PycharmProjects\CS65_3\vr_env\lib\site-packages\rest_framework\views.py", line 480, in raise_uncaught_exception
    raise exc
  File "C:\Users\46121\PycharmProjects\CS65_3\vr_env\lib\site-packages\rest_framework\views.py", line 506, in dispatch
    response = handler(request, *args, **kwargs)
  File "C:\Users\46121\PycharmProjects\CS65_3\vr_env\lib\site-packages\rest_framework\decorators.py", line 50, in handler
    return func(*args, **kwargs)
  File "C:\Users\46121\PycharmProjects\CS65_3\cs65_4\cs65_5\polls\views.py", line 168, in client_status
    requests.get(scrapyd_url(client.ip, client.port), timeout=3)
  File "C:\Users\46121\PycharmProjects\CS65_3\vr_env\lib\site-packages\requests\api.py", line 75, in get
    return request('get', url, params=params, **kwargs)
  File "C:\Users\46121\PycharmProjects\CS65_3\vr_env\lib\site-packages\requests\api.py", line 61, in request
    return session.request(method=method, url=url, **kwargs)
  File "C:\Users\46121\PycharmProjects\CS65_3\vr_env\lib\site-packages\requests\sessions.py", line 529, in request
    resp = self.send(prep, **send_kwargs)
  File "C:\Users\46121\PycharmProjects\CS65_3\vr_env\lib\site-packages\requests\sessions.py", line 645, in send
    r = adapter.send(request, **kwargs)
  File "C:\Users\46121\PycharmProjects\CS65_3\vr_env\lib\site-packages\requests\adapters.py", line 519, in send
    raise ConnectionError(e, request=request)
requests.exceptions.ConnectionError: HTTPConnectionPool(host='127.0.0.1', port=6800): Max retries exceeded with url: / (Caused by NewConnectionError('<urllib3.connection.HTTPConnection object at 0x000001EC57B2BA00>: Failed to establish a new connection: [WinError 10061] No connection could be made because the target machine actively refused it'))
ERROR - 2022-05-18 13:45:52,707 - process: 41476 - utils.py - polls.utils - 76 - utils - HTTPConnectionPool(host='127.0.0.1', port=6800): Max retries exceeded with url: / (Caused by NewConnectionError('<urllib3.connection.HTTPConnection object at 0x000001EC57B34D00>: Failed to establish a new connection: [WinError 10061] No connection could be made because the target machine actively refused it'))
Traceback (most recent call last):
  File "C:\Users\46121\PycharmProjects\CS65_3\vr_env\lib\site-packages\urllib3\connection.py", line 174, in _new_conn
    conn = connection.create_connection(
  File "C:\Users\46121\PycharmProjects\CS65_3\vr_env\lib\site-packages\urllib3\util\connection.py", line 95, in create_connection
    raise err
  File "C:\Users\46121\PycharmProjects\CS65_3\vr_env\lib\site-packages\urllib3\util\connection.py", line 85, in create_connection
    sock.connect(sa)
ConnectionRefusedError: [WinError 10061] No connection could be made because the target machine actively refused it

During handling of the above exception, another exception occurred:

Traceback (most recent call last):
  File "C:\Users\46121\PycharmProjects\CS65_3\vr_env\lib\site-packages\urllib3\connectionpool.py", line 703, in urlopen
    httplib_response = self._make_request(
  File "C:\Users\46121\PycharmProjects\CS65_3\vr_env\lib\site-packages\urllib3\connectionpool.py", line 398, in _make_request
    conn.request(method, url, **httplib_request_kw)
  File "C:\Users\46121\PycharmProjects\CS65_3\vr_env\lib\site-packages\urllib3\connection.py", line 239, in request
    super(HTTPConnection, self).request(method, url, body=body, headers=headers)
  File "C:\Users\46121\AppData\Local\Programs\Python\Python38\lib\http\client.py", line 1240, in request
    self._send_request(method, url, body, headers, encode_chunked)
  File "C:\Users\46121\AppData\Local\Programs\Python\Python38\lib\http\client.py", line 1286, in _send_request
    self.endheaders(body, encode_chunked=encode_chunked)
  File "C:\Users\46121\AppData\Local\Programs\Python\Python38\lib\http\client.py", line 1235, in endheaders
    self._send_output(message_body, encode_chunked=encode_chunked)
  File "C:\Users\46121\AppData\Local\Programs\Python\Python38\lib\http\client.py", line 1006, in _send_output
    self.send(msg)
  File "C:\Users\46121\AppData\Local\Programs\Python\Python38\lib\http\client.py", line 946, in send
    self.connect()
  File "C:\Users\46121\PycharmProjects\CS65_3\vr_env\lib\site-packages\urllib3\connection.py", line 205, in connect
    conn = self._new_conn()
  File "C:\Users\46121\PycharmProjects\CS65_3\vr_env\lib\site-packages\urllib3\connection.py", line 186, in _new_conn
    raise NewConnectionError(
urllib3.exceptions.NewConnectionError: <urllib3.connection.HTTPConnection object at 0x000001EC57B34D00>: Failed to establish a new connection: [WinError 10061] No connection could be made because the target machine actively refused it

During handling of the above exception, another exception occurred:

Traceback (most recent call last):
  File "C:\Users\46121\PycharmProjects\CS65_3\vr_env\lib\site-packages\requests\adapters.py", line 440, in send
    resp = conn.urlopen(
  File "C:\Users\46121\PycharmProjects\CS65_3\vr_env\lib\site-packages\urllib3\connectionpool.py", line 785, in urlopen
    retries = retries.increment(
  File "C:\Users\46121\PycharmProjects\CS65_3\vr_env\lib\site-packages\urllib3\util\retry.py", line 592, in increment
    raise MaxRetryError(_pool, url, error or ResponseError(cause))
urllib3.exceptions.MaxRetryError: HTTPConnectionPool(host='127.0.0.1', port=6800): Max retries exceeded with url: / (Caused by NewConnectionError('<urllib3.connection.HTTPConnection object at 0x000001EC57B34D00>: Failed to establish a new connection: [WinError 10061] No connection could be made because the target machine actively refused it'))

During handling of the above exception, another exception occurred:

Traceback (most recent call last):
  File "C:\Users\46121\PycharmProjects\CS65_3\cs65_4\cs65_5\polls\utils.py", line 74, in wrapper
    result = func(*args, **kwargs)
  File "C:\Users\46121\PycharmProjects\CS65_3\vr_env\lib\site-packages\django\views\decorators\csrf.py", line 54, in wrapped_view
    return view_func(*args, **kwargs)
  File "C:\Users\46121\PycharmProjects\CS65_3\vr_env\lib\site-packages\django\views\generic\base.py", line 69, in view
    return self.dispatch(request, *args, **kwargs)
  File "C:\Users\46121\PycharmProjects\CS65_3\vr_env\lib\site-packages\rest_framework\views.py", line 509, in dispatch
    response = self.handle_exception(exc)
  File "C:\Users\46121\PycharmProjects\CS65_3\vr_env\lib\site-packages\rest_framework\views.py", line 469, in handle_exception
    self.raise_uncaught_exception(exc)
  File "C:\Users\46121\PycharmProjects\CS65_3\vr_env\lib\site-packages\rest_framework\views.py", line 480, in raise_uncaught_exception
    raise exc
  File "C:\Users\46121\PycharmProjects\CS65_3\vr_env\lib\site-packages\rest_framework\views.py", line 506, in dispatch
    response = handler(request, *args, **kwargs)
  File "C:\Users\46121\PycharmProjects\CS65_3\vr_env\lib\site-packages\rest_framework\decorators.py", line 50, in handler
    return func(*args, **kwargs)
  File "C:\Users\46121\PycharmProjects\CS65_3\cs65_4\cs65_5\polls\views.py", line 168, in client_status
    requests.get(scrapyd_url(client.ip, client.port), timeout=3)
  File "C:\Users\46121\PycharmProjects\CS65_3\vr_env\lib\site-packages\requests\api.py", line 75, in get
    return request('get', url, params=params, **kwargs)
  File "C:\Users\46121\PycharmProjects\CS65_3\vr_env\lib\site-packages\requests\api.py", line 61, in request
    return session.request(method=method, url=url, **kwargs)
  File "C:\Users\46121\PycharmProjects\CS65_3\vr_env\lib\site-packages\requests\sessions.py", line 529, in request
    resp = self.send(prep, **send_kwargs)
  File "C:\Users\46121\PycharmProjects\CS65_3\vr_env\lib\site-packages\requests\sessions.py", line 645, in send
    r = adapter.send(request, **kwargs)
  File "C:\Users\46121\PycharmProjects\CS65_3\vr_env\lib\site-packages\requests\adapters.py", line 519, in send
    raise ConnectionError(e, request=request)
requests.exceptions.ConnectionError: HTTPConnectionPool(host='127.0.0.1', port=6800): Max retries exceeded with url: / (Caused by NewConnectionError('<urllib3.connection.HTTPConnection object at 0x000001EC57B34D00>: Failed to establish a new connection: [WinError 10061] No connection could be made because the target machine actively refused it'))
ERROR - 2022-05-18 13:45:56,666 - process: 41476 - utils.py - polls.utils - 76 - utils - HTTPConnectionPool(host='127.0.0.1', port=6800): Max retries exceeded with url: / (Caused by NewConnectionError('<urllib3.connection.HTTPConnection object at 0x000001EC57A25A30>: Failed to establish a new connection: [WinError 10061] No connection could be made because the target machine actively refused it'))
Traceback (most recent call last):
  File "C:\Users\46121\PycharmProjects\CS65_3\vr_env\lib\site-packages\urllib3\connection.py", line 174, in _new_conn
    conn = connection.create_connection(
  File "C:\Users\46121\PycharmProjects\CS65_3\vr_env\lib\site-packages\urllib3\util\connection.py", line 95, in create_connection
    raise err
  File "C:\Users\46121\PycharmProjects\CS65_3\vr_env\lib\site-packages\urllib3\util\connection.py", line 85, in create_connection
    sock.connect(sa)
ConnectionRefusedError: [WinError 10061] No connection could be made because the target machine actively refused it

During handling of the above exception, another exception occurred:

Traceback (most recent call last):
  File "C:\Users\46121\PycharmProjects\CS65_3\vr_env\lib\site-packages\urllib3\connectionpool.py", line 703, in urlopen
    httplib_response = self._make_request(
  File "C:\Users\46121\PycharmProjects\CS65_3\vr_env\lib\site-packages\urllib3\connectionpool.py", line 398, in _make_request
    conn.request(method, url, **httplib_request_kw)
  File "C:\Users\46121\PycharmProjects\CS65_3\vr_env\lib\site-packages\urllib3\connection.py", line 239, in request
    super(HTTPConnection, self).request(method, url, body=body, headers=headers)
  File "C:\Users\46121\AppData\Local\Programs\Python\Python38\lib\http\client.py", line 1240, in request
    self._send_request(method, url, body, headers, encode_chunked)
  File "C:\Users\46121\AppData\Local\Programs\Python\Python38\lib\http\client.py", line 1286, in _send_request
    self.endheaders(body, encode_chunked=encode_chunked)
  File "C:\Users\46121\AppData\Local\Programs\Python\Python38\lib\http\client.py", line 1235, in endheaders
    self._send_output(message_body, encode_chunked=encode_chunked)
  File "C:\Users\46121\AppData\Local\Programs\Python\Python38\lib\http\client.py", line 1006, in _send_output
    self.send(msg)
  File "C:\Users\46121\AppData\Local\Programs\Python\Python38\lib\http\client.py", line 946, in send
    self.connect()
  File "C:\Users\46121\PycharmProjects\CS65_3\vr_env\lib\site-packages\urllib3\connection.py", line 205, in connect
    conn = self._new_conn()
  File "C:\Users\46121\PycharmProjects\CS65_3\vr_env\lib\site-packages\urllib3\connection.py", line 186, in _new_conn
    raise NewConnectionError(
urllib3.exceptions.NewConnectionError: <urllib3.connection.HTTPConnection object at 0x000001EC57A25A30>: Failed to establish a new connection: [WinError 10061] No connection could be made because the target machine actively refused it

During handling of the above exception, another exception occurred:

Traceback (most recent call last):
  File "C:\Users\46121\PycharmProjects\CS65_3\vr_env\lib\site-packages\requests\adapters.py", line 440, in send
    resp = conn.urlopen(
  File "C:\Users\46121\PycharmProjects\CS65_3\vr_env\lib\site-packages\urllib3\connectionpool.py", line 785, in urlopen
    retries = retries.increment(
  File "C:\Users\46121\PycharmProjects\CS65_3\vr_env\lib\site-packages\urllib3\util\retry.py", line 592, in increment
    raise MaxRetryError(_pool, url, error or ResponseError(cause))
urllib3.exceptions.MaxRetryError: HTTPConnectionPool(host='127.0.0.1', port=6800): Max retries exceeded with url: / (Caused by NewConnectionError('<urllib3.connection.HTTPConnection object at 0x000001EC57A25A30>: Failed to establish a new connection: [WinError 10061] No connection could be made because the target machine actively refused it'))

During handling of the above exception, another exception occurred:

Traceback (most recent call last):
  File "C:\Users\46121\PycharmProjects\CS65_3\cs65_4\cs65_5\polls\utils.py", line 74, in wrapper
    result = func(*args, **kwargs)
  File "C:\Users\46121\PycharmProjects\CS65_3\vr_env\lib\site-packages\django\views\decorators\csrf.py", line 54, in wrapped_view
    return view_func(*args, **kwargs)
  File "C:\Users\46121\PycharmProjects\CS65_3\vr_env\lib\site-packages\django\views\generic\base.py", line 69, in view
    return self.dispatch(request, *args, **kwargs)
  File "C:\Users\46121\PycharmProjects\CS65_3\vr_env\lib\site-packages\rest_framework\views.py", line 509, in dispatch
    response = self.handle_exception(exc)
  File "C:\Users\46121\PycharmProjects\CS65_3\vr_env\lib\site-packages\rest_framework\views.py", line 469, in handle_exception
    self.raise_uncaught_exception(exc)
  File "C:\Users\46121\PycharmProjects\CS65_3\vr_env\lib\site-packages\rest_framework\views.py", line 480, in raise_uncaught_exception
    raise exc
  File "C:\Users\46121\PycharmProjects\CS65_3\vr_env\lib\site-packages\rest_framework\views.py", line 506, in dispatch
    response = handler(request, *args, **kwargs)
  File "C:\Users\46121\PycharmProjects\CS65_3\vr_env\lib\site-packages\rest_framework\decorators.py", line 50, in handler
    return func(*args, **kwargs)
  File "C:\Users\46121\PycharmProjects\CS65_3\cs65_4\cs65_5\polls\views.py", line 168, in client_status
    requests.get(scrapyd_url(client.ip, client.port), timeout=3)
  File "C:\Users\46121\PycharmProjects\CS65_3\vr_env\lib\site-packages\requests\api.py", line 75, in get
    return request('get', url, params=params, **kwargs)
  File "C:\Users\46121\PycharmProjects\CS65_3\vr_env\lib\site-packages\requests\api.py", line 61, in request
    return session.request(method=method, url=url, **kwargs)
  File "C:\Users\46121\PycharmProjects\CS65_3\vr_env\lib\site-packages\requests\sessions.py", line 529, in request
    resp = self.send(prep, **send_kwargs)
  File "C:\Users\46121\PycharmProjects\CS65_3\vr_env\lib\site-packages\requests\sessions.py", line 645, in send
    r = adapter.send(request, **kwargs)
  File "C:\Users\46121\PycharmProjects\CS65_3\vr_env\lib\site-packages\requests\adapters.py", line 519, in send
    raise ConnectionError(e, request=request)
requests.exceptions.ConnectionError: HTTPConnectionPool(host='127.0.0.1', port=6800): Max retries exceeded with url: / (Caused by NewConnectionError('<urllib3.connection.HTTPConnection object at 0x000001EC57A25A30>: Failed to establish a new connection: [WinError 10061] No connection could be made because the target machine actively refused it'))
ERROR - 2022-05-18 13:46:51,750 - process: 41476 - utils.py - polls.utils - 76 - utils - [WinError 3] The system cannot find the path specified: 'C:\\Users\\46121\\PycharmProjects\\CS65_3\\cs65_4\\cs65_5\\projects\\undefined'
Traceback (most recent call last):
  File "C:\Users\46121\PycharmProjects\CS65_3\cs65_4\cs65_5\polls\utils.py", line 74, in wrapper
    result = func(*args, **kwargs)
  File "C:\Users\46121\PycharmProjects\CS65_3\vr_env\lib\site-packages\django\views\decorators\csrf.py", line 54, in wrapped_view
    return view_func(*args, **kwargs)
  File "C:\Users\46121\PycharmProjects\CS65_3\vr_env\lib\site-packages\django\views\generic\base.py", line 69, in view
    return self.dispatch(request, *args, **kwargs)
  File "C:\Users\46121\PycharmProjects\CS65_3\vr_env\lib\site-packages\rest_framework\views.py", line 509, in dispatch
    response = self.handle_exception(exc)
  File "C:\Users\46121\PycharmProjects\CS65_3\vr_env\lib\site-packages\rest_framework\views.py", line 469, in handle_exception
    self.raise_uncaught_exception(exc)
  File "C:\Users\46121\PycharmProjects\CS65_3\vr_env\lib\site-packages\rest_framework\views.py", line 480, in raise_uncaught_exception
    raise exc
  File "C:\Users\46121\PycharmProjects\CS65_3\vr_env\lib\site-packages\rest_framework\views.py", line 506, in dispatch
    response = handler(request, *args, **kwargs)
  File "C:\Users\46121\PycharmProjects\CS65_3\vr_env\lib\site-packages\rest_framework\decorators.py", line 50, in handler
    return func(*args, **kwargs)
  File "C:\Users\46121\PycharmProjects\CS65_3\cs65_4\cs65_5\polls\views.py", line 414, in project_tree
    tree = get_tree(join(path, project_name))
  File "C:\Users\46121\PycharmProjects\CS65_3\cs65_4\cs65_5\polls\utils.py", line 101, in get_tree
    for file in os.listdir(path):
FileNotFoundError: [WinError 3] The system cannot find the path specified: 'C:\\Users\\46121\\PycharmProjects\\CS65_3\\cs65_4\\cs65_5\\projects\\undefined'
ERROR - 2022-05-18 14:02:58,391 - process: 41476 - utils.py - polls.utils - 76 - utils - [WinError 3] The system cannot find the path specified: 'C:\\Users\\46121\\PycharmProjects\\CS65_3\\cs65_4\\cs65_5\\projects\\undefined'
Traceback (most recent call last):
  File "C:\Users\46121\PycharmProjects\CS65_3\cs65_4\cs65_5\polls\utils.py", line 74, in wrapper
    result = func(*args, **kwargs)
  File "C:\Users\46121\PycharmProjects\CS65_3\vr_env\lib\site-packages\django\views\decorators\csrf.py", line 54, in wrapped_view
    return view_func(*args, **kwargs)
  File "C:\Users\46121\PycharmProjects\CS65_3\vr_env\lib\site-packages\django\views\generic\base.py", line 69, in view
    return self.dispatch(request, *args, **kwargs)
  File "C:\Users\46121\PycharmProjects\CS65_3\vr_env\lib\site-packages\rest_framework\views.py", line 509, in dispatch
    response = self.handle_exception(exc)
  File "C:\Users\46121\PycharmProjects\CS65_3\vr_env\lib\site-packages\rest_framework\views.py", line 469, in handle_exception
    self.raise_uncaught_exception(exc)
  File "C:\Users\46121\PycharmProjects\CS65_3\vr_env\lib\site-packages\rest_framework\views.py", line 480, in raise_uncaught_exception
    raise exc
  File "C:\Users\46121\PycharmProjects\CS65_3\vr_env\lib\site-packages\rest_framework\views.py", line 506, in dispatch
    response = handler(request, *args, **kwargs)
  File "C:\Users\46121\PycharmProjects\CS65_3\vr_env\lib\site-packages\rest_framework\decorators.py", line 50, in handler
    return func(*args, **kwargs)
  File "C:\Users\46121\PycharmProjects\CS65_3\cs65_4\cs65_5\polls\views.py", line 414, in project_tree
    tree = get_tree(join(path, project_name))
  File "C:\Users\46121\PycharmProjects\CS65_3\cs65_4\cs65_5\polls\utils.py", line 101, in get_tree
    for file in os.listdir(path):
FileNotFoundError: [WinError 3] The system cannot find the path specified: 'C:\\Users\\46121\\PycharmProjects\\CS65_3\\cs65_4\\cs65_5\\projects\\undefined'
ERROR - 2022-05-18 14:03:01,024 - process: 41476 - utils.py - polls.utils - 76 - utils - [WinError 3] The system cannot find the path specified: 'C:\\Users\\46121\\PycharmProjects\\CS65_3\\cs65_4\\cs65_5\\projects\\undefined'
Traceback (most recent call last):
  File "C:\Users\46121\PycharmProjects\CS65_3\cs65_4\cs65_5\polls\utils.py", line 74, in wrapper
    result = func(*args, **kwargs)
  File "C:\Users\46121\PycharmProjects\CS65_3\vr_env\lib\site-packages\django\views\decorators\csrf.py", line 54, in wrapped_view
    return view_func(*args, **kwargs)
  File "C:\Users\46121\PycharmProjects\CS65_3\vr_env\lib\site-packages\django\views\generic\base.py", line 69, in view
    return self.dispatch(request, *args, **kwargs)
  File "C:\Users\46121\PycharmProjects\CS65_3\vr_env\lib\site-packages\rest_framework\views.py", line 509, in dispatch
    response = self.handle_exception(exc)
  File "C:\Users\46121\PycharmProjects\CS65_3\vr_env\lib\site-packages\rest_framework\views.py", line 469, in handle_exception
    self.raise_uncaught_exception(exc)
  File "C:\Users\46121\PycharmProjects\CS65_3\vr_env\lib\site-packages\rest_framework\views.py", line 480, in raise_uncaught_exception
    raise exc
  File "C:\Users\46121\PycharmProjects\CS65_3\vr_env\lib\site-packages\rest_framework\views.py", line 506, in dispatch
    response = handler(request, *args, **kwargs)
  File "C:\Users\46121\PycharmProjects\CS65_3\vr_env\lib\site-packages\rest_framework\decorators.py", line 50, in handler
    return func(*args, **kwargs)
  File "C:\Users\46121\PycharmProjects\CS65_3\cs65_4\cs65_5\polls\views.py", line 414, in project_tree
    tree = get_tree(join(path, project_name))
  File "C:\Users\46121\PycharmProjects\CS65_3\cs65_4\cs65_5\polls\utils.py", line 101, in get_tree
    for file in os.listdir(path):
FileNotFoundError: [WinError 3] The system cannot find the path specified: 'C:\\Users\\46121\\PycharmProjects\\CS65_3\\cs65_4\\cs65_5\\projects\\undefined'
ERROR - 2022-05-18 14:03:08,407 - process: 41476 - utils.py - polls.utils - 76 - utils - [WinError 3] The system cannot find the path specified: 'C:\\Users\\46121\\PycharmProjects\\CS65_3\\cs65_4\\cs65_5\\projects\\undefined'
Traceback (most recent call last):
  File "C:\Users\46121\PycharmProjects\CS65_3\cs65_4\cs65_5\polls\utils.py", line 74, in wrapper
    result = func(*args, **kwargs)
  File "C:\Users\46121\PycharmProjects\CS65_3\vr_env\lib\site-packages\django\views\decorators\csrf.py", line 54, in wrapped_view
    return view_func(*args, **kwargs)
  File "C:\Users\46121\PycharmProjects\CS65_3\vr_env\lib\site-packages\django\views\generic\base.py", line 69, in view
    return self.dispatch(request, *args, **kwargs)
  File "C:\Users\46121\PycharmProjects\CS65_3\vr_env\lib\site-packages\rest_framework\views.py", line 509, in dispatch
    response = self.handle_exception(exc)
  File "C:\Users\46121\PycharmProjects\CS65_3\vr_env\lib\site-packages\rest_framework\views.py", line 469, in handle_exception
    self.raise_uncaught_exception(exc)
  File "C:\Users\46121\PycharmProjects\CS65_3\vr_env\lib\site-packages\rest_framework\views.py", line 480, in raise_uncaught_exception
    raise exc
  File "C:\Users\46121\PycharmProjects\CS65_3\vr_env\lib\site-packages\rest_framework\views.py", line 506, in dispatch
    response = handler(request, *args, **kwargs)
  File "C:\Users\46121\PycharmProjects\CS65_3\vr_env\lib\site-packages\rest_framework\decorators.py", line 50, in handler
    return func(*args, **kwargs)
  File "C:\Users\46121\PycharmProjects\CS65_3\cs65_4\cs65_5\polls\views.py", line 414, in project_tree
    tree = get_tree(join(path, project_name))
  File "C:\Users\46121\PycharmProjects\CS65_3\cs65_4\cs65_5\polls\utils.py", line 101, in get_tree
    for file in os.listdir(path):
FileNotFoundError: [WinError 3] The system cannot find the path specified: 'C:\\Users\\46121\\PycharmProjects\\CS65_3\\cs65_4\\cs65_5\\projects\\undefined'
ERROR - 2022-05-18 14:03:10,690 - process: 41476 - utils.py - polls.utils - 76 - utils - [WinError 3] The system cannot find the path specified: 'C:\\Users\\46121\\PycharmProjects\\CS65_3\\cs65_4\\cs65_5\\projects\\undefined'
Traceback (most recent call last):
  File "C:\Users\46121\PycharmProjects\CS65_3\cs65_4\cs65_5\polls\utils.py", line 74, in wrapper
    result = func(*args, **kwargs)
  File "C:\Users\46121\PycharmProjects\CS65_3\vr_env\lib\site-packages\django\views\decorators\csrf.py", line 54, in wrapped_view
    return view_func(*args, **kwargs)
  File "C:\Users\46121\PycharmProjects\CS65_3\vr_env\lib\site-packages\django\views\generic\base.py", line 69, in view
    return self.dispatch(request, *args, **kwargs)
  File "C:\Users\46121\PycharmProjects\CS65_3\vr_env\lib\site-packages\rest_framework\views.py", line 509, in dispatch
    response = self.handle_exception(exc)
  File "C:\Users\46121\PycharmProjects\CS65_3\vr_env\lib\site-packages\rest_framework\views.py", line 469, in handle_exception
    self.raise_uncaught_exception(exc)
  File "C:\Users\46121\PycharmProjects\CS65_3\vr_env\lib\site-packages\rest_framework\views.py", line 480, in raise_uncaught_exception
    raise exc
  File "C:\Users\46121\PycharmProjects\CS65_3\vr_env\lib\site-packages\rest_framework\views.py", line 506, in dispatch
    response = handler(request, *args, **kwargs)
  File "C:\Users\46121\PycharmProjects\CS65_3\vr_env\lib\site-packages\rest_framework\decorators.py", line 50, in handler
    return func(*args, **kwargs)
  File "C:\Users\46121\PycharmProjects\CS65_3\cs65_4\cs65_5\polls\views.py", line 414, in project_tree
    tree = get_tree(join(path, project_name))
  File "C:\Users\46121\PycharmProjects\CS65_3\cs65_4\cs65_5\polls\utils.py", line 101, in get_tree
    for file in os.listdir(path):
FileNotFoundError: [WinError 3] The system cannot find the path specified: 'C:\\Users\\46121\\PycharmProjects\\CS65_3\\cs65_4\\cs65_5\\projects\\undefined'
INFO - 2022-05-18 14:20:55,968 - process: 41476 - build.py - polls.build - 24 - build - successfully build project health to egg file C:\Users\46121\PycharmProjects\CS65_3\cs65_4\cs65_5\projects\health\project-1.0-py3.8.egg
ERROR - 2022-05-18 15:35:45,285 - process: 41476 - utils.py - polls.utils - 76 - utils - [WinError 3] The system cannot find the path specified: 'C:\\Users\\46121\\PycharmProjects\\CS65_3\\cs65_4\\cs65_5\\projects\\undefined'
Traceback (most recent call last):
  File "C:\Users\46121\PycharmProjects\CS65_3\cs65_4\cs65_5\polls\utils.py", line 74, in wrapper
    result = func(*args, **kwargs)
  File "C:\Users\46121\PycharmProjects\CS65_3\vr_env\lib\site-packages\django\views\decorators\csrf.py", line 54, in wrapped_view
    return view_func(*args, **kwargs)
  File "C:\Users\46121\PycharmProjects\CS65_3\vr_env\lib\site-packages\django\views\generic\base.py", line 69, in view
    return self.dispatch(request, *args, **kwargs)
  File "C:\Users\46121\PycharmProjects\CS65_3\vr_env\lib\site-packages\rest_framework\views.py", line 509, in dispatch
    response = self.handle_exception(exc)
  File "C:\Users\46121\PycharmProjects\CS65_3\vr_env\lib\site-packages\rest_framework\views.py", line 469, in handle_exception
    self.raise_uncaught_exception(exc)
  File "C:\Users\46121\PycharmProjects\CS65_3\vr_env\lib\site-packages\rest_framework\views.py", line 480, in raise_uncaught_exception
    raise exc
  File "C:\Users\46121\PycharmProjects\CS65_3\vr_env\lib\site-packages\rest_framework\views.py", line 506, in dispatch
    response = handler(request, *args, **kwargs)
  File "C:\Users\46121\PycharmProjects\CS65_3\vr_env\lib\site-packages\rest_framework\decorators.py", line 50, in handler
    return func(*args, **kwargs)
  File "C:\Users\46121\PycharmProjects\CS65_3\cs65_4\cs65_5\polls\views.py", line 414, in project_tree
    tree = get_tree(join(path, project_name))
  File "C:\Users\46121\PycharmProjects\CS65_3\cs65_4\cs65_5\polls\utils.py", line 101, in get_tree
    for file in os.listdir(path):
FileNotFoundError: [WinError 3] The system cannot find the path specified: 'C:\\Users\\46121\\PycharmProjects\\CS65_3\\cs65_4\\cs65_5\\projects\\undefined'
ERROR - 2022-05-18 15:35:46,392 - process: 41476 - utils.py - polls.utils - 76 - utils - [WinError 3] The system cannot find the path specified: 'C:\\Users\\46121\\PycharmProjects\\CS65_3\\cs65_4\\cs65_5\\projects\\undefined'
Traceback (most recent call last):
  File "C:\Users\46121\PycharmProjects\CS65_3\cs65_4\cs65_5\polls\utils.py", line 74, in wrapper
    result = func(*args, **kwargs)
  File "C:\Users\46121\PycharmProjects\CS65_3\vr_env\lib\site-packages\django\views\decorators\csrf.py", line 54, in wrapped_view
    return view_func(*args, **kwargs)
  File "C:\Users\46121\PycharmProjects\CS65_3\vr_env\lib\site-packages\django\views\generic\base.py", line 69, in view
    return self.dispatch(request, *args, **kwargs)
  File "C:\Users\46121\PycharmProjects\CS65_3\vr_env\lib\site-packages\rest_framework\views.py", line 509, in dispatch
    response = self.handle_exception(exc)
  File "C:\Users\46121\PycharmProjects\CS65_3\vr_env\lib\site-packages\rest_framework\views.py", line 469, in handle_exception
    self.raise_uncaught_exception(exc)
  File "C:\Users\46121\PycharmProjects\CS65_3\vr_env\lib\site-packages\rest_framework\views.py", line 480, in raise_uncaught_exception
    raise exc
  File "C:\Users\46121\PycharmProjects\CS65_3\vr_env\lib\site-packages\rest_framework\views.py", line 506, in dispatch
    response = handler(request, *args, **kwargs)
  File "C:\Users\46121\PycharmProjects\CS65_3\vr_env\lib\site-packages\rest_framework\decorators.py", line 50, in handler
    return func(*args, **kwargs)
  File "C:\Users\46121\PycharmProjects\CS65_3\cs65_4\cs65_5\polls\views.py", line 414, in project_tree
    tree = get_tree(join(path, project_name))
  File "C:\Users\46121\PycharmProjects\CS65_3\cs65_4\cs65_5\polls\utils.py", line 101, in get_tree
    for file in os.listdir(path):
FileNotFoundError: [WinError 3] The system cannot find the path specified: 'C:\\Users\\46121\\PycharmProjects\\CS65_3\\cs65_4\\cs65_5\\projects\\undefined'
ERROR - 2022-05-18 15:35:48,005 - process: 41476 - utils.py - polls.utils - 76 - utils - [WinError 3] The system cannot find the path specified: 'C:\\Users\\46121\\PycharmProjects\\CS65_3\\cs65_4\\cs65_5\\projects\\undefined'
Traceback (most recent call last):
  File "C:\Users\46121\PycharmProjects\CS65_3\cs65_4\cs65_5\polls\utils.py", line 74, in wrapper
    result = func(*args, **kwargs)
  File "C:\Users\46121\PycharmProjects\CS65_3\vr_env\lib\site-packages\django\views\decorators\csrf.py", line 54, in wrapped_view
    return view_func(*args, **kwargs)
  File "C:\Users\46121\PycharmProjects\CS65_3\vr_env\lib\site-packages\django\views\generic\base.py", line 69, in view
    return self.dispatch(request, *args, **kwargs)
  File "C:\Users\46121\PycharmProjects\CS65_3\vr_env\lib\site-packages\rest_framework\views.py", line 509, in dispatch
    response = self.handle_exception(exc)
  File "C:\Users\46121\PycharmProjects\CS65_3\vr_env\lib\site-packages\rest_framework\views.py", line 469, in handle_exception
    self.raise_uncaught_exception(exc)
  File "C:\Users\46121\PycharmProjects\CS65_3\vr_env\lib\site-packages\rest_framework\views.py", line 480, in raise_uncaught_exception
    raise exc
  File "C:\Users\46121\PycharmProjects\CS65_3\vr_env\lib\site-packages\rest_framework\views.py", line 506, in dispatch
    response = handler(request, *args, **kwargs)
  File "C:\Users\46121\PycharmProjects\CS65_3\vr_env\lib\site-packages\rest_framework\decorators.py", line 50, in handler
    return func(*args, **kwargs)
  File "C:\Users\46121\PycharmProjects\CS65_3\cs65_4\cs65_5\polls\views.py", line 414, in project_tree
    tree = get_tree(join(path, project_name))
  File "C:\Users\46121\PycharmProjects\CS65_3\cs65_4\cs65_5\polls\utils.py", line 101, in get_tree
    for file in os.listdir(path):
FileNotFoundError: [WinError 3] The system cannot find the path specified: 'C:\\Users\\46121\\PycharmProjects\\CS65_3\\cs65_4\\cs65_5\\projects\\undefined'
ERROR - 2022-05-18 15:35:50,117 - process: 41476 - utils.py - polls.utils - 76 - utils - [WinError 3] The system cannot find the path specified: 'C:\\Users\\46121\\PycharmProjects\\CS65_3\\cs65_4\\cs65_5\\projects\\undefined'
Traceback (most recent call last):
  File "C:\Users\46121\PycharmProjects\CS65_3\cs65_4\cs65_5\polls\utils.py", line 74, in wrapper
    result = func(*args, **kwargs)
  File "C:\Users\46121\PycharmProjects\CS65_3\vr_env\lib\site-packages\django\views\decorators\csrf.py", line 54, in wrapped_view
    return view_func(*args, **kwargs)
  File "C:\Users\46121\PycharmProjects\CS65_3\vr_env\lib\site-packages\django\views\generic\base.py", line 69, in view
    return self.dispatch(request, *args, **kwargs)
  File "C:\Users\46121\PycharmProjects\CS65_3\vr_env\lib\site-packages\rest_framework\views.py", line 509, in dispatch
    response = self.handle_exception(exc)
  File "C:\Users\46121\PycharmProjects\CS65_3\vr_env\lib\site-packages\rest_framework\views.py", line 469, in handle_exception
    self.raise_uncaught_exception(exc)
  File "C:\Users\46121\PycharmProjects\CS65_3\vr_env\lib\site-packages\rest_framework\views.py", line 480, in raise_uncaught_exception
    raise exc
  File "C:\Users\46121\PycharmProjects\CS65_3\vr_env\lib\site-packages\rest_framework\views.py", line 506, in dispatch
    response = handler(request, *args, **kwargs)
  File "C:\Users\46121\PycharmProjects\CS65_3\vr_env\lib\site-packages\rest_framework\decorators.py", line 50, in handler
    return func(*args, **kwargs)
  File "C:\Users\46121\PycharmProjects\CS65_3\cs65_4\cs65_5\polls\views.py", line 414, in project_tree
    tree = get_tree(join(path, project_name))
  File "C:\Users\46121\PycharmProjects\CS65_3\cs65_4\cs65_5\polls\utils.py", line 101, in get_tree
    for file in os.listdir(path):
FileNotFoundError: [WinError 3] The system cannot find the path specified: 'C:\\Users\\46121\\PycharmProjects\\CS65_3\\cs65_4\\cs65_5\\projects\\undefined'
ERROR - 2022-05-18 15:35:57,789 - process: 41476 - utils.py - polls.utils - 76 - utils - [WinError 3] The system cannot find the path specified: 'C:\\Users\\46121\\PycharmProjects\\CS65_3\\cs65_4\\cs65_5\\projects\\undefined'
Traceback (most recent call last):
  File "C:\Users\46121\PycharmProjects\CS65_3\cs65_4\cs65_5\polls\utils.py", line 74, in wrapper
    result = func(*args, **kwargs)
  File "C:\Users\46121\PycharmProjects\CS65_3\vr_env\lib\site-packages\django\views\decorators\csrf.py", line 54, in wrapped_view
    return view_func(*args, **kwargs)
  File "C:\Users\46121\PycharmProjects\CS65_3\vr_env\lib\site-packages\django\views\generic\base.py", line 69, in view
    return self.dispatch(request, *args, **kwargs)
  File "C:\Users\46121\PycharmProjects\CS65_3\vr_env\lib\site-packages\rest_framework\views.py", line 509, in dispatch
    response = self.handle_exception(exc)
  File "C:\Users\46121\PycharmProjects\CS65_3\vr_env\lib\site-packages\rest_framework\views.py", line 469, in handle_exception
    self.raise_uncaught_exception(exc)
  File "C:\Users\46121\PycharmProjects\CS65_3\vr_env\lib\site-packages\rest_framework\views.py", line 480, in raise_uncaught_exception
    raise exc
  File "C:\Users\46121\PycharmProjects\CS65_3\vr_env\lib\site-packages\rest_framework\views.py", line 506, in dispatch
    response = handler(request, *args, **kwargs)
  File "C:\Users\46121\PycharmProjects\CS65_3\vr_env\lib\site-packages\rest_framework\decorators.py", line 50, in handler
    return func(*args, **kwargs)
  File "C:\Users\46121\PycharmProjects\CS65_3\cs65_4\cs65_5\polls\views.py", line 414, in project_tree
    tree = get_tree(join(path, project_name))
  File "C:\Users\46121\PycharmProjects\CS65_3\cs65_4\cs65_5\polls\utils.py", line 101, in get_tree
    for file in os.listdir(path):
FileNotFoundError: [WinError 3] The system cannot find the path specified: 'C:\\Users\\46121\\PycharmProjects\\CS65_3\\cs65_4\\cs65_5\\projects\\undefined'
ERROR - 2022-05-18 15:41:28,330 - process: 41476 - utils.py - polls.utils - 76 - utils - [WinError 3] The system cannot find the path specified: 'C:\\Users\\46121\\PycharmProjects\\CS65_3\\cs65_4\\cs65_5\\projects\\undefined'
Traceback (most recent call last):
  File "C:\Users\46121\PycharmProjects\CS65_3\cs65_4\cs65_5\polls\utils.py", line 74, in wrapper
    result = func(*args, **kwargs)
  File "C:\Users\46121\PycharmProjects\CS65_3\vr_env\lib\site-packages\django\views\decorators\csrf.py", line 54, in wrapped_view
    return view_func(*args, **kwargs)
  File "C:\Users\46121\PycharmProjects\CS65_3\vr_env\lib\site-packages\django\views\generic\base.py", line 69, in view
    return self.dispatch(request, *args, **kwargs)
  File "C:\Users\46121\PycharmProjects\CS65_3\vr_env\lib\site-packages\rest_framework\views.py", line 509, in dispatch
    response = self.handle_exception(exc)
  File "C:\Users\46121\PycharmProjects\CS65_3\vr_env\lib\site-packages\rest_framework\views.py", line 469, in handle_exception
    self.raise_uncaught_exception(exc)
  File "C:\Users\46121\PycharmProjects\CS65_3\vr_env\lib\site-packages\rest_framework\views.py", line 480, in raise_uncaught_exception
    raise exc
  File "C:\Users\46121\PycharmProjects\CS65_3\vr_env\lib\site-packages\rest_framework\views.py", line 506, in dispatch
    response = handler(request, *args, **kwargs)
  File "C:\Users\46121\PycharmProjects\CS65_3\vr_env\lib\site-packages\rest_framework\decorators.py", line 50, in handler
    return func(*args, **kwargs)
  File "C:\Users\46121\PycharmProjects\CS65_3\cs65_4\cs65_5\polls\views.py", line 414, in project_tree
    tree = get_tree(join(path, project_name))
  File "C:\Users\46121\PycharmProjects\CS65_3\cs65_4\cs65_5\polls\utils.py", line 101, in get_tree
    for file in os.listdir(path):
FileNotFoundError: [WinError 3] The system cannot find the path specified: 'C:\\Users\\46121\\PycharmProjects\\CS65_3\\cs65_4\\cs65_5\\projects\\undefined'
ERROR - 2022-05-18 15:43:52,903 - process: 41476 - utils.py - polls.utils - 76 - utils - [WinError 3] The system cannot find the path specified: 'C:\\Users\\46121\\PycharmProjects\\CS65_3\\cs65_4\\cs65_5\\projects\\undefined'
Traceback (most recent call last):
  File "C:\Users\46121\PycharmProjects\CS65_3\cs65_4\cs65_5\polls\utils.py", line 74, in wrapper
    result = func(*args, **kwargs)
  File "C:\Users\46121\PycharmProjects\CS65_3\vr_env\lib\site-packages\django\views\decorators\csrf.py", line 54, in wrapped_view
    return view_func(*args, **kwargs)
  File "C:\Users\46121\PycharmProjects\CS65_3\vr_env\lib\site-packages\django\views\generic\base.py", line 69, in view
    return self.dispatch(request, *args, **kwargs)
  File "C:\Users\46121\PycharmProjects\CS65_3\vr_env\lib\site-packages\rest_framework\views.py", line 509, in dispatch
    response = self.handle_exception(exc)
  File "C:\Users\46121\PycharmProjects\CS65_3\vr_env\lib\site-packages\rest_framework\views.py", line 469, in handle_exception
    self.raise_uncaught_exception(exc)
  File "C:\Users\46121\PycharmProjects\CS65_3\vr_env\lib\site-packages\rest_framework\views.py", line 480, in raise_uncaught_exception
    raise exc
  File "C:\Users\46121\PycharmProjects\CS65_3\vr_env\lib\site-packages\rest_framework\views.py", line 506, in dispatch
    response = handler(request, *args, **kwargs)
  File "C:\Users\46121\PycharmProjects\CS65_3\vr_env\lib\site-packages\rest_framework\decorators.py", line 50, in handler
    return func(*args, **kwargs)
  File "C:\Users\46121\PycharmProjects\CS65_3\cs65_4\cs65_5\polls\views.py", line 414, in project_tree
    tree = get_tree(join(path, project_name))
  File "C:\Users\46121\PycharmProjects\CS65_3\cs65_4\cs65_5\polls\utils.py", line 101, in get_tree
    for file in os.listdir(path):
FileNotFoundError: [WinError 3] The system cannot find the path specified: 'C:\\Users\\46121\\PycharmProjects\\CS65_3\\cs65_4\\cs65_5\\projects\\undefined'
ERROR - 2022-05-18 15:45:17,549 - process: 41476 - utils.py - polls.utils - 76 - utils - [WinError 3] The system cannot find the path specified: 'C:\\Users\\46121\\PycharmProjects\\CS65_3\\cs65_4\\cs65_5\\projects\\undefined'
Traceback (most recent call last):
  File "C:\Users\46121\PycharmProjects\CS65_3\cs65_4\cs65_5\polls\utils.py", line 74, in wrapper
    result = func(*args, **kwargs)
  File "C:\Users\46121\PycharmProjects\CS65_3\vr_env\lib\site-packages\django\views\decorators\csrf.py", line 54, in wrapped_view
    return view_func(*args, **kwargs)
  File "C:\Users\46121\PycharmProjects\CS65_3\vr_env\lib\site-packages\django\views\generic\base.py", line 69, in view
    return self.dispatch(request, *args, **kwargs)
  File "C:\Users\46121\PycharmProjects\CS65_3\vr_env\lib\site-packages\rest_framework\views.py", line 509, in dispatch
    response = self.handle_exception(exc)
  File "C:\Users\46121\PycharmProjects\CS65_3\vr_env\lib\site-packages\rest_framework\views.py", line 469, in handle_exception
    self.raise_uncaught_exception(exc)
  File "C:\Users\46121\PycharmProjects\CS65_3\vr_env\lib\site-packages\rest_framework\views.py", line 480, in raise_uncaught_exception
    raise exc
  File "C:\Users\46121\PycharmProjects\CS65_3\vr_env\lib\site-packages\rest_framework\views.py", line 506, in dispatch
    response = handler(request, *args, **kwargs)
  File "C:\Users\46121\PycharmProjects\CS65_3\vr_env\lib\site-packages\rest_framework\decorators.py", line 50, in handler
    return func(*args, **kwargs)
  File "C:\Users\46121\PycharmProjects\CS65_3\cs65_4\cs65_5\polls\views.py", line 414, in project_tree
    tree = get_tree(join(path, project_name))
  File "C:\Users\46121\PycharmProjects\CS65_3\cs65_4\cs65_5\polls\utils.py", line 101, in get_tree
    for file in os.listdir(path):
FileNotFoundError: [WinError 3] The system cannot find the path specified: 'C:\\Users\\46121\\PycharmProjects\\CS65_3\\cs65_4\\cs65_5\\projects\\undefined'
ERROR - 2022-05-18 15:53:34,510 - process: 41476 - utils.py - polls.utils - 76 - utils - [WinError 3] The system cannot find the path specified: 'C:\\Users\\46121\\PycharmProjects\\CS65_3\\cs65_4\\cs65_5\\projects\\undefined'
Traceback (most recent call last):
  File "C:\Users\46121\PycharmProjects\CS65_3\cs65_4\cs65_5\polls\utils.py", line 74, in wrapper
    result = func(*args, **kwargs)
  File "C:\Users\46121\PycharmProjects\CS65_3\vr_env\lib\site-packages\django\views\decorators\csrf.py", line 54, in wrapped_view
    return view_func(*args, **kwargs)
  File "C:\Users\46121\PycharmProjects\CS65_3\vr_env\lib\site-packages\django\views\generic\base.py", line 69, in view
    return self.dispatch(request, *args, **kwargs)
  File "C:\Users\46121\PycharmProjects\CS65_3\vr_env\lib\site-packages\rest_framework\views.py", line 509, in dispatch
    response = self.handle_exception(exc)
  File "C:\Users\46121\PycharmProjects\CS65_3\vr_env\lib\site-packages\rest_framework\views.py", line 469, in handle_exception
    self.raise_uncaught_exception(exc)
  File "C:\Users\46121\PycharmProjects\CS65_3\vr_env\lib\site-packages\rest_framework\views.py", line 480, in raise_uncaught_exception
    raise exc
  File "C:\Users\46121\PycharmProjects\CS65_3\vr_env\lib\site-packages\rest_framework\views.py", line 506, in dispatch
    response = handler(request, *args, **kwargs)
  File "C:\Users\46121\PycharmProjects\CS65_3\vr_env\lib\site-packages\rest_framework\decorators.py", line 50, in handler
    return func(*args, **kwargs)
  File "C:\Users\46121\PycharmProjects\CS65_3\cs65_4\cs65_5\polls\views.py", line 414, in project_tree
    tree = get_tree(join(path, project_name))
  File "C:\Users\46121\PycharmProjects\CS65_3\cs65_4\cs65_5\polls\utils.py", line 101, in get_tree
    for file in os.listdir(path):
FileNotFoundError: [WinError 3] The system cannot find the path specified: 'C:\\Users\\46121\\PycharmProjects\\CS65_3\\cs65_4\\cs65_5\\projects\\undefined'
ERROR - 2022-05-18 15:53:37,526 - process: 41476 - utils.py - polls.utils - 76 - utils - [WinError 3] The system cannot find the path specified: 'C:\\Users\\46121\\PycharmProjects\\CS65_3\\cs65_4\\cs65_5\\projects\\undefined'
Traceback (most recent call last):
  File "C:\Users\46121\PycharmProjects\CS65_3\cs65_4\cs65_5\polls\utils.py", line 74, in wrapper
    result = func(*args, **kwargs)
  File "C:\Users\46121\PycharmProjects\CS65_3\vr_env\lib\site-packages\django\views\decorators\csrf.py", line 54, in wrapped_view
    return view_func(*args, **kwargs)
  File "C:\Users\46121\PycharmProjects\CS65_3\vr_env\lib\site-packages\django\views\generic\base.py", line 69, in view
    return self.dispatch(request, *args, **kwargs)
  File "C:\Users\46121\PycharmProjects\CS65_3\vr_env\lib\site-packages\rest_framework\views.py", line 509, in dispatch
    response = self.handle_exception(exc)
  File "C:\Users\46121\PycharmProjects\CS65_3\vr_env\lib\site-packages\rest_framework\views.py", line 469, in handle_exception
    self.raise_uncaught_exception(exc)
  File "C:\Users\46121\PycharmProjects\CS65_3\vr_env\lib\site-packages\rest_framework\views.py", line 480, in raise_uncaught_exception
    raise exc
  File "C:\Users\46121\PycharmProjects\CS65_3\vr_env\lib\site-packages\rest_framework\views.py", line 506, in dispatch
    response = handler(request, *args, **kwargs)
  File "C:\Users\46121\PycharmProjects\CS65_3\vr_env\lib\site-packages\rest_framework\decorators.py", line 50, in handler
    return func(*args, **kwargs)
  File "C:\Users\46121\PycharmProjects\CS65_3\cs65_4\cs65_5\polls\views.py", line 414, in project_tree
    tree = get_tree(join(path, project_name))
  File "C:\Users\46121\PycharmProjects\CS65_3\cs65_4\cs65_5\polls\utils.py", line 101, in get_tree
    for file in os.listdir(path):
FileNotFoundError: [WinError 3] The system cannot find the path specified: 'C:\\Users\\46121\\PycharmProjects\\CS65_3\\cs65_4\\cs65_5\\projects\\undefined'
ERROR - 2022-05-18 15:53:40,447 - process: 41476 - utils.py - polls.utils - 76 - utils - [WinError 3] The system cannot find the path specified: 'C:\\Users\\46121\\PycharmProjects\\CS65_3\\cs65_4\\cs65_5\\projects\\undefined'
Traceback (most recent call last):
  File "C:\Users\46121\PycharmProjects\CS65_3\cs65_4\cs65_5\polls\utils.py", line 74, in wrapper
    result = func(*args, **kwargs)
  File "C:\Users\46121\PycharmProjects\CS65_3\vr_env\lib\site-packages\django\views\decorators\csrf.py", line 54, in wrapped_view
    return view_func(*args, **kwargs)
  File "C:\Users\46121\PycharmProjects\CS65_3\vr_env\lib\site-packages\django\views\generic\base.py", line 69, in view
    return self.dispatch(request, *args, **kwargs)
  File "C:\Users\46121\PycharmProjects\CS65_3\vr_env\lib\site-packages\rest_framework\views.py", line 509, in dispatch
    response = self.handle_exception(exc)
  File "C:\Users\46121\PycharmProjects\CS65_3\vr_env\lib\site-packages\rest_framework\views.py", line 469, in handle_exception
    self.raise_uncaught_exception(exc)
  File "C:\Users\46121\PycharmProjects\CS65_3\vr_env\lib\site-packages\rest_framework\views.py", line 480, in raise_uncaught_exception
    raise exc
  File "C:\Users\46121\PycharmProjects\CS65_3\vr_env\lib\site-packages\rest_framework\views.py", line 506, in dispatch
    response = handler(request, *args, **kwargs)
  File "C:\Users\46121\PycharmProjects\CS65_3\vr_env\lib\site-packages\rest_framework\decorators.py", line 50, in handler
    return func(*args, **kwargs)
  File "C:\Users\46121\PycharmProjects\CS65_3\cs65_4\cs65_5\polls\views.py", line 414, in project_tree
    tree = get_tree(join(path, project_name))
  File "C:\Users\46121\PycharmProjects\CS65_3\cs65_4\cs65_5\polls\utils.py", line 101, in get_tree
    for file in os.listdir(path):
FileNotFoundError: [WinError 3] The system cannot find the path specified: 'C:\\Users\\46121\\PycharmProjects\\CS65_3\\cs65_4\\cs65_5\\projects\\undefined'
ERROR - 2022-05-18 15:53:42,370 - process: 41476 - utils.py - polls.utils - 76 - utils - [WinError 3] The system cannot find the path specified: 'C:\\Users\\46121\\PycharmProjects\\CS65_3\\cs65_4\\cs65_5\\projects\\undefined'
Traceback (most recent call last):
  File "C:\Users\46121\PycharmProjects\CS65_3\cs65_4\cs65_5\polls\utils.py", line 74, in wrapper
    result = func(*args, **kwargs)
  File "C:\Users\46121\PycharmProjects\CS65_3\vr_env\lib\site-packages\django\views\decorators\csrf.py", line 54, in wrapped_view
    return view_func(*args, **kwargs)
  File "C:\Users\46121\PycharmProjects\CS65_3\vr_env\lib\site-packages\django\views\generic\base.py", line 69, in view
    return self.dispatch(request, *args, **kwargs)
  File "C:\Users\46121\PycharmProjects\CS65_3\vr_env\lib\site-packages\rest_framework\views.py", line 509, in dispatch
    response = self.handle_exception(exc)
  File "C:\Users\46121\PycharmProjects\CS65_3\vr_env\lib\site-packages\rest_framework\views.py", line 469, in handle_exception
    self.raise_uncaught_exception(exc)
  File "C:\Users\46121\PycharmProjects\CS65_3\vr_env\lib\site-packages\rest_framework\views.py", line 480, in raise_uncaught_exception
    raise exc
  File "C:\Users\46121\PycharmProjects\CS65_3\vr_env\lib\site-packages\rest_framework\views.py", line 506, in dispatch
    response = handler(request, *args, **kwargs)
  File "C:\Users\46121\PycharmProjects\CS65_3\vr_env\lib\site-packages\rest_framework\decorators.py", line 50, in handler
    return func(*args, **kwargs)
  File "C:\Users\46121\PycharmProjects\CS65_3\cs65_4\cs65_5\polls\views.py", line 414, in project_tree
    tree = get_tree(join(path, project_name))
  File "C:\Users\46121\PycharmProjects\CS65_3\cs65_4\cs65_5\polls\utils.py", line 101, in get_tree
    for file in os.listdir(path):
FileNotFoundError: [WinError 3] The system cannot find the path specified: 'C:\\Users\\46121\\PycharmProjects\\CS65_3\\cs65_4\\cs65_5\\projects\\undefined'
ERROR - 2022-05-18 15:53:44,879 - process: 41476 - utils.py - polls.utils - 76 - utils - [WinError 3] The system cannot find the path specified: 'C:\\Users\\46121\\PycharmProjects\\CS65_3\\cs65_4\\cs65_5\\projects\\undefined'
Traceback (most recent call last):
  File "C:\Users\46121\PycharmProjects\CS65_3\cs65_4\cs65_5\polls\utils.py", line 74, in wrapper
    result = func(*args, **kwargs)
  File "C:\Users\46121\PycharmProjects\CS65_3\vr_env\lib\site-packages\django\views\decorators\csrf.py", line 54, in wrapped_view
    return view_func(*args, **kwargs)
  File "C:\Users\46121\PycharmProjects\CS65_3\vr_env\lib\site-packages\django\views\generic\base.py", line 69, in view
    return self.dispatch(request, *args, **kwargs)
  File "C:\Users\46121\PycharmProjects\CS65_3\vr_env\lib\site-packages\rest_framework\views.py", line 509, in dispatch
    response = self.handle_exception(exc)
  File "C:\Users\46121\PycharmProjects\CS65_3\vr_env\lib\site-packages\rest_framework\views.py", line 469, in handle_exception
    self.raise_uncaught_exception(exc)
  File "C:\Users\46121\PycharmProjects\CS65_3\vr_env\lib\site-packages\rest_framework\views.py", line 480, in raise_uncaught_exception
    raise exc
  File "C:\Users\46121\PycharmProjects\CS65_3\vr_env\lib\site-packages\rest_framework\views.py", line 506, in dispatch
    response = handler(request, *args, **kwargs)
  File "C:\Users\46121\PycharmProjects\CS65_3\vr_env\lib\site-packages\rest_framework\decorators.py", line 50, in handler
    return func(*args, **kwargs)
  File "C:\Users\46121\PycharmProjects\CS65_3\cs65_4\cs65_5\polls\views.py", line 414, in project_tree
    tree = get_tree(join(path, project_name))
  File "C:\Users\46121\PycharmProjects\CS65_3\cs65_4\cs65_5\polls\utils.py", line 101, in get_tree
    for file in os.listdir(path):
FileNotFoundError: [WinError 3] The system cannot find the path specified: 'C:\\Users\\46121\\PycharmProjects\\CS65_3\\cs65_4\\cs65_5\\projects\\undefined'
INFO - 2022-05-18 17:01:28,430 - process: 41476 - build.py - polls.build - 24 - build - successfully build project MayoSpider to egg file C:\Users\46121\PycharmProjects\CS65_3\cs65_4\cs65_5\projects\MayoSpider\MayoSpider-1.0-py3.8.egg
