INFO - 2022-06-07 11:42:42,158 - process: 2456 - scheduler.py - polls.scheduler - 105 - scheduler - successfully synced task with jobs with force
ERROR - 2022-06-07 11:48:30,584 - process: 2456 - utils.py - polls.utils - 533 - utils - HTTPConnectionPool(host='127.0.0.1', port=6800): Max retries exceeded with url: / (Caused by NewConnectionError('<urllib3.connection.HTTPConnection object at 0x0000022E00A241F0>: Failed to establish a new connection: [WinError 10061] 由于目标计算机积极拒绝，无法连接。'))
Traceback (most recent call last):
  File "E:\python\lib\site-packages\urllib3\connection.py", line 174, in _new_conn
    conn = connection.create_connection(
  File "E:\python\lib\site-packages\urllib3\util\connection.py", line 95, in create_connection
    raise err
  File "E:\python\lib\site-packages\urllib3\util\connection.py", line 85, in create_connection
    sock.connect(sa)
ConnectionRefusedError: [WinError 10061] 由于目标计算机积极拒绝，无法连接。

During handling of the above exception, another exception occurred:

Traceback (most recent call last):
  File "E:\python\lib\site-packages\urllib3\connectionpool.py", line 703, in urlopen
    httplib_response = self._make_request(
  File "E:\python\lib\site-packages\urllib3\connectionpool.py", line 398, in _make_request
    conn.request(method, url, **httplib_request_kw)
  File "E:\python\lib\site-packages\urllib3\connection.py", line 239, in request
    super(HTTPConnection, self).request(method, url, body=body, headers=headers)
  File "E:\python\lib\http\client.py", line 1282, in request
    self._send_request(method, url, body, headers, encode_chunked)
  File "E:\python\lib\http\client.py", line 1328, in _send_request
    self.endheaders(body, encode_chunked=encode_chunked)
  File "E:\python\lib\http\client.py", line 1277, in endheaders
    self._send_output(message_body, encode_chunked=encode_chunked)
  File "E:\python\lib\http\client.py", line 1037, in _send_output
    self.send(msg)
  File "E:\python\lib\http\client.py", line 975, in send
    self.connect()
  File "E:\python\lib\site-packages\urllib3\connection.py", line 205, in connect
    conn = self._new_conn()
  File "E:\python\lib\site-packages\urllib3\connection.py", line 186, in _new_conn
    raise NewConnectionError(
urllib3.exceptions.NewConnectionError: <urllib3.connection.HTTPConnection object at 0x0000022E00A241F0>: Failed to establish a new connection: [WinError 10061] 由于目标计算机积极拒绝，无法连接。

During handling of the above exception, another exception occurred:

Traceback (most recent call last):
  File "E:\python\lib\site-packages\requests\adapters.py", line 440, in send
    resp = conn.urlopen(
  File "E:\python\lib\site-packages\urllib3\connectionpool.py", line 785, in urlopen
    retries = retries.increment(
  File "E:\python\lib\site-packages\urllib3\util\retry.py", line 592, in increment
    raise MaxRetryError(_pool, url, error or ResponseError(cause))
urllib3.exceptions.MaxRetryError: HTTPConnectionPool(host='127.0.0.1', port=6800): Max retries exceeded with url: / (Caused by NewConnectionError('<urllib3.connection.HTTPConnection object at 0x0000022E00A241F0>: Failed to establish a new connection: [WinError 10061] 由于目标计算机积极拒绝，无法连接。'))

During handling of the above exception, another exception occurred:

Traceback (most recent call last):
  File "E:\5703\git_nlp_repository\COMP5703CS65_NLP\polls\utils.py", line 531, in wrapper
    result = func(*args, **kwargs)
  File "E:\python\lib\site-packages\django\views\decorators\csrf.py", line 54, in wrapped_view
    return view_func(*args, **kwargs)
  File "E:\python\lib\site-packages\django\views\generic\base.py", line 84, in view
    return self.dispatch(request, *args, **kwargs)
  File "E:\python\lib\site-packages\rest_framework\views.py", line 509, in dispatch
    response = self.handle_exception(exc)
  File "E:\python\lib\site-packages\rest_framework\views.py", line 469, in handle_exception
    self.raise_uncaught_exception(exc)
  File "E:\python\lib\site-packages\rest_framework\views.py", line 480, in raise_uncaught_exception
    raise exc
  File "E:\python\lib\site-packages\rest_framework\views.py", line 506, in dispatch
    response = handler(request, *args, **kwargs)
  File "E:\python\lib\site-packages\rest_framework\decorators.py", line 50, in handler
    return func(*args, **kwargs)
  File "E:\5703\git_nlp_repository\COMP5703CS65_NLP\polls\views.py", line 127, in client_status
    requests.get(scrapyd_url(client.ip, client.port), timeout=3)
  File "E:\python\lib\site-packages\requests\api.py", line 75, in get
    return request('get', url, params=params, **kwargs)
  File "E:\python\lib\site-packages\requests\api.py", line 61, in request
    return session.request(method=method, url=url, **kwargs)
  File "E:\python\lib\site-packages\requests\sessions.py", line 529, in request
    resp = self.send(prep, **send_kwargs)
  File "E:\python\lib\site-packages\requests\sessions.py", line 645, in send
    r = adapter.send(request, **kwargs)
  File "E:\python\lib\site-packages\requests\adapters.py", line 519, in send
    raise ConnectionError(e, request=request)
requests.exceptions.ConnectionError: HTTPConnectionPool(host='127.0.0.1', port=6800): Max retries exceeded with url: / (Caused by NewConnectionError('<urllib3.connection.HTTPConnection object at 0x0000022E00A241F0>: Failed to establish a new connection: [WinError 10061] 由于目标计算机积极拒绝，无法连接。'))
ERROR - 2022-06-07 11:48:30,583 - process: 2456 - views.py - polls.views - 412 - views - cannot connect to scrapyd
Traceback (most recent call last):
  File "E:\python\lib\site-packages\urllib3\connection.py", line 174, in _new_conn
    conn = connection.create_connection(
  File "E:\python\lib\site-packages\urllib3\util\connection.py", line 95, in create_connection
    raise err
  File "E:\python\lib\site-packages\urllib3\util\connection.py", line 85, in create_connection
    sock.connect(sa)
ConnectionRefusedError: [WinError 10061] 由于目标计算机积极拒绝，无法连接。

During handling of the above exception, another exception occurred:

Traceback (most recent call last):
  File "E:\python\lib\site-packages\urllib3\connectionpool.py", line 703, in urlopen
    httplib_response = self._make_request(
  File "E:\python\lib\site-packages\urllib3\connectionpool.py", line 398, in _make_request
    conn.request(method, url, **httplib_request_kw)
  File "E:\python\lib\site-packages\urllib3\connection.py", line 239, in request
    super(HTTPConnection, self).request(method, url, body=body, headers=headers)
  File "E:\python\lib\http\client.py", line 1282, in request
    self._send_request(method, url, body, headers, encode_chunked)
  File "E:\python\lib\http\client.py", line 1328, in _send_request
    self.endheaders(body, encode_chunked=encode_chunked)
  File "E:\python\lib\http\client.py", line 1277, in endheaders
    self._send_output(message_body, encode_chunked=encode_chunked)
  File "E:\python\lib\http\client.py", line 1037, in _send_output
    self.send(msg)
  File "E:\python\lib\http\client.py", line 975, in send
    self.connect()
  File "E:\python\lib\site-packages\urllib3\connection.py", line 205, in connect
    conn = self._new_conn()
  File "E:\python\lib\site-packages\urllib3\connection.py", line 186, in _new_conn
    raise NewConnectionError(
urllib3.exceptions.NewConnectionError: <urllib3.connection.HTTPConnection object at 0x0000022E00A26680>: Failed to establish a new connection: [WinError 10061] 由于目标计算机积极拒绝，无法连接。

During handling of the above exception, another exception occurred:

Traceback (most recent call last):
  File "E:\python\lib\site-packages\requests\adapters.py", line 440, in send
    resp = conn.urlopen(
  File "E:\python\lib\site-packages\urllib3\connectionpool.py", line 785, in urlopen
    retries = retries.increment(
  File "E:\python\lib\site-packages\urllib3\util\retry.py", line 592, in increment
    raise MaxRetryError(_pool, url, error or ResponseError(cause))
urllib3.exceptions.MaxRetryError: HTTPConnectionPool(host='127.0.0.1', port=6800): Max retries exceeded with url: /listversions.json?project=health_redis (Caused by NewConnectionError('<urllib3.connection.HTTPConnection object at 0x0000022E00A26680>: Failed to establish a new connection: [WinError 10061] 由于目标计算机积极拒绝，无法连接。'))

During handling of the above exception, another exception occurred:

Traceback (most recent call last):
  File "E:\5703\git_nlp_repository\COMP5703CS65_NLP\polls\views.py", line 410, in project_version
    versions = scrapyd.list_versions(project_name)
  File "E:\python\lib\site-packages\scrapyd_api\wrapper.py", line 168, in list_versions
    json = self.client.get(url, params=params, timeout=self.timeout)
  File "E:\python\lib\site-packages\requests\sessions.py", line 542, in get
    return self.request('GET', url, **kwargs)
  File "E:\python\lib\site-packages\scrapyd_api\client.py", line 37, in request
    response = super(Client, self).request(*args, **kwargs)
  File "E:\python\lib\site-packages\requests\sessions.py", line 529, in request
    resp = self.send(prep, **send_kwargs)
  File "E:\python\lib\site-packages\requests\sessions.py", line 645, in send
    r = adapter.send(request, **kwargs)
  File "E:\python\lib\site-packages\requests\adapters.py", line 519, in send
    raise ConnectionError(e, request=request)
requests.exceptions.ConnectionError: HTTPConnectionPool(host='127.0.0.1', port=6800): Max retries exceeded with url: /listversions.json?project=health_redis (Caused by NewConnectionError('<urllib3.connection.HTTPConnection object at 0x0000022E00A26680>: Failed to establish a new connection: [WinError 10061] 由于目标计算机积极拒绝，无法连接。'))
ERROR - 2022-06-07 11:48:37,418 - process: 2456 - build.py - polls.build - 79 - build - error occurred ('settings',)
INFO - 2022-06-07 11:48:37,419 - process: 2456 - build.py - polls.build - 24 - build - successfully build project health_redis to egg file None
ERROR - 2022-06-07 11:49:57,119 - process: 2456 - views.py - polls.views - 412 - views - cannot connect to scrapyd
Traceback (most recent call last):
  File "E:\python\lib\site-packages\urllib3\connection.py", line 174, in _new_conn
    conn = connection.create_connection(
  File "E:\python\lib\site-packages\urllib3\util\connection.py", line 95, in create_connection
    raise err
  File "E:\python\lib\site-packages\urllib3\util\connection.py", line 85, in create_connection
    sock.connect(sa)
ConnectionRefusedError: [WinError 10061] 由于目标计算机积极拒绝，无法连接。

During handling of the above exception, another exception occurred:

Traceback (most recent call last):
  File "E:\python\lib\site-packages\urllib3\connectionpool.py", line 703, in urlopen
    httplib_response = self._make_request(
  File "E:\python\lib\site-packages\urllib3\connectionpool.py", line 398, in _make_request
    conn.request(method, url, **httplib_request_kw)
  File "E:\python\lib\site-packages\urllib3\connection.py", line 239, in request
    super(HTTPConnection, self).request(method, url, body=body, headers=headers)
  File "E:\python\lib\http\client.py", line 1282, in request
    self._send_request(method, url, body, headers, encode_chunked)
  File "E:\python\lib\http\client.py", line 1328, in _send_request
    self.endheaders(body, encode_chunked=encode_chunked)
  File "E:\python\lib\http\client.py", line 1277, in endheaders
    self._send_output(message_body, encode_chunked=encode_chunked)
  File "E:\python\lib\http\client.py", line 1037, in _send_output
    self.send(msg)
  File "E:\python\lib\http\client.py", line 975, in send
    self.connect()
  File "E:\python\lib\site-packages\urllib3\connection.py", line 205, in connect
    conn = self._new_conn()
  File "E:\python\lib\site-packages\urllib3\connection.py", line 186, in _new_conn
    raise NewConnectionError(
urllib3.exceptions.NewConnectionError: <urllib3.connection.HTTPConnection object at 0x0000022E00AA1B70>: Failed to establish a new connection: [WinError 10061] 由于目标计算机积极拒绝，无法连接。

During handling of the above exception, another exception occurred:

Traceback (most recent call last):
  File "E:\python\lib\site-packages\requests\adapters.py", line 440, in send
    resp = conn.urlopen(
  File "E:\python\lib\site-packages\urllib3\connectionpool.py", line 785, in urlopen
    retries = retries.increment(
  File "E:\python\lib\site-packages\urllib3\util\retry.py", line 592, in increment
    raise MaxRetryError(_pool, url, error or ResponseError(cause))
urllib3.exceptions.MaxRetryError: HTTPConnectionPool(host='127.0.0.1', port=6800): Max retries exceeded with url: /listversions.json?project=health_redis (Caused by NewConnectionError('<urllib3.connection.HTTPConnection object at 0x0000022E00AA1B70>: Failed to establish a new connection: [WinError 10061] 由于目标计算机积极拒绝，无法连接。'))

During handling of the above exception, another exception occurred:

Traceback (most recent call last):
  File "E:\5703\git_nlp_repository\COMP5703CS65_NLP\polls\views.py", line 410, in project_version
    versions = scrapyd.list_versions(project_name)
  File "E:\python\lib\site-packages\scrapyd_api\wrapper.py", line 168, in list_versions
    json = self.client.get(url, params=params, timeout=self.timeout)
  File "E:\python\lib\site-packages\requests\sessions.py", line 542, in get
    return self.request('GET', url, **kwargs)
  File "E:\python\lib\site-packages\scrapyd_api\client.py", line 37, in request
    response = super(Client, self).request(*args, **kwargs)
  File "E:\python\lib\site-packages\requests\sessions.py", line 529, in request
    resp = self.send(prep, **send_kwargs)
  File "E:\python\lib\site-packages\requests\sessions.py", line 645, in send
    r = adapter.send(request, **kwargs)
  File "E:\python\lib\site-packages\requests\adapters.py", line 519, in send
    raise ConnectionError(e, request=request)
requests.exceptions.ConnectionError: HTTPConnectionPool(host='127.0.0.1', port=6800): Max retries exceeded with url: /listversions.json?project=health_redis (Caused by NewConnectionError('<urllib3.connection.HTTPConnection object at 0x0000022E00AA1B70>: Failed to establish a new connection: [WinError 10061] 由于目标计算机积极拒绝，无法连接。'))
ERROR - 2022-06-07 11:49:57,120 - process: 2456 - utils.py - polls.utils - 533 - utils - HTTPConnectionPool(host='127.0.0.1', port=6800): Max retries exceeded with url: / (Caused by NewConnectionError('<urllib3.connection.HTTPConnection object at 0x0000022E00AA0F10>: Failed to establish a new connection: [WinError 10061] 由于目标计算机积极拒绝，无法连接。'))
Traceback (most recent call last):
  File "E:\python\lib\site-packages\urllib3\connection.py", line 174, in _new_conn
    conn = connection.create_connection(
  File "E:\python\lib\site-packages\urllib3\util\connection.py", line 95, in create_connection
    raise err
  File "E:\python\lib\site-packages\urllib3\util\connection.py", line 85, in create_connection
    sock.connect(sa)
ConnectionRefusedError: [WinError 10061] 由于目标计算机积极拒绝，无法连接。

During handling of the above exception, another exception occurred:

Traceback (most recent call last):
  File "E:\python\lib\site-packages\urllib3\connectionpool.py", line 703, in urlopen
    httplib_response = self._make_request(
  File "E:\python\lib\site-packages\urllib3\connectionpool.py", line 398, in _make_request
    conn.request(method, url, **httplib_request_kw)
  File "E:\python\lib\site-packages\urllib3\connection.py", line 239, in request
    super(HTTPConnection, self).request(method, url, body=body, headers=headers)
  File "E:\python\lib\http\client.py", line 1282, in request
    self._send_request(method, url, body, headers, encode_chunked)
  File "E:\python\lib\http\client.py", line 1328, in _send_request
    self.endheaders(body, encode_chunked=encode_chunked)
  File "E:\python\lib\http\client.py", line 1277, in endheaders
    self._send_output(message_body, encode_chunked=encode_chunked)
  File "E:\python\lib\http\client.py", line 1037, in _send_output
    self.send(msg)
  File "E:\python\lib\http\client.py", line 975, in send
    self.connect()
  File "E:\python\lib\site-packages\urllib3\connection.py", line 205, in connect
    conn = self._new_conn()
  File "E:\python\lib\site-packages\urllib3\connection.py", line 186, in _new_conn
    raise NewConnectionError(
urllib3.exceptions.NewConnectionError: <urllib3.connection.HTTPConnection object at 0x0000022E00AA0F10>: Failed to establish a new connection: [WinError 10061] 由于目标计算机积极拒绝，无法连接。

During handling of the above exception, another exception occurred:

Traceback (most recent call last):
  File "E:\python\lib\site-packages\requests\adapters.py", line 440, in send
    resp = conn.urlopen(
  File "E:\python\lib\site-packages\urllib3\connectionpool.py", line 785, in urlopen
    retries = retries.increment(
  File "E:\python\lib\site-packages\urllib3\util\retry.py", line 592, in increment
    raise MaxRetryError(_pool, url, error or ResponseError(cause))
urllib3.exceptions.MaxRetryError: HTTPConnectionPool(host='127.0.0.1', port=6800): Max retries exceeded with url: / (Caused by NewConnectionError('<urllib3.connection.HTTPConnection object at 0x0000022E00AA0F10>: Failed to establish a new connection: [WinError 10061] 由于目标计算机积极拒绝，无法连接。'))

During handling of the above exception, another exception occurred:

Traceback (most recent call last):
  File "E:\5703\git_nlp_repository\COMP5703CS65_NLP\polls\utils.py", line 531, in wrapper
    result = func(*args, **kwargs)
  File "E:\python\lib\site-packages\django\views\decorators\csrf.py", line 54, in wrapped_view
    return view_func(*args, **kwargs)
  File "E:\python\lib\site-packages\django\views\generic\base.py", line 84, in view
    return self.dispatch(request, *args, **kwargs)
  File "E:\python\lib\site-packages\rest_framework\views.py", line 509, in dispatch
    response = self.handle_exception(exc)
  File "E:\python\lib\site-packages\rest_framework\views.py", line 469, in handle_exception
    self.raise_uncaught_exception(exc)
  File "E:\python\lib\site-packages\rest_framework\views.py", line 480, in raise_uncaught_exception
    raise exc
  File "E:\python\lib\site-packages\rest_framework\views.py", line 506, in dispatch
    response = handler(request, *args, **kwargs)
  File "E:\python\lib\site-packages\rest_framework\decorators.py", line 50, in handler
    return func(*args, **kwargs)
  File "E:\5703\git_nlp_repository\COMP5703CS65_NLP\polls\views.py", line 127, in client_status
    requests.get(scrapyd_url(client.ip, client.port), timeout=3)
  File "E:\python\lib\site-packages\requests\api.py", line 75, in get
    return request('get', url, params=params, **kwargs)
  File "E:\python\lib\site-packages\requests\api.py", line 61, in request
    return session.request(method=method, url=url, **kwargs)
  File "E:\python\lib\site-packages\requests\sessions.py", line 529, in request
    resp = self.send(prep, **send_kwargs)
  File "E:\python\lib\site-packages\requests\sessions.py", line 645, in send
    r = adapter.send(request, **kwargs)
  File "E:\python\lib\site-packages\requests\adapters.py", line 519, in send
    raise ConnectionError(e, request=request)
requests.exceptions.ConnectionError: HTTPConnectionPool(host='127.0.0.1', port=6800): Max retries exceeded with url: / (Caused by NewConnectionError('<urllib3.connection.HTTPConnection object at 0x0000022E00AA0F10>: Failed to establish a new connection: [WinError 10061] 由于目标计算机积极拒绝，无法连接。'))
ERROR - 2022-06-07 11:50:00,842 - process: 2456 - build.py - polls.build - 79 - build - error occurred ('settings',)
INFO - 2022-06-07 11:50:00,843 - process: 2456 - build.py - polls.build - 24 - build - successfully build project health_redis to egg file None
ERROR - 2022-06-07 11:52:08,027 - process: 2456 - utils.py - polls.utils - 533 - utils - HTTPConnectionPool(host='127.0.0.1', port=6800): Max retries exceeded with url: / (Caused by NewConnectionError('<urllib3.connection.HTTPConnection object at 0x0000022E01125180>: Failed to establish a new connection: [WinError 10061] 由于目标计算机积极拒绝，无法连接。'))
Traceback (most recent call last):
  File "E:\python\lib\site-packages\urllib3\connection.py", line 174, in _new_conn
    conn = connection.create_connection(
  File "E:\python\lib\site-packages\urllib3\util\connection.py", line 95, in create_connection
    raise err
  File "E:\python\lib\site-packages\urllib3\util\connection.py", line 85, in create_connection
    sock.connect(sa)
ConnectionRefusedError: [WinError 10061] 由于目标计算机积极拒绝，无法连接。

During handling of the above exception, another exception occurred:

Traceback (most recent call last):
  File "E:\python\lib\site-packages\urllib3\connectionpool.py", line 703, in urlopen
    httplib_response = self._make_request(
  File "E:\python\lib\site-packages\urllib3\connectionpool.py", line 398, in _make_request
    conn.request(method, url, **httplib_request_kw)
  File "E:\python\lib\site-packages\urllib3\connection.py", line 239, in request
    super(HTTPConnection, self).request(method, url, body=body, headers=headers)
  File "E:\python\lib\http\client.py", line 1282, in request
    self._send_request(method, url, body, headers, encode_chunked)
  File "E:\python\lib\http\client.py", line 1328, in _send_request
    self.endheaders(body, encode_chunked=encode_chunked)
  File "E:\python\lib\http\client.py", line 1277, in endheaders
    self._send_output(message_body, encode_chunked=encode_chunked)
  File "E:\python\lib\http\client.py", line 1037, in _send_output
    self.send(msg)
  File "E:\python\lib\http\client.py", line 975, in send
    self.connect()
  File "E:\python\lib\site-packages\urllib3\connection.py", line 205, in connect
    conn = self._new_conn()
  File "E:\python\lib\site-packages\urllib3\connection.py", line 186, in _new_conn
    raise NewConnectionError(
urllib3.exceptions.NewConnectionError: <urllib3.connection.HTTPConnection object at 0x0000022E01125180>: Failed to establish a new connection: [WinError 10061] 由于目标计算机积极拒绝，无法连接。

During handling of the above exception, another exception occurred:

Traceback (most recent call last):
  File "E:\python\lib\site-packages\requests\adapters.py", line 440, in send
    resp = conn.urlopen(
  File "E:\python\lib\site-packages\urllib3\connectionpool.py", line 785, in urlopen
    retries = retries.increment(
  File "E:\python\lib\site-packages\urllib3\util\retry.py", line 592, in increment
    raise MaxRetryError(_pool, url, error or ResponseError(cause))
urllib3.exceptions.MaxRetryError: HTTPConnectionPool(host='127.0.0.1', port=6800): Max retries exceeded with url: / (Caused by NewConnectionError('<urllib3.connection.HTTPConnection object at 0x0000022E01125180>: Failed to establish a new connection: [WinError 10061] 由于目标计算机积极拒绝，无法连接。'))

During handling of the above exception, another exception occurred:

Traceback (most recent call last):
  File "E:\5703\git_nlp_repository\COMP5703CS65_NLP\polls\utils.py", line 531, in wrapper
    result = func(*args, **kwargs)
  File "E:\python\lib\site-packages\django\views\decorators\csrf.py", line 54, in wrapped_view
    return view_func(*args, **kwargs)
  File "E:\python\lib\site-packages\django\views\generic\base.py", line 84, in view
    return self.dispatch(request, *args, **kwargs)
  File "E:\python\lib\site-packages\rest_framework\views.py", line 509, in dispatch
    response = self.handle_exception(exc)
  File "E:\python\lib\site-packages\rest_framework\views.py", line 469, in handle_exception
    self.raise_uncaught_exception(exc)
  File "E:\python\lib\site-packages\rest_framework\views.py", line 480, in raise_uncaught_exception
    raise exc
  File "E:\python\lib\site-packages\rest_framework\views.py", line 506, in dispatch
    response = handler(request, *args, **kwargs)
  File "E:\python\lib\site-packages\rest_framework\decorators.py", line 50, in handler
    return func(*args, **kwargs)
  File "E:\5703\git_nlp_repository\COMP5703CS65_NLP\polls\views.py", line 127, in client_status
    requests.get(scrapyd_url(client.ip, client.port), timeout=3)
  File "E:\python\lib\site-packages\requests\api.py", line 75, in get
    return request('get', url, params=params, **kwargs)
  File "E:\python\lib\site-packages\requests\api.py", line 61, in request
    return session.request(method=method, url=url, **kwargs)
  File "E:\python\lib\site-packages\requests\sessions.py", line 529, in request
    resp = self.send(prep, **send_kwargs)
  File "E:\python\lib\site-packages\requests\sessions.py", line 645, in send
    r = adapter.send(request, **kwargs)
  File "E:\python\lib\site-packages\requests\adapters.py", line 519, in send
    raise ConnectionError(e, request=request)
requests.exceptions.ConnectionError: HTTPConnectionPool(host='127.0.0.1', port=6800): Max retries exceeded with url: / (Caused by NewConnectionError('<urllib3.connection.HTTPConnection object at 0x0000022E01125180>: Failed to establish a new connection: [WinError 10061] 由于目标计算机积极拒绝，无法连接。'))
ERROR - 2022-06-07 11:52:08,029 - process: 2456 - views.py - polls.views - 412 - views - cannot connect to scrapyd
Traceback (most recent call last):
  File "E:\python\lib\site-packages\urllib3\connection.py", line 174, in _new_conn
    conn = connection.create_connection(
  File "E:\python\lib\site-packages\urllib3\util\connection.py", line 95, in create_connection
    raise err
  File "E:\python\lib\site-packages\urllib3\util\connection.py", line 85, in create_connection
    sock.connect(sa)
ConnectionRefusedError: [WinError 10061] 由于目标计算机积极拒绝，无法连接。

During handling of the above exception, another exception occurred:

Traceback (most recent call last):
  File "E:\python\lib\site-packages\urllib3\connectionpool.py", line 703, in urlopen
    httplib_response = self._make_request(
  File "E:\python\lib\site-packages\urllib3\connectionpool.py", line 398, in _make_request
    conn.request(method, url, **httplib_request_kw)
  File "E:\python\lib\site-packages\urllib3\connection.py", line 239, in request
    super(HTTPConnection, self).request(method, url, body=body, headers=headers)
  File "E:\python\lib\http\client.py", line 1282, in request
    self._send_request(method, url, body, headers, encode_chunked)
  File "E:\python\lib\http\client.py", line 1328, in _send_request
    self.endheaders(body, encode_chunked=encode_chunked)
  File "E:\python\lib\http\client.py", line 1277, in endheaders
    self._send_output(message_body, encode_chunked=encode_chunked)
  File "E:\python\lib\http\client.py", line 1037, in _send_output
    self.send(msg)
  File "E:\python\lib\http\client.py", line 975, in send
    self.connect()
  File "E:\python\lib\site-packages\urllib3\connection.py", line 205, in connect
    conn = self._new_conn()
  File "E:\python\lib\site-packages\urllib3\connection.py", line 186, in _new_conn
    raise NewConnectionError(
urllib3.exceptions.NewConnectionError: <urllib3.connection.HTTPConnection object at 0x0000022E00957AF0>: Failed to establish a new connection: [WinError 10061] 由于目标计算机积极拒绝，无法连接。

During handling of the above exception, another exception occurred:

Traceback (most recent call last):
  File "E:\python\lib\site-packages\requests\adapters.py", line 440, in send
    resp = conn.urlopen(
  File "E:\python\lib\site-packages\urllib3\connectionpool.py", line 785, in urlopen
    retries = retries.increment(
  File "E:\python\lib\site-packages\urllib3\util\retry.py", line 592, in increment
    raise MaxRetryError(_pool, url, error or ResponseError(cause))
urllib3.exceptions.MaxRetryError: HTTPConnectionPool(host='127.0.0.1', port=6800): Max retries exceeded with url: /listversions.json?project=health_redis (Caused by NewConnectionError('<urllib3.connection.HTTPConnection object at 0x0000022E00957AF0>: Failed to establish a new connection: [WinError 10061] 由于目标计算机积极拒绝，无法连接。'))

During handling of the above exception, another exception occurred:

Traceback (most recent call last):
  File "E:\5703\git_nlp_repository\COMP5703CS65_NLP\polls\views.py", line 410, in project_version
    versions = scrapyd.list_versions(project_name)
  File "E:\python\lib\site-packages\scrapyd_api\wrapper.py", line 168, in list_versions
    json = self.client.get(url, params=params, timeout=self.timeout)
  File "E:\python\lib\site-packages\requests\sessions.py", line 542, in get
    return self.request('GET', url, **kwargs)
  File "E:\python\lib\site-packages\scrapyd_api\client.py", line 37, in request
    response = super(Client, self).request(*args, **kwargs)
  File "E:\python\lib\site-packages\requests\sessions.py", line 529, in request
    resp = self.send(prep, **send_kwargs)
  File "E:\python\lib\site-packages\requests\sessions.py", line 645, in send
    r = adapter.send(request, **kwargs)
  File "E:\python\lib\site-packages\requests\adapters.py", line 519, in send
    raise ConnectionError(e, request=request)
requests.exceptions.ConnectionError: HTTPConnectionPool(host='127.0.0.1', port=6800): Max retries exceeded with url: /listversions.json?project=health_redis (Caused by NewConnectionError('<urllib3.connection.HTTPConnection object at 0x0000022E00957AF0>: Failed to establish a new connection: [WinError 10061] 由于目标计算机积极拒绝，无法连接。'))
INFO - 2022-06-07 11:52:11,598 - process: 2456 - build.py - polls.build - 24 - build - successfully build project health_redis to egg file E:\5703\git_nlp_repository\COMP5703CS65_NLP\projects\health_redis\health_redis-1.0-py3.10.egg
ERROR - 2022-06-07 11:52:57,063 - process: 2456 - utils.py - polls.utils - 533 - utils - HTTPConnectionPool(host='127.0.0.1', port=6800): Max retries exceeded with url: / (Caused by NewConnectionError('<urllib3.connection.HTTPConnection object at 0x0000022E007C5120>: Failed to establish a new connection: [WinError 10061] 由于目标计算机积极拒绝，无法连接。'))
Traceback (most recent call last):
  File "E:\python\lib\site-packages\urllib3\connection.py", line 174, in _new_conn
    conn = connection.create_connection(
  File "E:\python\lib\site-packages\urllib3\util\connection.py", line 95, in create_connection
    raise err
  File "E:\python\lib\site-packages\urllib3\util\connection.py", line 85, in create_connection
    sock.connect(sa)
ConnectionRefusedError: [WinError 10061] 由于目标计算机积极拒绝，无法连接。

During handling of the above exception, another exception occurred:

Traceback (most recent call last):
  File "E:\python\lib\site-packages\urllib3\connectionpool.py", line 703, in urlopen
    httplib_response = self._make_request(
  File "E:\python\lib\site-packages\urllib3\connectionpool.py", line 398, in _make_request
    conn.request(method, url, **httplib_request_kw)
  File "E:\python\lib\site-packages\urllib3\connection.py", line 239, in request
    super(HTTPConnection, self).request(method, url, body=body, headers=headers)
  File "E:\python\lib\http\client.py", line 1282, in request
    self._send_request(method, url, body, headers, encode_chunked)
  File "E:\python\lib\http\client.py", line 1328, in _send_request
    self.endheaders(body, encode_chunked=encode_chunked)
  File "E:\python\lib\http\client.py", line 1277, in endheaders
    self._send_output(message_body, encode_chunked=encode_chunked)
  File "E:\python\lib\http\client.py", line 1037, in _send_output
    self.send(msg)
  File "E:\python\lib\http\client.py", line 975, in send
    self.connect()
  File "E:\python\lib\site-packages\urllib3\connection.py", line 205, in connect
    conn = self._new_conn()
  File "E:\python\lib\site-packages\urllib3\connection.py", line 186, in _new_conn
    raise NewConnectionError(
urllib3.exceptions.NewConnectionError: <urllib3.connection.HTTPConnection object at 0x0000022E007C5120>: Failed to establish a new connection: [WinError 10061] 由于目标计算机积极拒绝，无法连接。

During handling of the above exception, another exception occurred:

Traceback (most recent call last):
  File "E:\python\lib\site-packages\requests\adapters.py", line 440, in send
    resp = conn.urlopen(
  File "E:\python\lib\site-packages\urllib3\connectionpool.py", line 785, in urlopen
    retries = retries.increment(
  File "E:\python\lib\site-packages\urllib3\util\retry.py", line 592, in increment
    raise MaxRetryError(_pool, url, error or ResponseError(cause))
urllib3.exceptions.MaxRetryError: HTTPConnectionPool(host='127.0.0.1', port=6800): Max retries exceeded with url: / (Caused by NewConnectionError('<urllib3.connection.HTTPConnection object at 0x0000022E007C5120>: Failed to establish a new connection: [WinError 10061] 由于目标计算机积极拒绝，无法连接。'))

During handling of the above exception, another exception occurred:

Traceback (most recent call last):
  File "E:\5703\git_nlp_repository\COMP5703CS65_NLP\polls\utils.py", line 531, in wrapper
    result = func(*args, **kwargs)
  File "E:\python\lib\site-packages\django\views\decorators\csrf.py", line 54, in wrapped_view
    return view_func(*args, **kwargs)
  File "E:\python\lib\site-packages\django\views\generic\base.py", line 84, in view
    return self.dispatch(request, *args, **kwargs)
  File "E:\python\lib\site-packages\rest_framework\views.py", line 509, in dispatch
    response = self.handle_exception(exc)
  File "E:\python\lib\site-packages\rest_framework\views.py", line 469, in handle_exception
    self.raise_uncaught_exception(exc)
  File "E:\python\lib\site-packages\rest_framework\views.py", line 480, in raise_uncaught_exception
    raise exc
  File "E:\python\lib\site-packages\rest_framework\views.py", line 506, in dispatch
    response = handler(request, *args, **kwargs)
  File "E:\python\lib\site-packages\rest_framework\decorators.py", line 50, in handler
    return func(*args, **kwargs)
  File "E:\5703\git_nlp_repository\COMP5703CS65_NLP\polls\views.py", line 127, in client_status
    requests.get(scrapyd_url(client.ip, client.port), timeout=3)
  File "E:\python\lib\site-packages\requests\api.py", line 75, in get
    return request('get', url, params=params, **kwargs)
  File "E:\python\lib\site-packages\requests\api.py", line 61, in request
    return session.request(method=method, url=url, **kwargs)
  File "E:\python\lib\site-packages\requests\sessions.py", line 529, in request
    resp = self.send(prep, **send_kwargs)
  File "E:\python\lib\site-packages\requests\sessions.py", line 645, in send
    r = adapter.send(request, **kwargs)
  File "E:\python\lib\site-packages\requests\adapters.py", line 519, in send
    raise ConnectionError(e, request=request)
requests.exceptions.ConnectionError: HTTPConnectionPool(host='127.0.0.1', port=6800): Max retries exceeded with url: / (Caused by NewConnectionError('<urllib3.connection.HTTPConnection object at 0x0000022E007C5120>: Failed to establish a new connection: [WinError 10061] 由于目标计算机积极拒绝，无法连接。'))
ERROR - 2022-06-07 11:53:03,281 - process: 2456 - utils.py - polls.utils - 533 - utils - HTTPConnectionPool(host='127.0.0.1', port=6800): Max retries exceeded with url: / (Caused by NewConnectionError('<urllib3.connection.HTTPConnection object at 0x0000022E0063C5E0>: Failed to establish a new connection: [WinError 10061] 由于目标计算机积极拒绝，无法连接。'))
Traceback (most recent call last):
  File "E:\python\lib\site-packages\urllib3\connection.py", line 174, in _new_conn
    conn = connection.create_connection(
  File "E:\python\lib\site-packages\urllib3\util\connection.py", line 95, in create_connection
    raise err
  File "E:\python\lib\site-packages\urllib3\util\connection.py", line 85, in create_connection
    sock.connect(sa)
ConnectionRefusedError: [WinError 10061] 由于目标计算机积极拒绝，无法连接。

During handling of the above exception, another exception occurred:

Traceback (most recent call last):
  File "E:\python\lib\site-packages\urllib3\connectionpool.py", line 703, in urlopen
    httplib_response = self._make_request(
  File "E:\python\lib\site-packages\urllib3\connectionpool.py", line 398, in _make_request
    conn.request(method, url, **httplib_request_kw)
  File "E:\python\lib\site-packages\urllib3\connection.py", line 239, in request
    super(HTTPConnection, self).request(method, url, body=body, headers=headers)
  File "E:\python\lib\http\client.py", line 1282, in request
    self._send_request(method, url, body, headers, encode_chunked)
  File "E:\python\lib\http\client.py", line 1328, in _send_request
    self.endheaders(body, encode_chunked=encode_chunked)
  File "E:\python\lib\http\client.py", line 1277, in endheaders
    self._send_output(message_body, encode_chunked=encode_chunked)
  File "E:\python\lib\http\client.py", line 1037, in _send_output
    self.send(msg)
  File "E:\python\lib\http\client.py", line 975, in send
    self.connect()
  File "E:\python\lib\site-packages\urllib3\connection.py", line 205, in connect
    conn = self._new_conn()
  File "E:\python\lib\site-packages\urllib3\connection.py", line 186, in _new_conn
    raise NewConnectionError(
urllib3.exceptions.NewConnectionError: <urllib3.connection.HTTPConnection object at 0x0000022E0063C5E0>: Failed to establish a new connection: [WinError 10061] 由于目标计算机积极拒绝，无法连接。

During handling of the above exception, another exception occurred:

Traceback (most recent call last):
  File "E:\python\lib\site-packages\requests\adapters.py", line 440, in send
    resp = conn.urlopen(
  File "E:\python\lib\site-packages\urllib3\connectionpool.py", line 785, in urlopen
    retries = retries.increment(
  File "E:\python\lib\site-packages\urllib3\util\retry.py", line 592, in increment
    raise MaxRetryError(_pool, url, error or ResponseError(cause))
urllib3.exceptions.MaxRetryError: HTTPConnectionPool(host='127.0.0.1', port=6800): Max retries exceeded with url: / (Caused by NewConnectionError('<urllib3.connection.HTTPConnection object at 0x0000022E0063C5E0>: Failed to establish a new connection: [WinError 10061] 由于目标计算机积极拒绝，无法连接。'))

During handling of the above exception, another exception occurred:

Traceback (most recent call last):
  File "E:\5703\git_nlp_repository\COMP5703CS65_NLP\polls\utils.py", line 531, in wrapper
    result = func(*args, **kwargs)
  File "E:\python\lib\site-packages\django\views\decorators\csrf.py", line 54, in wrapped_view
    return view_func(*args, **kwargs)
  File "E:\python\lib\site-packages\django\views\generic\base.py", line 84, in view
    return self.dispatch(request, *args, **kwargs)
  File "E:\python\lib\site-packages\rest_framework\views.py", line 509, in dispatch
    response = self.handle_exception(exc)
  File "E:\python\lib\site-packages\rest_framework\views.py", line 469, in handle_exception
    self.raise_uncaught_exception(exc)
  File "E:\python\lib\site-packages\rest_framework\views.py", line 480, in raise_uncaught_exception
    raise exc
  File "E:\python\lib\site-packages\rest_framework\views.py", line 506, in dispatch
    response = handler(request, *args, **kwargs)
  File "E:\python\lib\site-packages\rest_framework\decorators.py", line 50, in handler
    return func(*args, **kwargs)
  File "E:\5703\git_nlp_repository\COMP5703CS65_NLP\polls\views.py", line 127, in client_status
    requests.get(scrapyd_url(client.ip, client.port), timeout=3)
  File "E:\python\lib\site-packages\requests\api.py", line 75, in get
    return request('get', url, params=params, **kwargs)
  File "E:\python\lib\site-packages\requests\api.py", line 61, in request
    return session.request(method=method, url=url, **kwargs)
  File "E:\python\lib\site-packages\requests\sessions.py", line 529, in request
    resp = self.send(prep, **send_kwargs)
  File "E:\python\lib\site-packages\requests\sessions.py", line 645, in send
    r = adapter.send(request, **kwargs)
  File "E:\python\lib\site-packages\requests\adapters.py", line 519, in send
    raise ConnectionError(e, request=request)
requests.exceptions.ConnectionError: HTTPConnectionPool(host='127.0.0.1', port=6800): Max retries exceeded with url: / (Caused by NewConnectionError('<urllib3.connection.HTTPConnection object at 0x0000022E0063C5E0>: Failed to establish a new connection: [WinError 10061] 由于目标计算机积极拒绝，无法连接。'))
