ERROR - 2022-06-02 03:02:35,052 - process: 22020 - utils.py - polls.utils - 84 - utils - 'dict' object is not callable
Traceback (most recent call last):
  File "C:\Users\46121\PycharmProjects\COMP5703CS65_NLP\polls\utils.py", line 82, in wrapper
    result = func(*args, **kwargs)
  File "C:\Users\46121\PycharmProjects\COMP5703CS65_NLP\vr_envver\lib\site-packages\django\views\decorators\csrf.py", line 54, in wrapped_view
    return view_func(*args, **kwargs)
  File "C:\Users\46121\PycharmProjects\COMP5703CS65_NLP\vr_envver\lib\site-packages\django\views\generic\base.py", line 84, in view
    return self.dispatch(request, *args, **kwargs)
  File "C:\Users\46121\PycharmProjects\COMP5703CS65_NLP\vr_envver\lib\site-packages\rest_framework\views.py", line 509, in dispatch
    response = self.handle_exception(exc)
  File "C:\Users\46121\PycharmProjects\COMP5703CS65_NLP\vr_envver\lib\site-packages\rest_framework\views.py", line 469, in handle_exception
    self.raise_uncaught_exception(exc)
  File "C:\Users\46121\PycharmProjects\COMP5703CS65_NLP\vr_envver\lib\site-packages\rest_framework\views.py", line 480, in raise_uncaught_exception
    raise exc
  File "C:\Users\46121\PycharmProjects\COMP5703CS65_NLP\vr_envver\lib\site-packages\rest_framework\views.py", line 506, in dispatch
    response = handler(request, *args, **kwargs)
  File "C:\Users\46121\PycharmProjects\COMP5703CS65_NLP\vr_envver\lib\site-packages\rest_framework\decorators.py", line 50, in handler
    return func(*args, **kwargs)
  File "C:\Users\46121\PycharmProjects\COMP5703CS65_NLP\polls\views.py", line 1194, in neo4j_chart_data
    return JsonResponse({'legend':legend_data},{'chart':legend_data})
  File "C:\Users\46121\PycharmProjects\COMP5703CS65_NLP\polls\response.py", line 32, in __init__
    data = json.dumps(data, cls=encoder, **json_dumps_params)
  File "C:\Users\46121\AppData\Local\Programs\Python\Python38\lib\json\__init__.py", line 234, in dumps
    return cls(
TypeError: 'dict' object is not callable
