ERROR - 2022-05-25 14:13:50,494 - process: 27260 - utils.py - polls.utils - 84 - utils - local variable 'result_find' referenced before assignment
Traceback (most recent call last):
  File "C:\Users\46121\PycharmProjects\CS65_3\cs65_4\cs65_5\polls\utils.py", line 82, in wrapper
    result = func(*args, **kwargs)
  File "C:\Users\46121\PycharmProjects\CS65_3\vr_env\lib\site-packages\django\views\decorators\csrf.py", line 54, in wrapped_view
    return view_func(*args, **kwargs)
  File "C:\Users\46121\PycharmProjects\CS65_3\vr_env\lib\site-packages\django\views\generic\base.py", line 69, in view
    return self.dispatch(request, *args, **kwargs)
  File "C:\Users\46121\PycharmProjects\CS65_3\vr_env\lib\site-packages\rest_framework\views.py", line 509, in dispatch
    response = self.handle_exception(exc)
  File "C:\Users\46121\PycharmProjects\CS65_3\vr_env\lib\site-packages\rest_framework\views.py", line 469, in handle_exception
    self.raise_uncaught_exception(exc)
  File "C:\Users\46121\PycharmProjects\CS65_3\vr_env\lib\site-packages\rest_framework\views.py", line 480, in raise_uncaught_exception
    raise exc
  File "C:\Users\46121\PycharmProjects\CS65_3\vr_env\lib\site-packages\rest_framework\views.py", line 506, in dispatch
    response = handler(request, *args, **kwargs)
  File "C:\Users\46121\PycharmProjects\CS65_3\vr_env\lib\site-packages\rest_framework\decorators.py", line 50, in handler
    return func(*args, **kwargs)
  File "C:\Users\46121\PycharmProjects\CS65_3\cs65_4\cs65_5\polls\views.py", line 1120, in neo4j_find
    output = app.find_node(disease_name)
  File "C:\Users\46121\PycharmProjects\CS65_3\cs65_4\cs65_5\polls\neo4jQuery.py", line 59, in find_node
    return result_find
UnboundLocalError: local variable 'result_find' referenced before assignment
ERROR - 2022-05-25 14:18:03,903 - process: 27260 - utils.py - polls.utils - 84 - utils - local variable 'result_find' referenced before assignment
Traceback (most recent call last):
  File "C:\Users\46121\PycharmProjects\CS65_3\cs65_4\cs65_5\polls\utils.py", line 82, in wrapper
    result = func(*args, **kwargs)
  File "C:\Users\46121\PycharmProjects\CS65_3\vr_env\lib\site-packages\django\views\decorators\csrf.py", line 54, in wrapped_view
    return view_func(*args, **kwargs)
  File "C:\Users\46121\PycharmProjects\CS65_3\vr_env\lib\site-packages\django\views\generic\base.py", line 69, in view
    return self.dispatch(request, *args, **kwargs)
  File "C:\Users\46121\PycharmProjects\CS65_3\vr_env\lib\site-packages\rest_framework\views.py", line 509, in dispatch
    response = self.handle_exception(exc)
  File "C:\Users\46121\PycharmProjects\CS65_3\vr_env\lib\site-packages\rest_framework\views.py", line 469, in handle_exception
    self.raise_uncaught_exception(exc)
  File "C:\Users\46121\PycharmProjects\CS65_3\vr_env\lib\site-packages\rest_framework\views.py", line 480, in raise_uncaught_exception
    raise exc
  File "C:\Users\46121\PycharmProjects\CS65_3\vr_env\lib\site-packages\rest_framework\views.py", line 506, in dispatch
    response = handler(request, *args, **kwargs)
  File "C:\Users\46121\PycharmProjects\CS65_3\vr_env\lib\site-packages\rest_framework\decorators.py", line 50, in handler
    return func(*args, **kwargs)
  File "C:\Users\46121\PycharmProjects\CS65_3\cs65_4\cs65_5\polls\views.py", line 1120, in neo4j_find
    output = app.find_node(disease_name)
  File "C:\Users\46121\PycharmProjects\CS65_3\cs65_4\cs65_5\polls\neo4jQuery.py", line 59, in find_node
    return result_find
UnboundLocalError: local variable 'result_find' referenced before assignment
ERROR - 2022-05-25 14:18:19,790 - process: 27260 - utils.py - polls.utils - 84 - utils - local variable 'result_find' referenced before assignment
Traceback (most recent call last):
  File "C:\Users\46121\PycharmProjects\CS65_3\cs65_4\cs65_5\polls\utils.py", line 82, in wrapper
    result = func(*args, **kwargs)
  File "C:\Users\46121\PycharmProjects\CS65_3\vr_env\lib\site-packages\django\views\decorators\csrf.py", line 54, in wrapped_view
    return view_func(*args, **kwargs)
  File "C:\Users\46121\PycharmProjects\CS65_3\vr_env\lib\site-packages\django\views\generic\base.py", line 69, in view
    return self.dispatch(request, *args, **kwargs)
  File "C:\Users\46121\PycharmProjects\CS65_3\vr_env\lib\site-packages\rest_framework\views.py", line 509, in dispatch
    response = self.handle_exception(exc)
  File "C:\Users\46121\PycharmProjects\CS65_3\vr_env\lib\site-packages\rest_framework\views.py", line 469, in handle_exception
    self.raise_uncaught_exception(exc)
  File "C:\Users\46121\PycharmProjects\CS65_3\vr_env\lib\site-packages\rest_framework\views.py", line 480, in raise_uncaught_exception
    raise exc
  File "C:\Users\46121\PycharmProjects\CS65_3\vr_env\lib\site-packages\rest_framework\views.py", line 506, in dispatch
    response = handler(request, *args, **kwargs)
  File "C:\Users\46121\PycharmProjects\CS65_3\vr_env\lib\site-packages\rest_framework\decorators.py", line 50, in handler
    return func(*args, **kwargs)
  File "C:\Users\46121\PycharmProjects\CS65_3\cs65_4\cs65_5\polls\views.py", line 1120, in neo4j_find
    output = app.find_node(disease_name)
  File "C:\Users\46121\PycharmProjects\CS65_3\cs65_4\cs65_5\polls\neo4jQuery.py", line 59, in find_node
    return result_find
UnboundLocalError: local variable 'result_find' referenced before assignment
ERROR - 2022-05-25 15:38:35,279 - process: 27260 - utils.py - polls.utils - 84 - utils - HTTPConnectionPool(host='127.0.0.1', port=6800): Max retries exceeded with url: / (Caused by NewConnectionError('<urllib3.connection.HTTPConnection object at 0x000001F38F3CBDC0>: Failed to establish a new connection: [WinError 10061] No connection could be made because the target machine actively refused it'))
Traceback (most recent call last):
  File "C:\Users\46121\PycharmProjects\CS65_3\vr_env\lib\site-packages\urllib3\connection.py", line 174, in _new_conn
    conn = connection.create_connection(
  File "C:\Users\46121\PycharmProjects\CS65_3\vr_env\lib\site-packages\urllib3\util\connection.py", line 95, in create_connection
    raise err
  File "C:\Users\46121\PycharmProjects\CS65_3\vr_env\lib\site-packages\urllib3\util\connection.py", line 85, in create_connection
    sock.connect(sa)
ConnectionRefusedError: [WinError 10061] No connection could be made because the target machine actively refused it

During handling of the above exception, another exception occurred:

Traceback (most recent call last):
  File "C:\Users\46121\PycharmProjects\CS65_3\vr_env\lib\site-packages\urllib3\connectionpool.py", line 703, in urlopen
    httplib_response = self._make_request(
  File "C:\Users\46121\PycharmProjects\CS65_3\vr_env\lib\site-packages\urllib3\connectionpool.py", line 398, in _make_request
    conn.request(method, url, **httplib_request_kw)
  File "C:\Users\46121\PycharmProjects\CS65_3\vr_env\lib\site-packages\urllib3\connection.py", line 239, in request
    super(HTTPConnection, self).request(method, url, body=body, headers=headers)
  File "C:\Users\46121\AppData\Local\Programs\Python\Python38\lib\http\client.py", line 1240, in request
    self._send_request(method, url, body, headers, encode_chunked)
  File "C:\Users\46121\AppData\Local\Programs\Python\Python38\lib\http\client.py", line 1286, in _send_request
    self.endheaders(body, encode_chunked=encode_chunked)
  File "C:\Users\46121\AppData\Local\Programs\Python\Python38\lib\http\client.py", line 1235, in endheaders
    self._send_output(message_body, encode_chunked=encode_chunked)
  File "C:\Users\46121\AppData\Local\Programs\Python\Python38\lib\http\client.py", line 1006, in _send_output
    self.send(msg)
  File "C:\Users\46121\AppData\Local\Programs\Python\Python38\lib\http\client.py", line 946, in send
    self.connect()
  File "C:\Users\46121\PycharmProjects\CS65_3\vr_env\lib\site-packages\urllib3\connection.py", line 205, in connect
    conn = self._new_conn()
  File "C:\Users\46121\PycharmProjects\CS65_3\vr_env\lib\site-packages\urllib3\connection.py", line 186, in _new_conn
    raise NewConnectionError(
urllib3.exceptions.NewConnectionError: <urllib3.connection.HTTPConnection object at 0x000001F38F3CBDC0>: Failed to establish a new connection: [WinError 10061] No connection could be made because the target machine actively refused it

During handling of the above exception, another exception occurred:

Traceback (most recent call last):
  File "C:\Users\46121\PycharmProjects\CS65_3\vr_env\lib\site-packages\requests\adapters.py", line 440, in send
    resp = conn.urlopen(
  File "C:\Users\46121\PycharmProjects\CS65_3\vr_env\lib\site-packages\urllib3\connectionpool.py", line 785, in urlopen
    retries = retries.increment(
  File "C:\Users\46121\PycharmProjects\CS65_3\vr_env\lib\site-packages\urllib3\util\retry.py", line 592, in increment
    raise MaxRetryError(_pool, url, error or ResponseError(cause))
urllib3.exceptions.MaxRetryError: HTTPConnectionPool(host='127.0.0.1', port=6800): Max retries exceeded with url: / (Caused by NewConnectionError('<urllib3.connection.HTTPConnection object at 0x000001F38F3CBDC0>: Failed to establish a new connection: [WinError 10061] No connection could be made because the target machine actively refused it'))

During handling of the above exception, another exception occurred:

Traceback (most recent call last):
  File "C:\Users\46121\PycharmProjects\CS65_3\cs65_4\cs65_5\polls\utils.py", line 82, in wrapper
    result = func(*args, **kwargs)
  File "C:\Users\46121\PycharmProjects\CS65_3\vr_env\lib\site-packages\django\views\decorators\csrf.py", line 54, in wrapped_view
    return view_func(*args, **kwargs)
  File "C:\Users\46121\PycharmProjects\CS65_3\vr_env\lib\site-packages\django\views\generic\base.py", line 69, in view
    return self.dispatch(request, *args, **kwargs)
  File "C:\Users\46121\PycharmProjects\CS65_3\vr_env\lib\site-packages\rest_framework\views.py", line 509, in dispatch
    response = self.handle_exception(exc)
  File "C:\Users\46121\PycharmProjects\CS65_3\vr_env\lib\site-packages\rest_framework\views.py", line 469, in handle_exception
    self.raise_uncaught_exception(exc)
  File "C:\Users\46121\PycharmProjects\CS65_3\vr_env\lib\site-packages\rest_framework\views.py", line 480, in raise_uncaught_exception
    raise exc
  File "C:\Users\46121\PycharmProjects\CS65_3\vr_env\lib\site-packages\rest_framework\views.py", line 506, in dispatch
    response = handler(request, *args, **kwargs)
  File "C:\Users\46121\PycharmProjects\CS65_3\vr_env\lib\site-packages\rest_framework\decorators.py", line 50, in handler
    return func(*args, **kwargs)
  File "C:\Users\46121\PycharmProjects\CS65_3\cs65_4\cs65_5\polls\views.py", line 171, in client_status
    requests.get(scrapyd_url(client.ip, client.port), timeout=3)
  File "C:\Users\46121\PycharmProjects\CS65_3\vr_env\lib\site-packages\requests\api.py", line 75, in get
    return request('get', url, params=params, **kwargs)
  File "C:\Users\46121\PycharmProjects\CS65_3\vr_env\lib\site-packages\requests\api.py", line 61, in request
    return session.request(method=method, url=url, **kwargs)
  File "C:\Users\46121\PycharmProjects\CS65_3\vr_env\lib\site-packages\requests\sessions.py", line 529, in request
    resp = self.send(prep, **send_kwargs)
  File "C:\Users\46121\PycharmProjects\CS65_3\vr_env\lib\site-packages\requests\sessions.py", line 645, in send
    r = adapter.send(request, **kwargs)
  File "C:\Users\46121\PycharmProjects\CS65_3\vr_env\lib\site-packages\requests\adapters.py", line 519, in send
    raise ConnectionError(e, request=request)
requests.exceptions.ConnectionError: HTTPConnectionPool(host='127.0.0.1', port=6800): Max retries exceeded with url: / (Caused by NewConnectionError('<urllib3.connection.HTTPConnection object at 0x000001F38F3CBDC0>: Failed to establish a new connection: [WinError 10061] No connection could be made because the target machine actively refused it'))
ERROR - 2022-05-25 15:38:47,309 - process: 27260 - utils.py - polls.utils - 84 - utils - HTTPConnectionPool(host='127.0.0.1', port=6800): Max retries exceeded with url: / (Caused by NewConnectionError('<urllib3.connection.HTTPConnection object at 0x000001F38F147A30>: Failed to establish a new connection: [WinError 10061] No connection could be made because the target machine actively refused it'))
Traceback (most recent call last):
  File "C:\Users\46121\PycharmProjects\CS65_3\vr_env\lib\site-packages\urllib3\connection.py", line 174, in _new_conn
    conn = connection.create_connection(
  File "C:\Users\46121\PycharmProjects\CS65_3\vr_env\lib\site-packages\urllib3\util\connection.py", line 95, in create_connection
    raise err
  File "C:\Users\46121\PycharmProjects\CS65_3\vr_env\lib\site-packages\urllib3\util\connection.py", line 85, in create_connection
    sock.connect(sa)
ConnectionRefusedError: [WinError 10061] No connection could be made because the target machine actively refused it

During handling of the above exception, another exception occurred:

Traceback (most recent call last):
  File "C:\Users\46121\PycharmProjects\CS65_3\vr_env\lib\site-packages\urllib3\connectionpool.py", line 703, in urlopen
    httplib_response = self._make_request(
  File "C:\Users\46121\PycharmProjects\CS65_3\vr_env\lib\site-packages\urllib3\connectionpool.py", line 398, in _make_request
    conn.request(method, url, **httplib_request_kw)
  File "C:\Users\46121\PycharmProjects\CS65_3\vr_env\lib\site-packages\urllib3\connection.py", line 239, in request
    super(HTTPConnection, self).request(method, url, body=body, headers=headers)
  File "C:\Users\46121\AppData\Local\Programs\Python\Python38\lib\http\client.py", line 1240, in request
    self._send_request(method, url, body, headers, encode_chunked)
  File "C:\Users\46121\AppData\Local\Programs\Python\Python38\lib\http\client.py", line 1286, in _send_request
    self.endheaders(body, encode_chunked=encode_chunked)
  File "C:\Users\46121\AppData\Local\Programs\Python\Python38\lib\http\client.py", line 1235, in endheaders
    self._send_output(message_body, encode_chunked=encode_chunked)
  File "C:\Users\46121\AppData\Local\Programs\Python\Python38\lib\http\client.py", line 1006, in _send_output
    self.send(msg)
  File "C:\Users\46121\AppData\Local\Programs\Python\Python38\lib\http\client.py", line 946, in send
    self.connect()
  File "C:\Users\46121\PycharmProjects\CS65_3\vr_env\lib\site-packages\urllib3\connection.py", line 205, in connect
    conn = self._new_conn()
  File "C:\Users\46121\PycharmProjects\CS65_3\vr_env\lib\site-packages\urllib3\connection.py", line 186, in _new_conn
    raise NewConnectionError(
urllib3.exceptions.NewConnectionError: <urllib3.connection.HTTPConnection object at 0x000001F38F147A30>: Failed to establish a new connection: [WinError 10061] No connection could be made because the target machine actively refused it

During handling of the above exception, another exception occurred:

Traceback (most recent call last):
  File "C:\Users\46121\PycharmProjects\CS65_3\vr_env\lib\site-packages\requests\adapters.py", line 440, in send
    resp = conn.urlopen(
  File "C:\Users\46121\PycharmProjects\CS65_3\vr_env\lib\site-packages\urllib3\connectionpool.py", line 785, in urlopen
    retries = retries.increment(
  File "C:\Users\46121\PycharmProjects\CS65_3\vr_env\lib\site-packages\urllib3\util\retry.py", line 592, in increment
    raise MaxRetryError(_pool, url, error or ResponseError(cause))
urllib3.exceptions.MaxRetryError: HTTPConnectionPool(host='127.0.0.1', port=6800): Max retries exceeded with url: / (Caused by NewConnectionError('<urllib3.connection.HTTPConnection object at 0x000001F38F147A30>: Failed to establish a new connection: [WinError 10061] No connection could be made because the target machine actively refused it'))

During handling of the above exception, another exception occurred:

Traceback (most recent call last):
  File "C:\Users\46121\PycharmProjects\CS65_3\cs65_4\cs65_5\polls\utils.py", line 82, in wrapper
    result = func(*args, **kwargs)
  File "C:\Users\46121\PycharmProjects\CS65_3\vr_env\lib\site-packages\django\views\decorators\csrf.py", line 54, in wrapped_view
    return view_func(*args, **kwargs)
  File "C:\Users\46121\PycharmProjects\CS65_3\vr_env\lib\site-packages\django\views\generic\base.py", line 69, in view
    return self.dispatch(request, *args, **kwargs)
  File "C:\Users\46121\PycharmProjects\CS65_3\vr_env\lib\site-packages\rest_framework\views.py", line 509, in dispatch
    response = self.handle_exception(exc)
  File "C:\Users\46121\PycharmProjects\CS65_3\vr_env\lib\site-packages\rest_framework\views.py", line 469, in handle_exception
    self.raise_uncaught_exception(exc)
  File "C:\Users\46121\PycharmProjects\CS65_3\vr_env\lib\site-packages\rest_framework\views.py", line 480, in raise_uncaught_exception
    raise exc
  File "C:\Users\46121\PycharmProjects\CS65_3\vr_env\lib\site-packages\rest_framework\views.py", line 506, in dispatch
    response = handler(request, *args, **kwargs)
  File "C:\Users\46121\PycharmProjects\CS65_3\vr_env\lib\site-packages\rest_framework\decorators.py", line 50, in handler
    return func(*args, **kwargs)
  File "C:\Users\46121\PycharmProjects\CS65_3\cs65_4\cs65_5\polls\views.py", line 171, in client_status
    requests.get(scrapyd_url(client.ip, client.port), timeout=3)
  File "C:\Users\46121\PycharmProjects\CS65_3\vr_env\lib\site-packages\requests\api.py", line 75, in get
    return request('get', url, params=params, **kwargs)
  File "C:\Users\46121\PycharmProjects\CS65_3\vr_env\lib\site-packages\requests\api.py", line 61, in request
    return session.request(method=method, url=url, **kwargs)
  File "C:\Users\46121\PycharmProjects\CS65_3\vr_env\lib\site-packages\requests\sessions.py", line 529, in request
    resp = self.send(prep, **send_kwargs)
  File "C:\Users\46121\PycharmProjects\CS65_3\vr_env\lib\site-packages\requests\sessions.py", line 645, in send
    r = adapter.send(request, **kwargs)
  File "C:\Users\46121\PycharmProjects\CS65_3\vr_env\lib\site-packages\requests\adapters.py", line 519, in send
    raise ConnectionError(e, request=request)
requests.exceptions.ConnectionError: HTTPConnectionPool(host='127.0.0.1', port=6800): Max retries exceeded with url: / (Caused by NewConnectionError('<urllib3.connection.HTTPConnection object at 0x000001F38F147A30>: Failed to establish a new connection: [WinError 10061] No connection could be made because the target machine actively refused it'))
ERROR - 2022-05-25 15:40:04,016 - process: 27260 - utils.py - polls.utils - 84 - utils - HTTPConnectionPool(host='127.0.0.1', port=6800): Max retries exceeded with url: / (Caused by NewConnectionError('<urllib3.connection.HTTPConnection object at 0x000001F38F294670>: Failed to establish a new connection: [WinError 10061] No connection could be made because the target machine actively refused it'))
Traceback (most recent call last):
  File "C:\Users\46121\PycharmProjects\CS65_3\vr_env\lib\site-packages\urllib3\connection.py", line 174, in _new_conn
    conn = connection.create_connection(
  File "C:\Users\46121\PycharmProjects\CS65_3\vr_env\lib\site-packages\urllib3\util\connection.py", line 95, in create_connection
    raise err
  File "C:\Users\46121\PycharmProjects\CS65_3\vr_env\lib\site-packages\urllib3\util\connection.py", line 85, in create_connection
    sock.connect(sa)
ConnectionRefusedError: [WinError 10061] No connection could be made because the target machine actively refused it

During handling of the above exception, another exception occurred:

Traceback (most recent call last):
  File "C:\Users\46121\PycharmProjects\CS65_3\vr_env\lib\site-packages\urllib3\connectionpool.py", line 703, in urlopen
    httplib_response = self._make_request(
  File "C:\Users\46121\PycharmProjects\CS65_3\vr_env\lib\site-packages\urllib3\connectionpool.py", line 398, in _make_request
    conn.request(method, url, **httplib_request_kw)
  File "C:\Users\46121\PycharmProjects\CS65_3\vr_env\lib\site-packages\urllib3\connection.py", line 239, in request
    super(HTTPConnection, self).request(method, url, body=body, headers=headers)
  File "C:\Users\46121\AppData\Local\Programs\Python\Python38\lib\http\client.py", line 1240, in request
    self._send_request(method, url, body, headers, encode_chunked)
  File "C:\Users\46121\AppData\Local\Programs\Python\Python38\lib\http\client.py", line 1286, in _send_request
    self.endheaders(body, encode_chunked=encode_chunked)
  File "C:\Users\46121\AppData\Local\Programs\Python\Python38\lib\http\client.py", line 1235, in endheaders
    self._send_output(message_body, encode_chunked=encode_chunked)
  File "C:\Users\46121\AppData\Local\Programs\Python\Python38\lib\http\client.py", line 1006, in _send_output
    self.send(msg)
  File "C:\Users\46121\AppData\Local\Programs\Python\Python38\lib\http\client.py", line 946, in send
    self.connect()
  File "C:\Users\46121\PycharmProjects\CS65_3\vr_env\lib\site-packages\urllib3\connection.py", line 205, in connect
    conn = self._new_conn()
  File "C:\Users\46121\PycharmProjects\CS65_3\vr_env\lib\site-packages\urllib3\connection.py", line 186, in _new_conn
    raise NewConnectionError(
urllib3.exceptions.NewConnectionError: <urllib3.connection.HTTPConnection object at 0x000001F38F294670>: Failed to establish a new connection: [WinError 10061] No connection could be made because the target machine actively refused it

During handling of the above exception, another exception occurred:

Traceback (most recent call last):
  File "C:\Users\46121\PycharmProjects\CS65_3\vr_env\lib\site-packages\requests\adapters.py", line 440, in send
    resp = conn.urlopen(
  File "C:\Users\46121\PycharmProjects\CS65_3\vr_env\lib\site-packages\urllib3\connectionpool.py", line 785, in urlopen
    retries = retries.increment(
  File "C:\Users\46121\PycharmProjects\CS65_3\vr_env\lib\site-packages\urllib3\util\retry.py", line 592, in increment
    raise MaxRetryError(_pool, url, error or ResponseError(cause))
urllib3.exceptions.MaxRetryError: HTTPConnectionPool(host='127.0.0.1', port=6800): Max retries exceeded with url: / (Caused by NewConnectionError('<urllib3.connection.HTTPConnection object at 0x000001F38F294670>: Failed to establish a new connection: [WinError 10061] No connection could be made because the target machine actively refused it'))

During handling of the above exception, another exception occurred:

Traceback (most recent call last):
  File "C:\Users\46121\PycharmProjects\CS65_3\cs65_4\cs65_5\polls\utils.py", line 82, in wrapper
    result = func(*args, **kwargs)
  File "C:\Users\46121\PycharmProjects\CS65_3\vr_env\lib\site-packages\django\views\decorators\csrf.py", line 54, in wrapped_view
    return view_func(*args, **kwargs)
  File "C:\Users\46121\PycharmProjects\CS65_3\vr_env\lib\site-packages\django\views\generic\base.py", line 69, in view
    return self.dispatch(request, *args, **kwargs)
  File "C:\Users\46121\PycharmProjects\CS65_3\vr_env\lib\site-packages\rest_framework\views.py", line 509, in dispatch
    response = self.handle_exception(exc)
  File "C:\Users\46121\PycharmProjects\CS65_3\vr_env\lib\site-packages\rest_framework\views.py", line 469, in handle_exception
    self.raise_uncaught_exception(exc)
  File "C:\Users\46121\PycharmProjects\CS65_3\vr_env\lib\site-packages\rest_framework\views.py", line 480, in raise_uncaught_exception
    raise exc
  File "C:\Users\46121\PycharmProjects\CS65_3\vr_env\lib\site-packages\rest_framework\views.py", line 506, in dispatch
    response = handler(request, *args, **kwargs)
  File "C:\Users\46121\PycharmProjects\CS65_3\vr_env\lib\site-packages\rest_framework\decorators.py", line 50, in handler
    return func(*args, **kwargs)
  File "C:\Users\46121\PycharmProjects\CS65_3\cs65_4\cs65_5\polls\views.py", line 171, in client_status
    requests.get(scrapyd_url(client.ip, client.port), timeout=3)
  File "C:\Users\46121\PycharmProjects\CS65_3\vr_env\lib\site-packages\requests\api.py", line 75, in get
    return request('get', url, params=params, **kwargs)
  File "C:\Users\46121\PycharmProjects\CS65_3\vr_env\lib\site-packages\requests\api.py", line 61, in request
    return session.request(method=method, url=url, **kwargs)
  File "C:\Users\46121\PycharmProjects\CS65_3\vr_env\lib\site-packages\requests\sessions.py", line 529, in request
    resp = self.send(prep, **send_kwargs)
  File "C:\Users\46121\PycharmProjects\CS65_3\vr_env\lib\site-packages\requests\sessions.py", line 645, in send
    r = adapter.send(request, **kwargs)
  File "C:\Users\46121\PycharmProjects\CS65_3\vr_env\lib\site-packages\requests\adapters.py", line 519, in send
    raise ConnectionError(e, request=request)
requests.exceptions.ConnectionError: HTTPConnectionPool(host='127.0.0.1', port=6800): Max retries exceeded with url: / (Caused by NewConnectionError('<urllib3.connection.HTTPConnection object at 0x000001F38F294670>: Failed to establish a new connection: [WinError 10061] No connection could be made because the target machine actively refused it'))
ERROR - 2022-05-25 15:41:55,572 - process: 27260 - utils.py - polls.utils - 84 - utils - HTTPConnectionPool(host='127.0.0.1', port=6800): Max retries exceeded with url: / (Caused by NewConnectionError('<urllib3.connection.HTTPConnection object at 0x000001F38DB46790>: Failed to establish a new connection: [WinError 10061] No connection could be made because the target machine actively refused it'))
Traceback (most recent call last):
  File "C:\Users\46121\PycharmProjects\CS65_3\vr_env\lib\site-packages\urllib3\connection.py", line 174, in _new_conn
    conn = connection.create_connection(
  File "C:\Users\46121\PycharmProjects\CS65_3\vr_env\lib\site-packages\urllib3\util\connection.py", line 95, in create_connection
    raise err
  File "C:\Users\46121\PycharmProjects\CS65_3\vr_env\lib\site-packages\urllib3\util\connection.py", line 85, in create_connection
    sock.connect(sa)
ConnectionRefusedError: [WinError 10061] No connection could be made because the target machine actively refused it

During handling of the above exception, another exception occurred:

Traceback (most recent call last):
  File "C:\Users\46121\PycharmProjects\CS65_3\vr_env\lib\site-packages\urllib3\connectionpool.py", line 703, in urlopen
    httplib_response = self._make_request(
  File "C:\Users\46121\PycharmProjects\CS65_3\vr_env\lib\site-packages\urllib3\connectionpool.py", line 398, in _make_request
    conn.request(method, url, **httplib_request_kw)
  File "C:\Users\46121\PycharmProjects\CS65_3\vr_env\lib\site-packages\urllib3\connection.py", line 239, in request
    super(HTTPConnection, self).request(method, url, body=body, headers=headers)
  File "C:\Users\46121\AppData\Local\Programs\Python\Python38\lib\http\client.py", line 1240, in request
    self._send_request(method, url, body, headers, encode_chunked)
  File "C:\Users\46121\AppData\Local\Programs\Python\Python38\lib\http\client.py", line 1286, in _send_request
    self.endheaders(body, encode_chunked=encode_chunked)
  File "C:\Users\46121\AppData\Local\Programs\Python\Python38\lib\http\client.py", line 1235, in endheaders
    self._send_output(message_body, encode_chunked=encode_chunked)
  File "C:\Users\46121\AppData\Local\Programs\Python\Python38\lib\http\client.py", line 1006, in _send_output
    self.send(msg)
  File "C:\Users\46121\AppData\Local\Programs\Python\Python38\lib\http\client.py", line 946, in send
    self.connect()
  File "C:\Users\46121\PycharmProjects\CS65_3\vr_env\lib\site-packages\urllib3\connection.py", line 205, in connect
    conn = self._new_conn()
  File "C:\Users\46121\PycharmProjects\CS65_3\vr_env\lib\site-packages\urllib3\connection.py", line 186, in _new_conn
    raise NewConnectionError(
urllib3.exceptions.NewConnectionError: <urllib3.connection.HTTPConnection object at 0x000001F38DB46790>: Failed to establish a new connection: [WinError 10061] No connection could be made because the target machine actively refused it

During handling of the above exception, another exception occurred:

Traceback (most recent call last):
  File "C:\Users\46121\PycharmProjects\CS65_3\vr_env\lib\site-packages\requests\adapters.py", line 440, in send
    resp = conn.urlopen(
  File "C:\Users\46121\PycharmProjects\CS65_3\vr_env\lib\site-packages\urllib3\connectionpool.py", line 785, in urlopen
    retries = retries.increment(
  File "C:\Users\46121\PycharmProjects\CS65_3\vr_env\lib\site-packages\urllib3\util\retry.py", line 592, in increment
    raise MaxRetryError(_pool, url, error or ResponseError(cause))
urllib3.exceptions.MaxRetryError: HTTPConnectionPool(host='127.0.0.1', port=6800): Max retries exceeded with url: / (Caused by NewConnectionError('<urllib3.connection.HTTPConnection object at 0x000001F38DB46790>: Failed to establish a new connection: [WinError 10061] No connection could be made because the target machine actively refused it'))

During handling of the above exception, another exception occurred:

Traceback (most recent call last):
  File "C:\Users\46121\PycharmProjects\CS65_3\cs65_4\cs65_5\polls\utils.py", line 82, in wrapper
    result = func(*args, **kwargs)
  File "C:\Users\46121\PycharmProjects\CS65_3\vr_env\lib\site-packages\django\views\decorators\csrf.py", line 54, in wrapped_view
    return view_func(*args, **kwargs)
  File "C:\Users\46121\PycharmProjects\CS65_3\vr_env\lib\site-packages\django\views\generic\base.py", line 69, in view
    return self.dispatch(request, *args, **kwargs)
  File "C:\Users\46121\PycharmProjects\CS65_3\vr_env\lib\site-packages\rest_framework\views.py", line 509, in dispatch
    response = self.handle_exception(exc)
  File "C:\Users\46121\PycharmProjects\CS65_3\vr_env\lib\site-packages\rest_framework\views.py", line 469, in handle_exception
    self.raise_uncaught_exception(exc)
  File "C:\Users\46121\PycharmProjects\CS65_3\vr_env\lib\site-packages\rest_framework\views.py", line 480, in raise_uncaught_exception
    raise exc
  File "C:\Users\46121\PycharmProjects\CS65_3\vr_env\lib\site-packages\rest_framework\views.py", line 506, in dispatch
    response = handler(request, *args, **kwargs)
  File "C:\Users\46121\PycharmProjects\CS65_3\vr_env\lib\site-packages\rest_framework\decorators.py", line 50, in handler
    return func(*args, **kwargs)
  File "C:\Users\46121\PycharmProjects\CS65_3\cs65_4\cs65_5\polls\views.py", line 171, in client_status
    requests.get(scrapyd_url(client.ip, client.port), timeout=3)
  File "C:\Users\46121\PycharmProjects\CS65_3\vr_env\lib\site-packages\requests\api.py", line 75, in get
    return request('get', url, params=params, **kwargs)
  File "C:\Users\46121\PycharmProjects\CS65_3\vr_env\lib\site-packages\requests\api.py", line 61, in request
    return session.request(method=method, url=url, **kwargs)
  File "C:\Users\46121\PycharmProjects\CS65_3\vr_env\lib\site-packages\requests\sessions.py", line 529, in request
    resp = self.send(prep, **send_kwargs)
  File "C:\Users\46121\PycharmProjects\CS65_3\vr_env\lib\site-packages\requests\sessions.py", line 645, in send
    r = adapter.send(request, **kwargs)
  File "C:\Users\46121\PycharmProjects\CS65_3\vr_env\lib\site-packages\requests\adapters.py", line 519, in send
    raise ConnectionError(e, request=request)
requests.exceptions.ConnectionError: HTTPConnectionPool(host='127.0.0.1', port=6800): Max retries exceeded with url: / (Caused by NewConnectionError('<urllib3.connection.HTTPConnection object at 0x000001F38DB46790>: Failed to establish a new connection: [WinError 10061] No connection could be made because the target machine actively refused it'))
ERROR - 2022-05-25 15:42:15,965 - process: 27260 - utils.py - polls.utils - 84 - utils - HTTPConnectionPool(host='127.0.0.1', port=6800): Max retries exceeded with url: / (Caused by NewConnectionError('<urllib3.connection.HTTPConnection object at 0x000001F38DB46EE0>: Failed to establish a new connection: [WinError 10061] No connection could be made because the target machine actively refused it'))
Traceback (most recent call last):
  File "C:\Users\46121\PycharmProjects\CS65_3\vr_env\lib\site-packages\urllib3\connection.py", line 174, in _new_conn
    conn = connection.create_connection(
  File "C:\Users\46121\PycharmProjects\CS65_3\vr_env\lib\site-packages\urllib3\util\connection.py", line 95, in create_connection
    raise err
  File "C:\Users\46121\PycharmProjects\CS65_3\vr_env\lib\site-packages\urllib3\util\connection.py", line 85, in create_connection
    sock.connect(sa)
ConnectionRefusedError: [WinError 10061] No connection could be made because the target machine actively refused it

During handling of the above exception, another exception occurred:

Traceback (most recent call last):
  File "C:\Users\46121\PycharmProjects\CS65_3\vr_env\lib\site-packages\urllib3\connectionpool.py", line 703, in urlopen
    httplib_response = self._make_request(
  File "C:\Users\46121\PycharmProjects\CS65_3\vr_env\lib\site-packages\urllib3\connectionpool.py", line 398, in _make_request
    conn.request(method, url, **httplib_request_kw)
  File "C:\Users\46121\PycharmProjects\CS65_3\vr_env\lib\site-packages\urllib3\connection.py", line 239, in request
    super(HTTPConnection, self).request(method, url, body=body, headers=headers)
  File "C:\Users\46121\AppData\Local\Programs\Python\Python38\lib\http\client.py", line 1240, in request
    self._send_request(method, url, body, headers, encode_chunked)
  File "C:\Users\46121\AppData\Local\Programs\Python\Python38\lib\http\client.py", line 1286, in _send_request
    self.endheaders(body, encode_chunked=encode_chunked)
  File "C:\Users\46121\AppData\Local\Programs\Python\Python38\lib\http\client.py", line 1235, in endheaders
    self._send_output(message_body, encode_chunked=encode_chunked)
  File "C:\Users\46121\AppData\Local\Programs\Python\Python38\lib\http\client.py", line 1006, in _send_output
    self.send(msg)
  File "C:\Users\46121\AppData\Local\Programs\Python\Python38\lib\http\client.py", line 946, in send
    self.connect()
  File "C:\Users\46121\PycharmProjects\CS65_3\vr_env\lib\site-packages\urllib3\connection.py", line 205, in connect
    conn = self._new_conn()
  File "C:\Users\46121\PycharmProjects\CS65_3\vr_env\lib\site-packages\urllib3\connection.py", line 186, in _new_conn
    raise NewConnectionError(
urllib3.exceptions.NewConnectionError: <urllib3.connection.HTTPConnection object at 0x000001F38DB46EE0>: Failed to establish a new connection: [WinError 10061] No connection could be made because the target machine actively refused it

During handling of the above exception, another exception occurred:

Traceback (most recent call last):
  File "C:\Users\46121\PycharmProjects\CS65_3\vr_env\lib\site-packages\requests\adapters.py", line 440, in send
    resp = conn.urlopen(
  File "C:\Users\46121\PycharmProjects\CS65_3\vr_env\lib\site-packages\urllib3\connectionpool.py", line 785, in urlopen
    retries = retries.increment(
  File "C:\Users\46121\PycharmProjects\CS65_3\vr_env\lib\site-packages\urllib3\util\retry.py", line 592, in increment
    raise MaxRetryError(_pool, url, error or ResponseError(cause))
urllib3.exceptions.MaxRetryError: HTTPConnectionPool(host='127.0.0.1', port=6800): Max retries exceeded with url: / (Caused by NewConnectionError('<urllib3.connection.HTTPConnection object at 0x000001F38DB46EE0>: Failed to establish a new connection: [WinError 10061] No connection could be made because the target machine actively refused it'))

During handling of the above exception, another exception occurred:

Traceback (most recent call last):
  File "C:\Users\46121\PycharmProjects\CS65_3\cs65_4\cs65_5\polls\utils.py", line 82, in wrapper
    result = func(*args, **kwargs)
  File "C:\Users\46121\PycharmProjects\CS65_3\vr_env\lib\site-packages\django\views\decorators\csrf.py", line 54, in wrapped_view
    return view_func(*args, **kwargs)
  File "C:\Users\46121\PycharmProjects\CS65_3\vr_env\lib\site-packages\django\views\generic\base.py", line 69, in view
    return self.dispatch(request, *args, **kwargs)
  File "C:\Users\46121\PycharmProjects\CS65_3\vr_env\lib\site-packages\rest_framework\views.py", line 509, in dispatch
    response = self.handle_exception(exc)
  File "C:\Users\46121\PycharmProjects\CS65_3\vr_env\lib\site-packages\rest_framework\views.py", line 469, in handle_exception
    self.raise_uncaught_exception(exc)
  File "C:\Users\46121\PycharmProjects\CS65_3\vr_env\lib\site-packages\rest_framework\views.py", line 480, in raise_uncaught_exception
    raise exc
  File "C:\Users\46121\PycharmProjects\CS65_3\vr_env\lib\site-packages\rest_framework\views.py", line 506, in dispatch
    response = handler(request, *args, **kwargs)
  File "C:\Users\46121\PycharmProjects\CS65_3\vr_env\lib\site-packages\rest_framework\decorators.py", line 50, in handler
    return func(*args, **kwargs)
  File "C:\Users\46121\PycharmProjects\CS65_3\cs65_4\cs65_5\polls\views.py", line 171, in client_status
    requests.get(scrapyd_url(client.ip, client.port), timeout=3)
  File "C:\Users\46121\PycharmProjects\CS65_3\vr_env\lib\site-packages\requests\api.py", line 75, in get
    return request('get', url, params=params, **kwargs)
  File "C:\Users\46121\PycharmProjects\CS65_3\vr_env\lib\site-packages\requests\api.py", line 61, in request
    return session.request(method=method, url=url, **kwargs)
  File "C:\Users\46121\PycharmProjects\CS65_3\vr_env\lib\site-packages\requests\sessions.py", line 529, in request
    resp = self.send(prep, **send_kwargs)
  File "C:\Users\46121\PycharmProjects\CS65_3\vr_env\lib\site-packages\requests\sessions.py", line 645, in send
    r = adapter.send(request, **kwargs)
  File "C:\Users\46121\PycharmProjects\CS65_3\vr_env\lib\site-packages\requests\adapters.py", line 519, in send
    raise ConnectionError(e, request=request)
requests.exceptions.ConnectionError: HTTPConnectionPool(host='127.0.0.1', port=6800): Max retries exceeded with url: / (Caused by NewConnectionError('<urllib3.connection.HTTPConnection object at 0x000001F38DB46EE0>: Failed to establish a new connection: [WinError 10061] No connection could be made because the target machine actively refused it'))
ERROR - 2022-05-25 15:43:07,762 - process: 27260 - utils.py - polls.utils - 84 - utils - HTTPConnectionPool(host='127.0.0.1', port=6800): Max retries exceeded with url: / (Caused by NewConnectionError('<urllib3.connection.HTTPConnection object at 0x000001F38DAA5760>: Failed to establish a new connection: [WinError 10061] No connection could be made because the target machine actively refused it'))
Traceback (most recent call last):
  File "C:\Users\46121\PycharmProjects\CS65_3\vr_env\lib\site-packages\urllib3\connection.py", line 174, in _new_conn
    conn = connection.create_connection(
  File "C:\Users\46121\PycharmProjects\CS65_3\vr_env\lib\site-packages\urllib3\util\connection.py", line 95, in create_connection
    raise err
  File "C:\Users\46121\PycharmProjects\CS65_3\vr_env\lib\site-packages\urllib3\util\connection.py", line 85, in create_connection
    sock.connect(sa)
ConnectionRefusedError: [WinError 10061] No connection could be made because the target machine actively refused it

During handling of the above exception, another exception occurred:

Traceback (most recent call last):
  File "C:\Users\46121\PycharmProjects\CS65_3\vr_env\lib\site-packages\urllib3\connectionpool.py", line 703, in urlopen
    httplib_response = self._make_request(
  File "C:\Users\46121\PycharmProjects\CS65_3\vr_env\lib\site-packages\urllib3\connectionpool.py", line 398, in _make_request
    conn.request(method, url, **httplib_request_kw)
  File "C:\Users\46121\PycharmProjects\CS65_3\vr_env\lib\site-packages\urllib3\connection.py", line 239, in request
    super(HTTPConnection, self).request(method, url, body=body, headers=headers)
  File "C:\Users\46121\AppData\Local\Programs\Python\Python38\lib\http\client.py", line 1240, in request
    self._send_request(method, url, body, headers, encode_chunked)
  File "C:\Users\46121\AppData\Local\Programs\Python\Python38\lib\http\client.py", line 1286, in _send_request
    self.endheaders(body, encode_chunked=encode_chunked)
  File "C:\Users\46121\AppData\Local\Programs\Python\Python38\lib\http\client.py", line 1235, in endheaders
    self._send_output(message_body, encode_chunked=encode_chunked)
  File "C:\Users\46121\AppData\Local\Programs\Python\Python38\lib\http\client.py", line 1006, in _send_output
    self.send(msg)
  File "C:\Users\46121\AppData\Local\Programs\Python\Python38\lib\http\client.py", line 946, in send
    self.connect()
  File "C:\Users\46121\PycharmProjects\CS65_3\vr_env\lib\site-packages\urllib3\connection.py", line 205, in connect
    conn = self._new_conn()
  File "C:\Users\46121\PycharmProjects\CS65_3\vr_env\lib\site-packages\urllib3\connection.py", line 186, in _new_conn
    raise NewConnectionError(
urllib3.exceptions.NewConnectionError: <urllib3.connection.HTTPConnection object at 0x000001F38DAA5760>: Failed to establish a new connection: [WinError 10061] No connection could be made because the target machine actively refused it

During handling of the above exception, another exception occurred:

Traceback (most recent call last):
  File "C:\Users\46121\PycharmProjects\CS65_3\vr_env\lib\site-packages\requests\adapters.py", line 440, in send
    resp = conn.urlopen(
  File "C:\Users\46121\PycharmProjects\CS65_3\vr_env\lib\site-packages\urllib3\connectionpool.py", line 785, in urlopen
    retries = retries.increment(
  File "C:\Users\46121\PycharmProjects\CS65_3\vr_env\lib\site-packages\urllib3\util\retry.py", line 592, in increment
    raise MaxRetryError(_pool, url, error or ResponseError(cause))
urllib3.exceptions.MaxRetryError: HTTPConnectionPool(host='127.0.0.1', port=6800): Max retries exceeded with url: / (Caused by NewConnectionError('<urllib3.connection.HTTPConnection object at 0x000001F38DAA5760>: Failed to establish a new connection: [WinError 10061] No connection could be made because the target machine actively refused it'))

During handling of the above exception, another exception occurred:

Traceback (most recent call last):
  File "C:\Users\46121\PycharmProjects\CS65_3\cs65_4\cs65_5\polls\utils.py", line 82, in wrapper
    result = func(*args, **kwargs)
  File "C:\Users\46121\PycharmProjects\CS65_3\vr_env\lib\site-packages\django\views\decorators\csrf.py", line 54, in wrapped_view
    return view_func(*args, **kwargs)
  File "C:\Users\46121\PycharmProjects\CS65_3\vr_env\lib\site-packages\django\views\generic\base.py", line 69, in view
    return self.dispatch(request, *args, **kwargs)
  File "C:\Users\46121\PycharmProjects\CS65_3\vr_env\lib\site-packages\rest_framework\views.py", line 509, in dispatch
    response = self.handle_exception(exc)
  File "C:\Users\46121\PycharmProjects\CS65_3\vr_env\lib\site-packages\rest_framework\views.py", line 469, in handle_exception
    self.raise_uncaught_exception(exc)
  File "C:\Users\46121\PycharmProjects\CS65_3\vr_env\lib\site-packages\rest_framework\views.py", line 480, in raise_uncaught_exception
    raise exc
  File "C:\Users\46121\PycharmProjects\CS65_3\vr_env\lib\site-packages\rest_framework\views.py", line 506, in dispatch
    response = handler(request, *args, **kwargs)
  File "C:\Users\46121\PycharmProjects\CS65_3\vr_env\lib\site-packages\rest_framework\decorators.py", line 50, in handler
    return func(*args, **kwargs)
  File "C:\Users\46121\PycharmProjects\CS65_3\cs65_4\cs65_5\polls\views.py", line 171, in client_status
    requests.get(scrapyd_url(client.ip, client.port), timeout=3)
  File "C:\Users\46121\PycharmProjects\CS65_3\vr_env\lib\site-packages\requests\api.py", line 75, in get
    return request('get', url, params=params, **kwargs)
  File "C:\Users\46121\PycharmProjects\CS65_3\vr_env\lib\site-packages\requests\api.py", line 61, in request
    return session.request(method=method, url=url, **kwargs)
  File "C:\Users\46121\PycharmProjects\CS65_3\vr_env\lib\site-packages\requests\sessions.py", line 529, in request
    resp = self.send(prep, **send_kwargs)
  File "C:\Users\46121\PycharmProjects\CS65_3\vr_env\lib\site-packages\requests\sessions.py", line 645, in send
    r = adapter.send(request, **kwargs)
  File "C:\Users\46121\PycharmProjects\CS65_3\vr_env\lib\site-packages\requests\adapters.py", line 519, in send
    raise ConnectionError(e, request=request)
requests.exceptions.ConnectionError: HTTPConnectionPool(host='127.0.0.1', port=6800): Max retries exceeded with url: / (Caused by NewConnectionError('<urllib3.connection.HTTPConnection object at 0x000001F38DAA5760>: Failed to establish a new connection: [WinError 10061] No connection could be made because the target machine actively refused it'))
ERROR - 2022-05-25 15:45:40,560 - process: 27260 - utils.py - polls.utils - 84 - utils - HTTPConnectionPool(host='127.0.0.1', port=6800): Max retries exceeded with url: / (Caused by NewConnectionError('<urllib3.connection.HTTPConnection object at 0x000001F38F2941F0>: Failed to establish a new connection: [WinError 10061] No connection could be made because the target machine actively refused it'))
Traceback (most recent call last):
  File "C:\Users\46121\PycharmProjects\CS65_3\vr_env\lib\site-packages\urllib3\connection.py", line 174, in _new_conn
    conn = connection.create_connection(
  File "C:\Users\46121\PycharmProjects\CS65_3\vr_env\lib\site-packages\urllib3\util\connection.py", line 95, in create_connection
    raise err
  File "C:\Users\46121\PycharmProjects\CS65_3\vr_env\lib\site-packages\urllib3\util\connection.py", line 85, in create_connection
    sock.connect(sa)
ConnectionRefusedError: [WinError 10061] No connection could be made because the target machine actively refused it

During handling of the above exception, another exception occurred:

Traceback (most recent call last):
  File "C:\Users\46121\PycharmProjects\CS65_3\vr_env\lib\site-packages\urllib3\connectionpool.py", line 703, in urlopen
    httplib_response = self._make_request(
  File "C:\Users\46121\PycharmProjects\CS65_3\vr_env\lib\site-packages\urllib3\connectionpool.py", line 398, in _make_request
    conn.request(method, url, **httplib_request_kw)
  File "C:\Users\46121\PycharmProjects\CS65_3\vr_env\lib\site-packages\urllib3\connection.py", line 239, in request
    super(HTTPConnection, self).request(method, url, body=body, headers=headers)
  File "C:\Users\46121\AppData\Local\Programs\Python\Python38\lib\http\client.py", line 1240, in request
    self._send_request(method, url, body, headers, encode_chunked)
  File "C:\Users\46121\AppData\Local\Programs\Python\Python38\lib\http\client.py", line 1286, in _send_request
    self.endheaders(body, encode_chunked=encode_chunked)
  File "C:\Users\46121\AppData\Local\Programs\Python\Python38\lib\http\client.py", line 1235, in endheaders
    self._send_output(message_body, encode_chunked=encode_chunked)
  File "C:\Users\46121\AppData\Local\Programs\Python\Python38\lib\http\client.py", line 1006, in _send_output
    self.send(msg)
  File "C:\Users\46121\AppData\Local\Programs\Python\Python38\lib\http\client.py", line 946, in send
    self.connect()
  File "C:\Users\46121\PycharmProjects\CS65_3\vr_env\lib\site-packages\urllib3\connection.py", line 205, in connect
    conn = self._new_conn()
  File "C:\Users\46121\PycharmProjects\CS65_3\vr_env\lib\site-packages\urllib3\connection.py", line 186, in _new_conn
    raise NewConnectionError(
urllib3.exceptions.NewConnectionError: <urllib3.connection.HTTPConnection object at 0x000001F38F2941F0>: Failed to establish a new connection: [WinError 10061] No connection could be made because the target machine actively refused it

During handling of the above exception, another exception occurred:

Traceback (most recent call last):
  File "C:\Users\46121\PycharmProjects\CS65_3\vr_env\lib\site-packages\requests\adapters.py", line 440, in send
    resp = conn.urlopen(
  File "C:\Users\46121\PycharmProjects\CS65_3\vr_env\lib\site-packages\urllib3\connectionpool.py", line 785, in urlopen
    retries = retries.increment(
  File "C:\Users\46121\PycharmProjects\CS65_3\vr_env\lib\site-packages\urllib3\util\retry.py", line 592, in increment
    raise MaxRetryError(_pool, url, error or ResponseError(cause))
urllib3.exceptions.MaxRetryError: HTTPConnectionPool(host='127.0.0.1', port=6800): Max retries exceeded with url: / (Caused by NewConnectionError('<urllib3.connection.HTTPConnection object at 0x000001F38F2941F0>: Failed to establish a new connection: [WinError 10061] No connection could be made because the target machine actively refused it'))

During handling of the above exception, another exception occurred:

Traceback (most recent call last):
  File "C:\Users\46121\PycharmProjects\CS65_3\cs65_4\cs65_5\polls\utils.py", line 82, in wrapper
    result = func(*args, **kwargs)
  File "C:\Users\46121\PycharmProjects\CS65_3\vr_env\lib\site-packages\django\views\decorators\csrf.py", line 54, in wrapped_view
    return view_func(*args, **kwargs)
  File "C:\Users\46121\PycharmProjects\CS65_3\vr_env\lib\site-packages\django\views\generic\base.py", line 69, in view
    return self.dispatch(request, *args, **kwargs)
  File "C:\Users\46121\PycharmProjects\CS65_3\vr_env\lib\site-packages\rest_framework\views.py", line 509, in dispatch
    response = self.handle_exception(exc)
  File "C:\Users\46121\PycharmProjects\CS65_3\vr_env\lib\site-packages\rest_framework\views.py", line 469, in handle_exception
    self.raise_uncaught_exception(exc)
  File "C:\Users\46121\PycharmProjects\CS65_3\vr_env\lib\site-packages\rest_framework\views.py", line 480, in raise_uncaught_exception
    raise exc
  File "C:\Users\46121\PycharmProjects\CS65_3\vr_env\lib\site-packages\rest_framework\views.py", line 506, in dispatch
    response = handler(request, *args, **kwargs)
  File "C:\Users\46121\PycharmProjects\CS65_3\vr_env\lib\site-packages\rest_framework\decorators.py", line 50, in handler
    return func(*args, **kwargs)
  File "C:\Users\46121\PycharmProjects\CS65_3\cs65_4\cs65_5\polls\views.py", line 171, in client_status
    requests.get(scrapyd_url(client.ip, client.port), timeout=3)
  File "C:\Users\46121\PycharmProjects\CS65_3\vr_env\lib\site-packages\requests\api.py", line 75, in get
    return request('get', url, params=params, **kwargs)
  File "C:\Users\46121\PycharmProjects\CS65_3\vr_env\lib\site-packages\requests\api.py", line 61, in request
    return session.request(method=method, url=url, **kwargs)
  File "C:\Users\46121\PycharmProjects\CS65_3\vr_env\lib\site-packages\requests\sessions.py", line 529, in request
    resp = self.send(prep, **send_kwargs)
  File "C:\Users\46121\PycharmProjects\CS65_3\vr_env\lib\site-packages\requests\sessions.py", line 645, in send
    r = adapter.send(request, **kwargs)
  File "C:\Users\46121\PycharmProjects\CS65_3\vr_env\lib\site-packages\requests\adapters.py", line 519, in send
    raise ConnectionError(e, request=request)
requests.exceptions.ConnectionError: HTTPConnectionPool(host='127.0.0.1', port=6800): Max retries exceeded with url: / (Caused by NewConnectionError('<urllib3.connection.HTTPConnection object at 0x000001F38F2941F0>: Failed to establish a new connection: [WinError 10061] No connection could be made because the target machine actively refused it'))
ERROR - 2022-05-25 15:45:43,245 - process: 27260 - utils.py - polls.utils - 84 - utils - HTTPConnectionPool(host='127.0.0.1', port=6800): Max retries exceeded with url: / (Caused by NewConnectionError('<urllib3.connection.HTTPConnection object at 0x000001F38DA85FA0>: Failed to establish a new connection: [WinError 10061] No connection could be made because the target machine actively refused it'))
Traceback (most recent call last):
  File "C:\Users\46121\PycharmProjects\CS65_3\vr_env\lib\site-packages\urllib3\connection.py", line 174, in _new_conn
    conn = connection.create_connection(
  File "C:\Users\46121\PycharmProjects\CS65_3\vr_env\lib\site-packages\urllib3\util\connection.py", line 95, in create_connection
    raise err
  File "C:\Users\46121\PycharmProjects\CS65_3\vr_env\lib\site-packages\urllib3\util\connection.py", line 85, in create_connection
    sock.connect(sa)
ConnectionRefusedError: [WinError 10061] No connection could be made because the target machine actively refused it

During handling of the above exception, another exception occurred:

Traceback (most recent call last):
  File "C:\Users\46121\PycharmProjects\CS65_3\vr_env\lib\site-packages\urllib3\connectionpool.py", line 703, in urlopen
    httplib_response = self._make_request(
  File "C:\Users\46121\PycharmProjects\CS65_3\vr_env\lib\site-packages\urllib3\connectionpool.py", line 398, in _make_request
    conn.request(method, url, **httplib_request_kw)
  File "C:\Users\46121\PycharmProjects\CS65_3\vr_env\lib\site-packages\urllib3\connection.py", line 239, in request
    super(HTTPConnection, self).request(method, url, body=body, headers=headers)
  File "C:\Users\46121\AppData\Local\Programs\Python\Python38\lib\http\client.py", line 1240, in request
    self._send_request(method, url, body, headers, encode_chunked)
  File "C:\Users\46121\AppData\Local\Programs\Python\Python38\lib\http\client.py", line 1286, in _send_request
    self.endheaders(body, encode_chunked=encode_chunked)
  File "C:\Users\46121\AppData\Local\Programs\Python\Python38\lib\http\client.py", line 1235, in endheaders
    self._send_output(message_body, encode_chunked=encode_chunked)
  File "C:\Users\46121\AppData\Local\Programs\Python\Python38\lib\http\client.py", line 1006, in _send_output
    self.send(msg)
  File "C:\Users\46121\AppData\Local\Programs\Python\Python38\lib\http\client.py", line 946, in send
    self.connect()
  File "C:\Users\46121\PycharmProjects\CS65_3\vr_env\lib\site-packages\urllib3\connection.py", line 205, in connect
    conn = self._new_conn()
  File "C:\Users\46121\PycharmProjects\CS65_3\vr_env\lib\site-packages\urllib3\connection.py", line 186, in _new_conn
    raise NewConnectionError(
urllib3.exceptions.NewConnectionError: <urllib3.connection.HTTPConnection object at 0x000001F38DA85FA0>: Failed to establish a new connection: [WinError 10061] No connection could be made because the target machine actively refused it

During handling of the above exception, another exception occurred:

Traceback (most recent call last):
  File "C:\Users\46121\PycharmProjects\CS65_3\vr_env\lib\site-packages\requests\adapters.py", line 440, in send
    resp = conn.urlopen(
  File "C:\Users\46121\PycharmProjects\CS65_3\vr_env\lib\site-packages\urllib3\connectionpool.py", line 785, in urlopen
    retries = retries.increment(
  File "C:\Users\46121\PycharmProjects\CS65_3\vr_env\lib\site-packages\urllib3\util\retry.py", line 592, in increment
    raise MaxRetryError(_pool, url, error or ResponseError(cause))
urllib3.exceptions.MaxRetryError: HTTPConnectionPool(host='127.0.0.1', port=6800): Max retries exceeded with url: / (Caused by NewConnectionError('<urllib3.connection.HTTPConnection object at 0x000001F38DA85FA0>: Failed to establish a new connection: [WinError 10061] No connection could be made because the target machine actively refused it'))

During handling of the above exception, another exception occurred:

Traceback (most recent call last):
  File "C:\Users\46121\PycharmProjects\CS65_3\cs65_4\cs65_5\polls\utils.py", line 82, in wrapper
    result = func(*args, **kwargs)
  File "C:\Users\46121\PycharmProjects\CS65_3\vr_env\lib\site-packages\django\views\decorators\csrf.py", line 54, in wrapped_view
    return view_func(*args, **kwargs)
  File "C:\Users\46121\PycharmProjects\CS65_3\vr_env\lib\site-packages\django\views\generic\base.py", line 69, in view
    return self.dispatch(request, *args, **kwargs)
  File "C:\Users\46121\PycharmProjects\CS65_3\vr_env\lib\site-packages\rest_framework\views.py", line 509, in dispatch
    response = self.handle_exception(exc)
  File "C:\Users\46121\PycharmProjects\CS65_3\vr_env\lib\site-packages\rest_framework\views.py", line 469, in handle_exception
    self.raise_uncaught_exception(exc)
  File "C:\Users\46121\PycharmProjects\CS65_3\vr_env\lib\site-packages\rest_framework\views.py", line 480, in raise_uncaught_exception
    raise exc
  File "C:\Users\46121\PycharmProjects\CS65_3\vr_env\lib\site-packages\rest_framework\views.py", line 506, in dispatch
    response = handler(request, *args, **kwargs)
  File "C:\Users\46121\PycharmProjects\CS65_3\vr_env\lib\site-packages\rest_framework\decorators.py", line 50, in handler
    return func(*args, **kwargs)
  File "C:\Users\46121\PycharmProjects\CS65_3\cs65_4\cs65_5\polls\views.py", line 171, in client_status
    requests.get(scrapyd_url(client.ip, client.port), timeout=3)
  File "C:\Users\46121\PycharmProjects\CS65_3\vr_env\lib\site-packages\requests\api.py", line 75, in get
    return request('get', url, params=params, **kwargs)
  File "C:\Users\46121\PycharmProjects\CS65_3\vr_env\lib\site-packages\requests\api.py", line 61, in request
    return session.request(method=method, url=url, **kwargs)
  File "C:\Users\46121\PycharmProjects\CS65_3\vr_env\lib\site-packages\requests\sessions.py", line 529, in request
    resp = self.send(prep, **send_kwargs)
  File "C:\Users\46121\PycharmProjects\CS65_3\vr_env\lib\site-packages\requests\sessions.py", line 645, in send
    r = adapter.send(request, **kwargs)
  File "C:\Users\46121\PycharmProjects\CS65_3\vr_env\lib\site-packages\requests\adapters.py", line 519, in send
    raise ConnectionError(e, request=request)
requests.exceptions.ConnectionError: HTTPConnectionPool(host='127.0.0.1', port=6800): Max retries exceeded with url: / (Caused by NewConnectionError('<urllib3.connection.HTTPConnection object at 0x000001F38DA85FA0>: Failed to establish a new connection: [WinError 10061] No connection could be made because the target machine actively refused it'))
ERROR - 2022-05-25 15:46:03,254 - process: 27260 - utils.py - polls.utils - 84 - utils - HTTPConnectionPool(host='127.0.0.1', port=6800): Max retries exceeded with url: / (Caused by NewConnectionError('<urllib3.connection.HTTPConnection object at 0x000001F38F10B400>: Failed to establish a new connection: [WinError 10061] No connection could be made because the target machine actively refused it'))
Traceback (most recent call last):
  File "C:\Users\46121\PycharmProjects\CS65_3\vr_env\lib\site-packages\urllib3\connection.py", line 174, in _new_conn
    conn = connection.create_connection(
  File "C:\Users\46121\PycharmProjects\CS65_3\vr_env\lib\site-packages\urllib3\util\connection.py", line 95, in create_connection
    raise err
  File "C:\Users\46121\PycharmProjects\CS65_3\vr_env\lib\site-packages\urllib3\util\connection.py", line 85, in create_connection
    sock.connect(sa)
ConnectionRefusedError: [WinError 10061] No connection could be made because the target machine actively refused it

During handling of the above exception, another exception occurred:

Traceback (most recent call last):
  File "C:\Users\46121\PycharmProjects\CS65_3\vr_env\lib\site-packages\urllib3\connectionpool.py", line 703, in urlopen
    httplib_response = self._make_request(
  File "C:\Users\46121\PycharmProjects\CS65_3\vr_env\lib\site-packages\urllib3\connectionpool.py", line 398, in _make_request
    conn.request(method, url, **httplib_request_kw)
  File "C:\Users\46121\PycharmProjects\CS65_3\vr_env\lib\site-packages\urllib3\connection.py", line 239, in request
    super(HTTPConnection, self).request(method, url, body=body, headers=headers)
  File "C:\Users\46121\AppData\Local\Programs\Python\Python38\lib\http\client.py", line 1240, in request
    self._send_request(method, url, body, headers, encode_chunked)
  File "C:\Users\46121\AppData\Local\Programs\Python\Python38\lib\http\client.py", line 1286, in _send_request
    self.endheaders(body, encode_chunked=encode_chunked)
  File "C:\Users\46121\AppData\Local\Programs\Python\Python38\lib\http\client.py", line 1235, in endheaders
    self._send_output(message_body, encode_chunked=encode_chunked)
  File "C:\Users\46121\AppData\Local\Programs\Python\Python38\lib\http\client.py", line 1006, in _send_output
    self.send(msg)
  File "C:\Users\46121\AppData\Local\Programs\Python\Python38\lib\http\client.py", line 946, in send
    self.connect()
  File "C:\Users\46121\PycharmProjects\CS65_3\vr_env\lib\site-packages\urllib3\connection.py", line 205, in connect
    conn = self._new_conn()
  File "C:\Users\46121\PycharmProjects\CS65_3\vr_env\lib\site-packages\urllib3\connection.py", line 186, in _new_conn
    raise NewConnectionError(
urllib3.exceptions.NewConnectionError: <urllib3.connection.HTTPConnection object at 0x000001F38F10B400>: Failed to establish a new connection: [WinError 10061] No connection could be made because the target machine actively refused it

During handling of the above exception, another exception occurred:

Traceback (most recent call last):
  File "C:\Users\46121\PycharmProjects\CS65_3\vr_env\lib\site-packages\requests\adapters.py", line 440, in send
    resp = conn.urlopen(
  File "C:\Users\46121\PycharmProjects\CS65_3\vr_env\lib\site-packages\urllib3\connectionpool.py", line 785, in urlopen
    retries = retries.increment(
  File "C:\Users\46121\PycharmProjects\CS65_3\vr_env\lib\site-packages\urllib3\util\retry.py", line 592, in increment
    raise MaxRetryError(_pool, url, error or ResponseError(cause))
urllib3.exceptions.MaxRetryError: HTTPConnectionPool(host='127.0.0.1', port=6800): Max retries exceeded with url: / (Caused by NewConnectionError('<urllib3.connection.HTTPConnection object at 0x000001F38F10B400>: Failed to establish a new connection: [WinError 10061] No connection could be made because the target machine actively refused it'))

During handling of the above exception, another exception occurred:

Traceback (most recent call last):
  File "C:\Users\46121\PycharmProjects\CS65_3\cs65_4\cs65_5\polls\utils.py", line 82, in wrapper
    result = func(*args, **kwargs)
  File "C:\Users\46121\PycharmProjects\CS65_3\vr_env\lib\site-packages\django\views\decorators\csrf.py", line 54, in wrapped_view
    return view_func(*args, **kwargs)
  File "C:\Users\46121\PycharmProjects\CS65_3\vr_env\lib\site-packages\django\views\generic\base.py", line 69, in view
    return self.dispatch(request, *args, **kwargs)
  File "C:\Users\46121\PycharmProjects\CS65_3\vr_env\lib\site-packages\rest_framework\views.py", line 509, in dispatch
    response = self.handle_exception(exc)
  File "C:\Users\46121\PycharmProjects\CS65_3\vr_env\lib\site-packages\rest_framework\views.py", line 469, in handle_exception
    self.raise_uncaught_exception(exc)
  File "C:\Users\46121\PycharmProjects\CS65_3\vr_env\lib\site-packages\rest_framework\views.py", line 480, in raise_uncaught_exception
    raise exc
  File "C:\Users\46121\PycharmProjects\CS65_3\vr_env\lib\site-packages\rest_framework\views.py", line 506, in dispatch
    response = handler(request, *args, **kwargs)
  File "C:\Users\46121\PycharmProjects\CS65_3\vr_env\lib\site-packages\rest_framework\decorators.py", line 50, in handler
    return func(*args, **kwargs)
  File "C:\Users\46121\PycharmProjects\CS65_3\cs65_4\cs65_5\polls\views.py", line 171, in client_status
    requests.get(scrapyd_url(client.ip, client.port), timeout=3)
  File "C:\Users\46121\PycharmProjects\CS65_3\vr_env\lib\site-packages\requests\api.py", line 75, in get
    return request('get', url, params=params, **kwargs)
  File "C:\Users\46121\PycharmProjects\CS65_3\vr_env\lib\site-packages\requests\api.py", line 61, in request
    return session.request(method=method, url=url, **kwargs)
  File "C:\Users\46121\PycharmProjects\CS65_3\vr_env\lib\site-packages\requests\sessions.py", line 529, in request
    resp = self.send(prep, **send_kwargs)
  File "C:\Users\46121\PycharmProjects\CS65_3\vr_env\lib\site-packages\requests\sessions.py", line 645, in send
    r = adapter.send(request, **kwargs)
  File "C:\Users\46121\PycharmProjects\CS65_3\vr_env\lib\site-packages\requests\adapters.py", line 519, in send
    raise ConnectionError(e, request=request)
requests.exceptions.ConnectionError: HTTPConnectionPool(host='127.0.0.1', port=6800): Max retries exceeded with url: / (Caused by NewConnectionError('<urllib3.connection.HTTPConnection object at 0x000001F38F10B400>: Failed to establish a new connection: [WinError 10061] No connection could be made because the target machine actively refused it'))
ERROR - 2022-05-25 15:46:34,136 - process: 27260 - utils.py - polls.utils - 84 - utils - HTTPConnectionPool(host='127.0.0.1', port=6800): Max retries exceeded with url: / (Caused by NewConnectionError('<urllib3.connection.HTTPConnection object at 0x000001F390ED8700>: Failed to establish a new connection: [WinError 10061] No connection could be made because the target machine actively refused it'))
Traceback (most recent call last):
  File "C:\Users\46121\PycharmProjects\CS65_3\vr_env\lib\site-packages\urllib3\connection.py", line 174, in _new_conn
    conn = connection.create_connection(
  File "C:\Users\46121\PycharmProjects\CS65_3\vr_env\lib\site-packages\urllib3\util\connection.py", line 95, in create_connection
    raise err
  File "C:\Users\46121\PycharmProjects\CS65_3\vr_env\lib\site-packages\urllib3\util\connection.py", line 85, in create_connection
    sock.connect(sa)
ConnectionRefusedError: [WinError 10061] No connection could be made because the target machine actively refused it

During handling of the above exception, another exception occurred:

Traceback (most recent call last):
  File "C:\Users\46121\PycharmProjects\CS65_3\vr_env\lib\site-packages\urllib3\connectionpool.py", line 703, in urlopen
    httplib_response = self._make_request(
  File "C:\Users\46121\PycharmProjects\CS65_3\vr_env\lib\site-packages\urllib3\connectionpool.py", line 398, in _make_request
    conn.request(method, url, **httplib_request_kw)
  File "C:\Users\46121\PycharmProjects\CS65_3\vr_env\lib\site-packages\urllib3\connection.py", line 239, in request
    super(HTTPConnection, self).request(method, url, body=body, headers=headers)
  File "C:\Users\46121\AppData\Local\Programs\Python\Python38\lib\http\client.py", line 1240, in request
    self._send_request(method, url, body, headers, encode_chunked)
  File "C:\Users\46121\AppData\Local\Programs\Python\Python38\lib\http\client.py", line 1286, in _send_request
    self.endheaders(body, encode_chunked=encode_chunked)
  File "C:\Users\46121\AppData\Local\Programs\Python\Python38\lib\http\client.py", line 1235, in endheaders
    self._send_output(message_body, encode_chunked=encode_chunked)
  File "C:\Users\46121\AppData\Local\Programs\Python\Python38\lib\http\client.py", line 1006, in _send_output
    self.send(msg)
  File "C:\Users\46121\AppData\Local\Programs\Python\Python38\lib\http\client.py", line 946, in send
    self.connect()
  File "C:\Users\46121\PycharmProjects\CS65_3\vr_env\lib\site-packages\urllib3\connection.py", line 205, in connect
    conn = self._new_conn()
  File "C:\Users\46121\PycharmProjects\CS65_3\vr_env\lib\site-packages\urllib3\connection.py", line 186, in _new_conn
    raise NewConnectionError(
urllib3.exceptions.NewConnectionError: <urllib3.connection.HTTPConnection object at 0x000001F390ED8700>: Failed to establish a new connection: [WinError 10061] No connection could be made because the target machine actively refused it

During handling of the above exception, another exception occurred:

Traceback (most recent call last):
  File "C:\Users\46121\PycharmProjects\CS65_3\vr_env\lib\site-packages\requests\adapters.py", line 440, in send
    resp = conn.urlopen(
  File "C:\Users\46121\PycharmProjects\CS65_3\vr_env\lib\site-packages\urllib3\connectionpool.py", line 785, in urlopen
    retries = retries.increment(
  File "C:\Users\46121\PycharmProjects\CS65_3\vr_env\lib\site-packages\urllib3\util\retry.py", line 592, in increment
    raise MaxRetryError(_pool, url, error or ResponseError(cause))
urllib3.exceptions.MaxRetryError: HTTPConnectionPool(host='127.0.0.1', port=6800): Max retries exceeded with url: / (Caused by NewConnectionError('<urllib3.connection.HTTPConnection object at 0x000001F390ED8700>: Failed to establish a new connection: [WinError 10061] No connection could be made because the target machine actively refused it'))

During handling of the above exception, another exception occurred:

Traceback (most recent call last):
  File "C:\Users\46121\PycharmProjects\CS65_3\cs65_4\cs65_5\polls\utils.py", line 82, in wrapper
    result = func(*args, **kwargs)
  File "C:\Users\46121\PycharmProjects\CS65_3\vr_env\lib\site-packages\django\views\decorators\csrf.py", line 54, in wrapped_view
    return view_func(*args, **kwargs)
  File "C:\Users\46121\PycharmProjects\CS65_3\vr_env\lib\site-packages\django\views\generic\base.py", line 69, in view
    return self.dispatch(request, *args, **kwargs)
  File "C:\Users\46121\PycharmProjects\CS65_3\vr_env\lib\site-packages\rest_framework\views.py", line 509, in dispatch
    response = self.handle_exception(exc)
  File "C:\Users\46121\PycharmProjects\CS65_3\vr_env\lib\site-packages\rest_framework\views.py", line 469, in handle_exception
    self.raise_uncaught_exception(exc)
  File "C:\Users\46121\PycharmProjects\CS65_3\vr_env\lib\site-packages\rest_framework\views.py", line 480, in raise_uncaught_exception
    raise exc
  File "C:\Users\46121\PycharmProjects\CS65_3\vr_env\lib\site-packages\rest_framework\views.py", line 506, in dispatch
    response = handler(request, *args, **kwargs)
  File "C:\Users\46121\PycharmProjects\CS65_3\vr_env\lib\site-packages\rest_framework\decorators.py", line 50, in handler
    return func(*args, **kwargs)
  File "C:\Users\46121\PycharmProjects\CS65_3\cs65_4\cs65_5\polls\views.py", line 171, in client_status
    requests.get(scrapyd_url(client.ip, client.port), timeout=3)
  File "C:\Users\46121\PycharmProjects\CS65_3\vr_env\lib\site-packages\requests\api.py", line 75, in get
    return request('get', url, params=params, **kwargs)
  File "C:\Users\46121\PycharmProjects\CS65_3\vr_env\lib\site-packages\requests\api.py", line 61, in request
    return session.request(method=method, url=url, **kwargs)
  File "C:\Users\46121\PycharmProjects\CS65_3\vr_env\lib\site-packages\requests\sessions.py", line 529, in request
    resp = self.send(prep, **send_kwargs)
  File "C:\Users\46121\PycharmProjects\CS65_3\vr_env\lib\site-packages\requests\sessions.py", line 645, in send
    r = adapter.send(request, **kwargs)
  File "C:\Users\46121\PycharmProjects\CS65_3\vr_env\lib\site-packages\requests\adapters.py", line 519, in send
    raise ConnectionError(e, request=request)
requests.exceptions.ConnectionError: HTTPConnectionPool(host='127.0.0.1', port=6800): Max retries exceeded with url: / (Caused by NewConnectionError('<urllib3.connection.HTTPConnection object at 0x000001F390ED8700>: Failed to establish a new connection: [WinError 10061] No connection could be made because the target machine actively refused it'))
ERROR - 2022-05-25 15:50:56,728 - process: 27260 - utils.py - polls.utils - 84 - utils - HTTPConnectionPool(host='127.0.0.1', port=6800): Max retries exceeded with url: / (Caused by NewConnectionError('<urllib3.connection.HTTPConnection object at 0x000001F38F6D0F70>: Failed to establish a new connection: [WinError 10061] No connection could be made because the target machine actively refused it'))
Traceback (most recent call last):
  File "C:\Users\46121\PycharmProjects\CS65_3\vr_env\lib\site-packages\urllib3\connection.py", line 174, in _new_conn
    conn = connection.create_connection(
  File "C:\Users\46121\PycharmProjects\CS65_3\vr_env\lib\site-packages\urllib3\util\connection.py", line 95, in create_connection
    raise err
  File "C:\Users\46121\PycharmProjects\CS65_3\vr_env\lib\site-packages\urllib3\util\connection.py", line 85, in create_connection
    sock.connect(sa)
ConnectionRefusedError: [WinError 10061] No connection could be made because the target machine actively refused it

During handling of the above exception, another exception occurred:

Traceback (most recent call last):
  File "C:\Users\46121\PycharmProjects\CS65_3\vr_env\lib\site-packages\urllib3\connectionpool.py", line 703, in urlopen
    httplib_response = self._make_request(
  File "C:\Users\46121\PycharmProjects\CS65_3\vr_env\lib\site-packages\urllib3\connectionpool.py", line 398, in _make_request
    conn.request(method, url, **httplib_request_kw)
  File "C:\Users\46121\PycharmProjects\CS65_3\vr_env\lib\site-packages\urllib3\connection.py", line 239, in request
    super(HTTPConnection, self).request(method, url, body=body, headers=headers)
  File "C:\Users\46121\AppData\Local\Programs\Python\Python38\lib\http\client.py", line 1240, in request
    self._send_request(method, url, body, headers, encode_chunked)
  File "C:\Users\46121\AppData\Local\Programs\Python\Python38\lib\http\client.py", line 1286, in _send_request
    self.endheaders(body, encode_chunked=encode_chunked)
  File "C:\Users\46121\AppData\Local\Programs\Python\Python38\lib\http\client.py", line 1235, in endheaders
    self._send_output(message_body, encode_chunked=encode_chunked)
  File "C:\Users\46121\AppData\Local\Programs\Python\Python38\lib\http\client.py", line 1006, in _send_output
    self.send(msg)
  File "C:\Users\46121\AppData\Local\Programs\Python\Python38\lib\http\client.py", line 946, in send
    self.connect()
  File "C:\Users\46121\PycharmProjects\CS65_3\vr_env\lib\site-packages\urllib3\connection.py", line 205, in connect
    conn = self._new_conn()
  File "C:\Users\46121\PycharmProjects\CS65_3\vr_env\lib\site-packages\urllib3\connection.py", line 186, in _new_conn
    raise NewConnectionError(
urllib3.exceptions.NewConnectionError: <urllib3.connection.HTTPConnection object at 0x000001F38F6D0F70>: Failed to establish a new connection: [WinError 10061] No connection could be made because the target machine actively refused it

During handling of the above exception, another exception occurred:

Traceback (most recent call last):
  File "C:\Users\46121\PycharmProjects\CS65_3\vr_env\lib\site-packages\requests\adapters.py", line 440, in send
    resp = conn.urlopen(
  File "C:\Users\46121\PycharmProjects\CS65_3\vr_env\lib\site-packages\urllib3\connectionpool.py", line 785, in urlopen
    retries = retries.increment(
  File "C:\Users\46121\PycharmProjects\CS65_3\vr_env\lib\site-packages\urllib3\util\retry.py", line 592, in increment
    raise MaxRetryError(_pool, url, error or ResponseError(cause))
urllib3.exceptions.MaxRetryError: HTTPConnectionPool(host='127.0.0.1', port=6800): Max retries exceeded with url: / (Caused by NewConnectionError('<urllib3.connection.HTTPConnection object at 0x000001F38F6D0F70>: Failed to establish a new connection: [WinError 10061] No connection could be made because the target machine actively refused it'))

During handling of the above exception, another exception occurred:

Traceback (most recent call last):
  File "C:\Users\46121\PycharmProjects\CS65_3\cs65_4\cs65_5\polls\utils.py", line 82, in wrapper
    result = func(*args, **kwargs)
  File "C:\Users\46121\PycharmProjects\CS65_3\vr_env\lib\site-packages\django\views\decorators\csrf.py", line 54, in wrapped_view
    return view_func(*args, **kwargs)
  File "C:\Users\46121\PycharmProjects\CS65_3\vr_env\lib\site-packages\django\views\generic\base.py", line 69, in view
    return self.dispatch(request, *args, **kwargs)
  File "C:\Users\46121\PycharmProjects\CS65_3\vr_env\lib\site-packages\rest_framework\views.py", line 509, in dispatch
    response = self.handle_exception(exc)
  File "C:\Users\46121\PycharmProjects\CS65_3\vr_env\lib\site-packages\rest_framework\views.py", line 469, in handle_exception
    self.raise_uncaught_exception(exc)
  File "C:\Users\46121\PycharmProjects\CS65_3\vr_env\lib\site-packages\rest_framework\views.py", line 480, in raise_uncaught_exception
    raise exc
  File "C:\Users\46121\PycharmProjects\CS65_3\vr_env\lib\site-packages\rest_framework\views.py", line 506, in dispatch
    response = handler(request, *args, **kwargs)
  File "C:\Users\46121\PycharmProjects\CS65_3\vr_env\lib\site-packages\rest_framework\decorators.py", line 50, in handler
    return func(*args, **kwargs)
  File "C:\Users\46121\PycharmProjects\CS65_3\cs65_4\cs65_5\polls\views.py", line 171, in client_status
    requests.get(scrapyd_url(client.ip, client.port), timeout=3)
  File "C:\Users\46121\PycharmProjects\CS65_3\vr_env\lib\site-packages\requests\api.py", line 75, in get
    return request('get', url, params=params, **kwargs)
  File "C:\Users\46121\PycharmProjects\CS65_3\vr_env\lib\site-packages\requests\api.py", line 61, in request
    return session.request(method=method, url=url, **kwargs)
  File "C:\Users\46121\PycharmProjects\CS65_3\vr_env\lib\site-packages\requests\sessions.py", line 529, in request
    resp = self.send(prep, **send_kwargs)
  File "C:\Users\46121\PycharmProjects\CS65_3\vr_env\lib\site-packages\requests\sessions.py", line 645, in send
    r = adapter.send(request, **kwargs)
  File "C:\Users\46121\PycharmProjects\CS65_3\vr_env\lib\site-packages\requests\adapters.py", line 519, in send
    raise ConnectionError(e, request=request)
requests.exceptions.ConnectionError: HTTPConnectionPool(host='127.0.0.1', port=6800): Max retries exceeded with url: / (Caused by NewConnectionError('<urllib3.connection.HTTPConnection object at 0x000001F38F6D0F70>: Failed to establish a new connection: [WinError 10061] No connection could be made because the target machine actively refused it'))
ERROR - 2022-05-25 15:51:04,654 - process: 27260 - utils.py - polls.utils - 84 - utils - HTTPConnectionPool(host='127.0.0.1', port=6800): Max retries exceeded with url: / (Caused by NewConnectionError('<urllib3.connection.HTTPConnection object at 0x000001F38F211A60>: Failed to establish a new connection: [WinError 10061] No connection could be made because the target machine actively refused it'))
Traceback (most recent call last):
  File "C:\Users\46121\PycharmProjects\CS65_3\vr_env\lib\site-packages\urllib3\connection.py", line 174, in _new_conn
    conn = connection.create_connection(
  File "C:\Users\46121\PycharmProjects\CS65_3\vr_env\lib\site-packages\urllib3\util\connection.py", line 95, in create_connection
    raise err
  File "C:\Users\46121\PycharmProjects\CS65_3\vr_env\lib\site-packages\urllib3\util\connection.py", line 85, in create_connection
    sock.connect(sa)
ConnectionRefusedError: [WinError 10061] No connection could be made because the target machine actively refused it

During handling of the above exception, another exception occurred:

Traceback (most recent call last):
  File "C:\Users\46121\PycharmProjects\CS65_3\vr_env\lib\site-packages\urllib3\connectionpool.py", line 703, in urlopen
    httplib_response = self._make_request(
  File "C:\Users\46121\PycharmProjects\CS65_3\vr_env\lib\site-packages\urllib3\connectionpool.py", line 398, in _make_request
    conn.request(method, url, **httplib_request_kw)
  File "C:\Users\46121\PycharmProjects\CS65_3\vr_env\lib\site-packages\urllib3\connection.py", line 239, in request
    super(HTTPConnection, self).request(method, url, body=body, headers=headers)
  File "C:\Users\46121\AppData\Local\Programs\Python\Python38\lib\http\client.py", line 1240, in request
    self._send_request(method, url, body, headers, encode_chunked)
  File "C:\Users\46121\AppData\Local\Programs\Python\Python38\lib\http\client.py", line 1286, in _send_request
    self.endheaders(body, encode_chunked=encode_chunked)
  File "C:\Users\46121\AppData\Local\Programs\Python\Python38\lib\http\client.py", line 1235, in endheaders
    self._send_output(message_body, encode_chunked=encode_chunked)
  File "C:\Users\46121\AppData\Local\Programs\Python\Python38\lib\http\client.py", line 1006, in _send_output
    self.send(msg)
  File "C:\Users\46121\AppData\Local\Programs\Python\Python38\lib\http\client.py", line 946, in send
    self.connect()
  File "C:\Users\46121\PycharmProjects\CS65_3\vr_env\lib\site-packages\urllib3\connection.py", line 205, in connect
    conn = self._new_conn()
  File "C:\Users\46121\PycharmProjects\CS65_3\vr_env\lib\site-packages\urllib3\connection.py", line 186, in _new_conn
    raise NewConnectionError(
urllib3.exceptions.NewConnectionError: <urllib3.connection.HTTPConnection object at 0x000001F38F211A60>: Failed to establish a new connection: [WinError 10061] No connection could be made because the target machine actively refused it

During handling of the above exception, another exception occurred:

Traceback (most recent call last):
  File "C:\Users\46121\PycharmProjects\CS65_3\vr_env\lib\site-packages\requests\adapters.py", line 440, in send
    resp = conn.urlopen(
  File "C:\Users\46121\PycharmProjects\CS65_3\vr_env\lib\site-packages\urllib3\connectionpool.py", line 785, in urlopen
    retries = retries.increment(
  File "C:\Users\46121\PycharmProjects\CS65_3\vr_env\lib\site-packages\urllib3\util\retry.py", line 592, in increment
    raise MaxRetryError(_pool, url, error or ResponseError(cause))
urllib3.exceptions.MaxRetryError: HTTPConnectionPool(host='127.0.0.1', port=6800): Max retries exceeded with url: / (Caused by NewConnectionError('<urllib3.connection.HTTPConnection object at 0x000001F38F211A60>: Failed to establish a new connection: [WinError 10061] No connection could be made because the target machine actively refused it'))

During handling of the above exception, another exception occurred:

Traceback (most recent call last):
  File "C:\Users\46121\PycharmProjects\CS65_3\cs65_4\cs65_5\polls\utils.py", line 82, in wrapper
    result = func(*args, **kwargs)
  File "C:\Users\46121\PycharmProjects\CS65_3\vr_env\lib\site-packages\django\views\decorators\csrf.py", line 54, in wrapped_view
    return view_func(*args, **kwargs)
  File "C:\Users\46121\PycharmProjects\CS65_3\vr_env\lib\site-packages\django\views\generic\base.py", line 69, in view
    return self.dispatch(request, *args, **kwargs)
  File "C:\Users\46121\PycharmProjects\CS65_3\vr_env\lib\site-packages\rest_framework\views.py", line 509, in dispatch
    response = self.handle_exception(exc)
  File "C:\Users\46121\PycharmProjects\CS65_3\vr_env\lib\site-packages\rest_framework\views.py", line 469, in handle_exception
    self.raise_uncaught_exception(exc)
  File "C:\Users\46121\PycharmProjects\CS65_3\vr_env\lib\site-packages\rest_framework\views.py", line 480, in raise_uncaught_exception
    raise exc
  File "C:\Users\46121\PycharmProjects\CS65_3\vr_env\lib\site-packages\rest_framework\views.py", line 506, in dispatch
    response = handler(request, *args, **kwargs)
  File "C:\Users\46121\PycharmProjects\CS65_3\vr_env\lib\site-packages\rest_framework\decorators.py", line 50, in handler
    return func(*args, **kwargs)
  File "C:\Users\46121\PycharmProjects\CS65_3\cs65_4\cs65_5\polls\views.py", line 171, in client_status
    requests.get(scrapyd_url(client.ip, client.port), timeout=3)
  File "C:\Users\46121\PycharmProjects\CS65_3\vr_env\lib\site-packages\requests\api.py", line 75, in get
    return request('get', url, params=params, **kwargs)
  File "C:\Users\46121\PycharmProjects\CS65_3\vr_env\lib\site-packages\requests\api.py", line 61, in request
    return session.request(method=method, url=url, **kwargs)
  File "C:\Users\46121\PycharmProjects\CS65_3\vr_env\lib\site-packages\requests\sessions.py", line 529, in request
    resp = self.send(prep, **send_kwargs)
  File "C:\Users\46121\PycharmProjects\CS65_3\vr_env\lib\site-packages\requests\sessions.py", line 645, in send
    r = adapter.send(request, **kwargs)
  File "C:\Users\46121\PycharmProjects\CS65_3\vr_env\lib\site-packages\requests\adapters.py", line 519, in send
    raise ConnectionError(e, request=request)
requests.exceptions.ConnectionError: HTTPConnectionPool(host='127.0.0.1', port=6800): Max retries exceeded with url: / (Caused by NewConnectionError('<urllib3.connection.HTTPConnection object at 0x000001F38F211A60>: Failed to establish a new connection: [WinError 10061] No connection could be made because the target machine actively refused it'))
ERROR - 2022-05-25 15:51:41,292 - process: 27260 - utils.py - polls.utils - 84 - utils - HTTPConnectionPool(host='127.0.0.1', port=6800): Max retries exceeded with url: / (Caused by NewConnectionError('<urllib3.connection.HTTPConnection object at 0x000001F390ED8580>: Failed to establish a new connection: [WinError 10061] No connection could be made because the target machine actively refused it'))
Traceback (most recent call last):
  File "C:\Users\46121\PycharmProjects\CS65_3\vr_env\lib\site-packages\urllib3\connection.py", line 174, in _new_conn
    conn = connection.create_connection(
  File "C:\Users\46121\PycharmProjects\CS65_3\vr_env\lib\site-packages\urllib3\util\connection.py", line 95, in create_connection
    raise err
  File "C:\Users\46121\PycharmProjects\CS65_3\vr_env\lib\site-packages\urllib3\util\connection.py", line 85, in create_connection
    sock.connect(sa)
ConnectionRefusedError: [WinError 10061] No connection could be made because the target machine actively refused it

During handling of the above exception, another exception occurred:

Traceback (most recent call last):
  File "C:\Users\46121\PycharmProjects\CS65_3\vr_env\lib\site-packages\urllib3\connectionpool.py", line 703, in urlopen
    httplib_response = self._make_request(
  File "C:\Users\46121\PycharmProjects\CS65_3\vr_env\lib\site-packages\urllib3\connectionpool.py", line 398, in _make_request
    conn.request(method, url, **httplib_request_kw)
  File "C:\Users\46121\PycharmProjects\CS65_3\vr_env\lib\site-packages\urllib3\connection.py", line 239, in request
    super(HTTPConnection, self).request(method, url, body=body, headers=headers)
  File "C:\Users\46121\AppData\Local\Programs\Python\Python38\lib\http\client.py", line 1240, in request
    self._send_request(method, url, body, headers, encode_chunked)
  File "C:\Users\46121\AppData\Local\Programs\Python\Python38\lib\http\client.py", line 1286, in _send_request
    self.endheaders(body, encode_chunked=encode_chunked)
  File "C:\Users\46121\AppData\Local\Programs\Python\Python38\lib\http\client.py", line 1235, in endheaders
    self._send_output(message_body, encode_chunked=encode_chunked)
  File "C:\Users\46121\AppData\Local\Programs\Python\Python38\lib\http\client.py", line 1006, in _send_output
    self.send(msg)
  File "C:\Users\46121\AppData\Local\Programs\Python\Python38\lib\http\client.py", line 946, in send
    self.connect()
  File "C:\Users\46121\PycharmProjects\CS65_3\vr_env\lib\site-packages\urllib3\connection.py", line 205, in connect
    conn = self._new_conn()
  File "C:\Users\46121\PycharmProjects\CS65_3\vr_env\lib\site-packages\urllib3\connection.py", line 186, in _new_conn
    raise NewConnectionError(
urllib3.exceptions.NewConnectionError: <urllib3.connection.HTTPConnection object at 0x000001F390ED8580>: Failed to establish a new connection: [WinError 10061] No connection could be made because the target machine actively refused it

During handling of the above exception, another exception occurred:

Traceback (most recent call last):
  File "C:\Users\46121\PycharmProjects\CS65_3\vr_env\lib\site-packages\requests\adapters.py", line 440, in send
    resp = conn.urlopen(
  File "C:\Users\46121\PycharmProjects\CS65_3\vr_env\lib\site-packages\urllib3\connectionpool.py", line 785, in urlopen
    retries = retries.increment(
  File "C:\Users\46121\PycharmProjects\CS65_3\vr_env\lib\site-packages\urllib3\util\retry.py", line 592, in increment
    raise MaxRetryError(_pool, url, error or ResponseError(cause))
urllib3.exceptions.MaxRetryError: HTTPConnectionPool(host='127.0.0.1', port=6800): Max retries exceeded with url: / (Caused by NewConnectionError('<urllib3.connection.HTTPConnection object at 0x000001F390ED8580>: Failed to establish a new connection: [WinError 10061] No connection could be made because the target machine actively refused it'))

During handling of the above exception, another exception occurred:

Traceback (most recent call last):
  File "C:\Users\46121\PycharmProjects\CS65_3\cs65_4\cs65_5\polls\utils.py", line 82, in wrapper
    result = func(*args, **kwargs)
  File "C:\Users\46121\PycharmProjects\CS65_3\vr_env\lib\site-packages\django\views\decorators\csrf.py", line 54, in wrapped_view
    return view_func(*args, **kwargs)
  File "C:\Users\46121\PycharmProjects\CS65_3\vr_env\lib\site-packages\django\views\generic\base.py", line 69, in view
    return self.dispatch(request, *args, **kwargs)
  File "C:\Users\46121\PycharmProjects\CS65_3\vr_env\lib\site-packages\rest_framework\views.py", line 509, in dispatch
    response = self.handle_exception(exc)
  File "C:\Users\46121\PycharmProjects\CS65_3\vr_env\lib\site-packages\rest_framework\views.py", line 469, in handle_exception
    self.raise_uncaught_exception(exc)
  File "C:\Users\46121\PycharmProjects\CS65_3\vr_env\lib\site-packages\rest_framework\views.py", line 480, in raise_uncaught_exception
    raise exc
  File "C:\Users\46121\PycharmProjects\CS65_3\vr_env\lib\site-packages\rest_framework\views.py", line 506, in dispatch
    response = handler(request, *args, **kwargs)
  File "C:\Users\46121\PycharmProjects\CS65_3\vr_env\lib\site-packages\rest_framework\decorators.py", line 50, in handler
    return func(*args, **kwargs)
  File "C:\Users\46121\PycharmProjects\CS65_3\cs65_4\cs65_5\polls\views.py", line 171, in client_status
    requests.get(scrapyd_url(client.ip, client.port), timeout=3)
  File "C:\Users\46121\PycharmProjects\CS65_3\vr_env\lib\site-packages\requests\api.py", line 75, in get
    return request('get', url, params=params, **kwargs)
  File "C:\Users\46121\PycharmProjects\CS65_3\vr_env\lib\site-packages\requests\api.py", line 61, in request
    return session.request(method=method, url=url, **kwargs)
  File "C:\Users\46121\PycharmProjects\CS65_3\vr_env\lib\site-packages\requests\sessions.py", line 529, in request
    resp = self.send(prep, **send_kwargs)
  File "C:\Users\46121\PycharmProjects\CS65_3\vr_env\lib\site-packages\requests\sessions.py", line 645, in send
    r = adapter.send(request, **kwargs)
  File "C:\Users\46121\PycharmProjects\CS65_3\vr_env\lib\site-packages\requests\adapters.py", line 519, in send
    raise ConnectionError(e, request=request)
requests.exceptions.ConnectionError: HTTPConnectionPool(host='127.0.0.1', port=6800): Max retries exceeded with url: / (Caused by NewConnectionError('<urllib3.connection.HTTPConnection object at 0x000001F390ED8580>: Failed to establish a new connection: [WinError 10061] No connection could be made because the target machine actively refused it'))
ERROR - 2022-05-25 15:51:44,002 - process: 27260 - utils.py - polls.utils - 84 - utils - HTTPConnectionPool(host='127.0.0.1', port=6800): Max retries exceeded with url: / (Caused by NewConnectionError('<urllib3.connection.HTTPConnection object at 0x000001F38DB46B20>: Failed to establish a new connection: [WinError 10061] No connection could be made because the target machine actively refused it'))
Traceback (most recent call last):
  File "C:\Users\46121\PycharmProjects\CS65_3\vr_env\lib\site-packages\urllib3\connection.py", line 174, in _new_conn
    conn = connection.create_connection(
  File "C:\Users\46121\PycharmProjects\CS65_3\vr_env\lib\site-packages\urllib3\util\connection.py", line 95, in create_connection
    raise err
  File "C:\Users\46121\PycharmProjects\CS65_3\vr_env\lib\site-packages\urllib3\util\connection.py", line 85, in create_connection
    sock.connect(sa)
ConnectionRefusedError: [WinError 10061] No connection could be made because the target machine actively refused it

During handling of the above exception, another exception occurred:

Traceback (most recent call last):
  File "C:\Users\46121\PycharmProjects\CS65_3\vr_env\lib\site-packages\urllib3\connectionpool.py", line 703, in urlopen
    httplib_response = self._make_request(
  File "C:\Users\46121\PycharmProjects\CS65_3\vr_env\lib\site-packages\urllib3\connectionpool.py", line 398, in _make_request
    conn.request(method, url, **httplib_request_kw)
  File "C:\Users\46121\PycharmProjects\CS65_3\vr_env\lib\site-packages\urllib3\connection.py", line 239, in request
    super(HTTPConnection, self).request(method, url, body=body, headers=headers)
  File "C:\Users\46121\AppData\Local\Programs\Python\Python38\lib\http\client.py", line 1240, in request
    self._send_request(method, url, body, headers, encode_chunked)
  File "C:\Users\46121\AppData\Local\Programs\Python\Python38\lib\http\client.py", line 1286, in _send_request
    self.endheaders(body, encode_chunked=encode_chunked)
  File "C:\Users\46121\AppData\Local\Programs\Python\Python38\lib\http\client.py", line 1235, in endheaders
    self._send_output(message_body, encode_chunked=encode_chunked)
  File "C:\Users\46121\AppData\Local\Programs\Python\Python38\lib\http\client.py", line 1006, in _send_output
    self.send(msg)
  File "C:\Users\46121\AppData\Local\Programs\Python\Python38\lib\http\client.py", line 946, in send
    self.connect()
  File "C:\Users\46121\PycharmProjects\CS65_3\vr_env\lib\site-packages\urllib3\connection.py", line 205, in connect
    conn = self._new_conn()
  File "C:\Users\46121\PycharmProjects\CS65_3\vr_env\lib\site-packages\urllib3\connection.py", line 186, in _new_conn
    raise NewConnectionError(
urllib3.exceptions.NewConnectionError: <urllib3.connection.HTTPConnection object at 0x000001F38DB46B20>: Failed to establish a new connection: [WinError 10061] No connection could be made because the target machine actively refused it

During handling of the above exception, another exception occurred:

Traceback (most recent call last):
  File "C:\Users\46121\PycharmProjects\CS65_3\vr_env\lib\site-packages\requests\adapters.py", line 440, in send
    resp = conn.urlopen(
  File "C:\Users\46121\PycharmProjects\CS65_3\vr_env\lib\site-packages\urllib3\connectionpool.py", line 785, in urlopen
    retries = retries.increment(
  File "C:\Users\46121\PycharmProjects\CS65_3\vr_env\lib\site-packages\urllib3\util\retry.py", line 592, in increment
    raise MaxRetryError(_pool, url, error or ResponseError(cause))
urllib3.exceptions.MaxRetryError: HTTPConnectionPool(host='127.0.0.1', port=6800): Max retries exceeded with url: / (Caused by NewConnectionError('<urllib3.connection.HTTPConnection object at 0x000001F38DB46B20>: Failed to establish a new connection: [WinError 10061] No connection could be made because the target machine actively refused it'))

During handling of the above exception, another exception occurred:

Traceback (most recent call last):
  File "C:\Users\46121\PycharmProjects\CS65_3\cs65_4\cs65_5\polls\utils.py", line 82, in wrapper
    result = func(*args, **kwargs)
  File "C:\Users\46121\PycharmProjects\CS65_3\vr_env\lib\site-packages\django\views\decorators\csrf.py", line 54, in wrapped_view
    return view_func(*args, **kwargs)
  File "C:\Users\46121\PycharmProjects\CS65_3\vr_env\lib\site-packages\django\views\generic\base.py", line 69, in view
    return self.dispatch(request, *args, **kwargs)
  File "C:\Users\46121\PycharmProjects\CS65_3\vr_env\lib\site-packages\rest_framework\views.py", line 509, in dispatch
    response = self.handle_exception(exc)
  File "C:\Users\46121\PycharmProjects\CS65_3\vr_env\lib\site-packages\rest_framework\views.py", line 469, in handle_exception
    self.raise_uncaught_exception(exc)
  File "C:\Users\46121\PycharmProjects\CS65_3\vr_env\lib\site-packages\rest_framework\views.py", line 480, in raise_uncaught_exception
    raise exc
  File "C:\Users\46121\PycharmProjects\CS65_3\vr_env\lib\site-packages\rest_framework\views.py", line 506, in dispatch
    response = handler(request, *args, **kwargs)
  File "C:\Users\46121\PycharmProjects\CS65_3\vr_env\lib\site-packages\rest_framework\decorators.py", line 50, in handler
    return func(*args, **kwargs)
  File "C:\Users\46121\PycharmProjects\CS65_3\cs65_4\cs65_5\polls\views.py", line 171, in client_status
    requests.get(scrapyd_url(client.ip, client.port), timeout=3)
  File "C:\Users\46121\PycharmProjects\CS65_3\vr_env\lib\site-packages\requests\api.py", line 75, in get
    return request('get', url, params=params, **kwargs)
  File "C:\Users\46121\PycharmProjects\CS65_3\vr_env\lib\site-packages\requests\api.py", line 61, in request
    return session.request(method=method, url=url, **kwargs)
  File "C:\Users\46121\PycharmProjects\CS65_3\vr_env\lib\site-packages\requests\sessions.py", line 529, in request
    resp = self.send(prep, **send_kwargs)
  File "C:\Users\46121\PycharmProjects\CS65_3\vr_env\lib\site-packages\requests\sessions.py", line 645, in send
    r = adapter.send(request, **kwargs)
  File "C:\Users\46121\PycharmProjects\CS65_3\vr_env\lib\site-packages\requests\adapters.py", line 519, in send
    raise ConnectionError(e, request=request)
requests.exceptions.ConnectionError: HTTPConnectionPool(host='127.0.0.1', port=6800): Max retries exceeded with url: / (Caused by NewConnectionError('<urllib3.connection.HTTPConnection object at 0x000001F38DB46B20>: Failed to establish a new connection: [WinError 10061] No connection could be made because the target machine actively refused it'))
